Workbook

Sheet Tabela 1 APS + Leitos Nec.
A1: RRAS | B1: DRS | C1: REGIÃO DE SAÚDE | D1: MUNICÍPIO DA RRAS | E1: NASCIDOS VIVOS | F1: COBERTURA ANS (%) | G1: Nº DE UBS | H1: COBERTURA ESF (%) | I1: COBERTURA AB (%) | J1: GESTANTES SUSDEPENDENTES ESTIMADAS/ANO | K1: NASCIDOS VIVOS SUSDEPENDENTES ESTIMADOS/ANO | L1: LEITOS OBSTÉTRICOS | M1: LEITOS GAR PARA ATENDER AS GESTANTES SUSDEPENDENTES DO MUNICÍPIO - RRAS | N1: LEITOS UTI ADULTO | O1: LEITOS UTIN | P1: LEITOS UCINCO | Q1: LEITOS UCINCA | R1: CPN I: 3 LEITOS | S1: CPN I: 5 LEITOS | T1: CPN II: 3 LEITOS | U1: CPN II: 5 LEITOS | V1: CGBP: 10 LEITOS | W1: CGBP: 15 LEITOS | X1: CGBP: 20 LEITOS | Y1: BLH
A2: RRAS 1 | B2: Grande São Paulo | C2: Grande ABC | D2: Diadema | E2: 4230 | F2: 45.08 | G2: 20 | H2: 74.07 | I2: 80.43 | J2: =(E2*(1-F2/100)*1.1) -> 2555.4276 | K2: =E2*(1-F2/100) -> 2323.116 | L2: =((J2*2.5)/(365*0.9))*1.21 -> 23.531715 | M2: =L2*30/100 -> 7.0595146 | N2: =(L2*6/100) -> 1.4119029 | O2: =K2*2/1000 -> 4.646232 | P2: =K2*3/1000 -> 6.969348 | Q2: =K2*1/1000 -> 2.323116 | U2: 1
A3: RRAS 1 | B3: Grande São Paulo | C3: Grande ABC | D3: Mauá | E3: 4404 | F3: 47.01 | G3: 23 | H3: 29.18 | I3: 41.23 | J3: =(E3*(1-F3/100)*1.1) -> 2567.0476 | K3: =E3*(1-F3/100) -> 2333.6796 | L3: =((J3*2.5)/(365*0.9))*1.21 -> 23.638718 | M3: =L3*30/100 -> 7.0916154 | N3: =(L3*6/100) -> 1.4183231 | O3: =K3*2/1000 -> 4.6673592 | P3: =K3*3/1000 -> 7.0010388 | Q3: =K3*1/1000 -> 2.3336796
A4: RRAS 1 | B4: Grande São Paulo | C4: Grande ABC | D4: Ribeirão Pires | E4: 1041 | F4: 48.59 | G4: 10 | H4: 39.14 | I4: 46.44 | J4: =(E4*(1-F4/100)*1.1) -> 588.69591 | K4: =E4*(1-F4/100) -> 535.1781 | L4: =((J4*2.5)/(365*0.9))*1.21 -> 5.4210202 | M4: =L4*30/100 -> 1.6263061 | N4: =(L4*6/100) -> 0.32526121 | O4: =K4*2/1000 -> 1.0703562 | P4: =K4*3/1000 -> 1.6055343 | Q4: =K4*1/1000 -> 0.5351781
A5: RRAS 1 | B5: Grande São Paulo | C5: Grande ABC | D5: Rio Grande da Serra | E5: 465 | F5: 34.24 | G5: 8 | H5: 47.5 | I5: 53.4 | J5: =(E5*(1-F5/100)*1.1) -> 336.3624 | K5: =E5*(1-F5/100) -> 305.784 | L5: =((J5*2.5)/(365*0.9))*1.21 -> 3.0974011 | M5: =L5*30/100 -> 0.92922033 | N5: =(L5*6/100) -> 0.18584407 | O5: =K5*2/1000 -> 0.611568 | P5: =K5*3/1000 -> 0.917352 | Q5: =K5*1/1000 -> 0.305784 | X5: 1
A6: RRAS 1 | B6: Grande São Paulo | C6: Grande ABC | D6: Santo André | E6: 7378 | F6: 57.35 | G6: 35 | H6: 24.48 | I6: 46.5 | J6: =(E6*(1-F6/100)*1.1) -> 3461.3887 | K6: =E6*(1-F6/100) -> 3146.717 | L6: =((J6*2.5)/(365*0.9))*1.21 -> 31.87428 | M6: =L6*30/100 -> 9.5622839 | N6: =(L6*6/100) -> 1.9124568 | O6: =K6*2/1000 -> 6.293434 | P6: =K6*3/1000 -> 9.440151 | Q6: =K6*1/1000 -> 3.146717 | U6: 1
A7: RRAS 1 | B7: Grande São Paulo | C7: Grande ABC | D7: São Bernardo do Campo | E7: 7815 | F7: 55.67 | G7: 34 | H7: 63.33 | I7: 74.77 | J7: =(E7*(1-F7/100)*1.1) -> 3810.8284 | K7: =E7*(1-F7/100) -> 3464.3895 | L7: =((J7*2.5)/(365*0.9))*1.21 -> 35.092104 | M7: =L7*30/100 -> 10.527631 | N7: =(L7*6/100) -> 2.1055262 | O7: =K7*2/1000 -> 6.928779 | P7: =K7*3/1000 -> 10.393168 | Q7: =K7*1/1000 -> 3.4643895 | R7: 1 | V7: 1
A8: RRAS 1 | B8: Grande São Paulo | C8: Grande ABC | D8: São Caetano do Sul | E8: 1345 | F8: 62.1 | G8: 12 | H8: 62.09 | I8: 100 | J8: =(E8*(1-F8/100)*1.1) -> 560.7305 | K8: =E8*(1-F8/100) -> 509.755 | L8: =((J8*2.5)/(365*0.9))*1.21 -> 5.1635 | M8: =L8*30/100 -> 1.54905 | N8: =(L8*6/100) -> 0.30981 | O8: =K8*2/1000 -> 1.01951 | P8: =K8*3/1000 -> 1.529265 | Q8: =K8*1/1000 -> 0.509755 | R8: 1
A9: RRAS 2 | B9: Grande São Paulo | C9: Alto Tietê | D9: Arujá | E9: 1290 | F9: 42.29 | G9: 7 | H9: 38.41 | I9: 65.53 | J9: =(E9*(1-F9/100)*1.1) -> 818.9049 | K9: =E9*(1-F9/100) -> 744.459 | L9: =((J9*2.5)/(365*0.9))*1.21 -> 7.5409051 | M9: =L9*30/100 -> 2.2622715 | N9: =(L9*6/100) -> 0.45245431 | O9: =K9*2/1000 -> 1.488918 | P9: =K9*3/1000 -> 2.233377 | Q9: =K9*1/1000 -> 0.744459
A10: RRAS 2 | B10: Grande São Paulo | C10: Alto Tietê | D10: Biritiba Mirim | E10: 336 | F10: 11.25 | G10: 7 | H10: 21.17 | I10: 30.37 | J10: =(E10*(1-F10/100)*1.1) -> 328.02 | K10: =E10*(1-F10/100) -> 298.2 | L10: =((J10*2.5)/(365*0.9))*1.21 -> 3.0205799 | M10: =L10*30/100 -> 0.90617397 | N10: =(L10*6/100) -> 0.18123479 | O10: =K10*2/1000 -> 0.5964 | P10: =K10*3/1000 -> 0.8946 | Q10: =K10*1/1000 -> 0.2982
A11: RRAS 2 | B11: Grande São Paulo | C11: Alto Tietê | D11: Ferraz de Vasconcelos | E11: 2279 | F11: 23.22 | G11: 14 | H11: 35.52 | I11: 57.98 | J11: =(E11*(1-F11/100)*1.1) -> 1924.7978 | K11: =E11*(1-F11/100) -> 1749.8162 | L11: =((J11*2.5)/(365*0.9))*1.21 -> 17.724546 | M11: =L11*30/100 -> 5.3173638 | N11: =(L11*6/100) -> 1.0634728 | O11: =K11*2/1000 -> 3.4996324 | P11: =K11*3/1000 -> 5.2494486 | Q11: =K11*1/1000 -> 1.7498162
A12: RRAS 2 | B12: Grande São Paulo | C12: Alto Tietê | D12: Guararema | E12: 327 | F12: 21.32 | G12: 1 | H12: 0 | I12: 58.39 | J12: =(E12*(1-F12/100)*1.1) -> 283.01196 | K12: =E12*(1-F12/100) -> 257.2836 | L12: =((J12*2.5)/(365*0.9))*1.21 -> 2.6061223 | M12: =L12*30/100 -> 0.78183669 | N12: =(L12*6/100) -> 0.15636734 | O12: =K12*2/1000 -> 0.5145672 | P12: =K12*3/1000 -> 0.7718508 | Q12: =K12*1/1000 -> 0.2572836
A13: RRAS 2 | B13: Grande São Paulo | C13: Alto Tietê | D13: Guarulhos | E13: 17501 | F13: 47.05 | G13: 69 | H13: 31.27 | I13: 40.23 | J13: =(E13*(1-F13/100)*1.1) -> 10193.457 | K13: =E13*(1-F13/100) -> 9266.7795 | L13: =((J13*2.5)/(365*0.9))*1.21 -> 93.866693 | M13: =L13*30/100 -> 28.160008 | N13: =(L13*6/100) -> 5.6320016 | O13: =K13*2/1000 -> 18.533559 | P13: =K13*3/1000 -> 27.800338 | Q13: =K13*1/1000 -> 9.2667795 | Y13: 1
A14: RRAS 2 | B14: Grande São Paulo | C14: Alto Tietê | D14: Itaquaquecetuba | E14: 5077 | F14: 26.14 | G14: 17 | H14: 18.61 | I14: 34.1 | J14: =(E14*(1-F14/100)*1.1) -> 4124.8594 | K14: =E14*(1-F14/100) -> 3749.8722 | L14: =((J14*2.5)/(365*0.9))*1.21 -> 37.983865 | M14: =L14*30/100 -> 11.39516 | N14: =(L14*6/100) -> 2.2790319 | O14: =K14*2/1000 -> 7.4997444 | P14: =K14*3/1000 -> 11.249617 | Q14: =K14*1/1000 -> 3.7498722
A15: RRAS 2 | B15: Grande São Paulo | C15: Alto Tietê | D15: Mogi das Cruzes | E15: 5222 | F15: 35.92 | G15: 36 | H15: 10.83 | I15: 50.84 | J15: =(E15*(1-F15/100)*1.1) -> 3680.8834 | K15: =E15*(1-F15/100) -> 3346.2576 | L15: =((J15*2.5)/(365*0.9))*1.21 -> 33.895501 | M15: =L15*30/100 -> 10.16865 | N15: =(L15*6/100) -> 2.0337301 | O15: =K15*2/1000 -> 6.6925152 | P15: =K15*3/1000 -> 10.038773 | Q15: =K15*1/1000 -> 3.3462576 | Y15: 1
A16: RRAS 2 | B16: Grande São Paulo | C16: Alto Tietê | D16: Poá | E16: 1249 | F16: 32.1 | G16: 12 | H16: 26.44 | I16: 31.54 | J16: =(E16*(1-F16/100)*1.1) -> 932.8781 | K16: =E16*(1-F16/100) -> 848.071 | L16: =((J16*2.5)/(365*0.9))*1.21 -> 8.59043 | M16: =L16*30/100 -> 2.577129 | N16: =(L16*6/100) -> 0.5154258 | O16: =K16*2/1000 -> 1.696142 | P16: =K16*3/1000 -> 2.544213 | Q16: =K16*1/1000 -> 0.848071
A17: RRAS 2 | B17: Grande São Paulo | C17: Alto Tietê | D17: Salesópolis | E17: 179 | F17: 11.9 | G17: 2 | H17: 0 | I17: 52.51 | J17: =(E17*(1-F17/100)*1.1) -> 173.4689 | K17: =E17*(1-F17/100) -> 157.699 | L17: =((J17*2.5)/(365*0.9))*1.21 -> 1.5973925 | M17: =L17*30/100 -> 0.47921774 | N17: =(L17*6/100) -> 0.095843547 | O17: =K17*2/1000 -> 0.315398 | P17: =K17*3/1000 -> 0.473097 | Q17: =K17*1/1000 -> 0.157699
A18: RRAS 2 | B18: Grande São Paulo | C18: Alto Tietê | D18: Santa Isabel | E18: 588 | F18: 25.52 | G18: 11 | H18: 30.06 | I18: 50.97 | J18: =(E18*(1-F18/100)*1.1) -> 481.73664 | K18: =E18*(1-F18/100) -> 437.9424 | L18: =((J18*2.5)/(365*0.9))*1.21 -> 4.4360832 | M18: =L18*30/100 -> 1.330825 | N18: =(L18*6/100) -> 0.26616499 | O18: =K18*2/1000 -> 0.8758848 | P18: =K18*3/1000 -> 1.3138272 | Q18: =K18*1/1000 -> 0.4379424
A19: RRAS 2 | B19: Grande São Paulo | C19: Alto Tietê | D19: Suzano | E19: 3942 | F19: 30.8 | G19: 24 | H19: 25.5 | I19: 51.28 | J19: =(E19*(1-F19/100)*1.1) -> 3000.6504 | K19: =E19*(1-F19/100) -> 2727.864 | L19: =((J19*2.5)/(365*0.9))*1.21 -> 27.63156 | M19: =L19*30/100 -> 8.289468 | N19: =(L19*6/100) -> 1.6578936 | O19: =K19*2/1000 -> 5.455728 | P19: =K19*3/1000 -> 8.183592 | Q19: =K19*1/1000 -> 2.727864
A20: RRAS 3 | B20: Grande São Paulo | C20: Franco da Rocha | D20: Caieiras | E20: 1147 | F20: 37.01 | G20: 14 | H20: 6.8 | I20: 62.24 | J20: =(E20*(1-F20/100)*1.1) -> 794.74483 | K20: =E20*(1-F20/100) -> 722.4953 | L20: =((J20*2.5)/(365*0.9))*1.21 -> 7.3184265 | M20: =L20*30/100 -> 2.195528 | N20: =(L20*6/100) -> 0.43910559 | O20: =K20*2/1000 -> 1.4449906 | P20: =K20*3/1000 -> 2.1674859 | Q20: =K20*1/1000 -> 0.7224953
A21: RRAS 3 | B21: Grande São Paulo | C21: Franco da Rocha | D21: Cajamar | E21: 1304 | F21: 45 | G21: 11 | H21: 53.91 | I21: 76.99 | J21: =(E21*(1-F21/100)*1.1) -> 788.92 | K21: =E21*(1-F21/100) -> 717.2 | L21: =((J21*2.5)/(365*0.9))*1.21 -> 7.2647884 | M21: =L21*30/100 -> 2.1794365 | N21: =(L21*6/100) -> 0.43588731 | O21: =K21*2/1000 -> 1.4344 | P21: =K21*3/1000 -> 2.1516 | Q21: =K21*1/1000 -> 0.7172
A22: RRAS 3 | B22: Grande São Paulo | C22: Franco da Rocha | D22: Francisco Morato | E22: 2488 | F22: 24.22 | G22: 13 | H22: 47.09 | I22: 50.5 | J22: =(E22*(1-F22/100)*1.1) -> 2073.947 | K22: =E22*(1-F22/100) -> 1885.4064 | L22: =((J22*2.5)/(365*0.9))*1.21 -> 19.09799 | M22: =L22*30/100 -> 5.7293971 | N22: =(L22*6/100) -> 1.1458794 | O22: =K22*2/1000 -> 3.7708128 | P22: =K22*3/1000 -> 5.6562192 | Q22: =K22*1/1000 -> 1.8854064
A23: RRAS 3 | B23: Grande São Paulo | C23: Franco da Rocha | D23: Franco da Rocha | E23: 1833 | F23: 27.18 | G23: 14 | H23: 55.83 | I23: 76.37 | J23: =(E23*(1-F23/100)*1.1) -> 1468.2697 | K23: =E23*(1-F23/100) -> 1334.7906 | L23: =((J23*2.5)/(365*0.9))*1.21 -> 13.520596 | M23: =L23*30/100 -> 4.0561787 | N23: =(L23*6/100) -> 0.81123575 | O23: =K23*2/1000 -> 2.6695812 | P23: =K23*3/1000 -> 4.0043718 | Q23: =K23*1/1000 -> 1.3347906
A24: RRAS 3 | B24: Grande São Paulo | C24: Franco da Rocha | D24: Mairiporã | E24: 910 | F24: 21.73 | G24: 17 | H24: 37.88 | I24: 58.84 | J24: =(E24*(1-F24/100)*1.1) -> 783.4827 | K24: =E24*(1-F24/100) -> 712.257 | L24: =((J24*2.5)/(365*0.9))*1.21 -> 7.2147189 | M24: =L24*30/100 -> 2.1644157 | N24: =(L24*6/100) -> 0.43288314 | O24: =K24*2/1000 -> 1.424514 | P24: =K24*3/1000 -> 2.136771 | Q24: =K24*1/1000 -> 0.712257
A25: RRAS 4 | B25: Grande São Paulo | C25: Mananciais | D25: Cotia | E25: 3560 | F25: 37.03 | G25: 26 | H25: 8.31 | I25: 42.31 | J25: =(E25*(1-F25/100)*1.1) -> 2465.9052 | K25: =E25*(1-F25/100) -> 2241.732 | L25: =((J25*2.5)/(365*0.9))*1.21 -> 22.707346 | M25: =L25*30/100 -> 6.8122039 | N25: =(L25*6/100) -> 1.3624408 | O25: =K25*2/1000 -> 4.483464 | P25: =K25*3/1000 -> 6.725196 | Q25: =K25*1/1000 -> 2.241732
A26: RRAS 4 | B26: Grande São Paulo | C26: Mananciais | D26: Embu das Artes | E26: 3332 | F26: 26.8 | G26: 17 | H26: 28.99 | I26: 54.8 | J26: =(E26*(1-F26/100)*1.1) -> 2682.9264 | K26: =E26*(1-F26/100) -> 2439.024 | L26: =((J26*2.5)/(365*0.9))*1.21 -> 24.705791 | M26: =L26*30/100 -> 7.4117373 | N26: =(L26*6/100) -> 1.4823475 | O26: =K26*2/1000 -> 4.878048 | P26: =K26*3/1000 -> 7.317072 | Q26: =K26*1/1000 -> 2.439024
A27: RRAS 4 | B27: Grande São Paulo | C27: Mananciais | D27: Embu Guaçu | E27: 804 | F27: 13.68 | G27: 11 | H27: 64.64 | I27: 69.83 | J27: =(E27*(1-F27/100)*1.1) -> 763.41408 | K27: =E27*(1-F27/100) -> 694.0128 | L27: =((J27*2.5)/(365*0.9))*1.21 -> 7.0299166 | M27: =L27*30/100 -> 2.108975 | N27: =(L27*6/100) -> 0.42179499 | O27: =K27*2/1000 -> 1.3880256 | P27: =K27*3/1000 -> 2.0820384 | Q27: =K27*1/1000 -> 0.6940128
... A44: RRAS 7 | B44: Baixada Santista | C44: Baixada Santista | D44: Mongaguá | E44: 667 | F44: 13.12 | G44: 9 | H44: 48.68 | I44: 48.68 | J44: =(E44*(1-F44/100)*1.1) -> 637.43856 | K44: =E44*(1-F44/100) -> 579.4896 | L44: =((J44*2.5)/(365*0.9))*1.21 -> 5.869868 | M44: =L44*30/100 -> 1.7609604 | N44: =(L44*6/100) -> 0.35219208 | O44: =K44*2/1000 -> 1.1589792 | P44: =K44*3/1000 -> 1.7384688 | Q44: =K44*1/1000 -> 0.5794896
A45: RRAS 7 | B45: Baixada Santista | C45: Baixada Santista | D45: Peruíbe | E45: 915 | F45: 15.53 | G45: 16 | H45: 70.73 | I45: 100 | J45: =(E45*(1-F45/100)*1.1) -> 850.19055 | K45: =E45*(1-F45/100) -> 772.9005 | L45: =((J45*2.5)/(365*0.9))*1.21 -> 7.8289997 | M45: =L45*30/100 -> 2.3486999 | N45: =(L45*6/100) -> 0.46973998 | O45: =K45*2/1000 -> 1.545801 | P45: =K45*3/1000 -> 2.3187015 | Q45: =K45*1/1000 -> 0.7729005 | S45: 2
A46: RRAS 7 | B46: Baixada Santista | C46: Baixada Santista | D46: Praia Grande | E46: 4098 | F46: 32.64 | G46: 30 | H46: 82.78 | I46: 86.13 | J46: =(E46*(1-F46/100)*1.1) -> 3036.4541 | K46: =E46*(1-F46/100) -> 2760.4128 | L46: =((J46*2.5)/(365*0.9))*1.21 -> 27.961259 | M46: =L46*30/100 -> 8.3883777 | N46: =(L46*6/100) -> 1.6776755 | O46: =K46*2/1000 -> 5.5208256 | P46: =K46*3/1000 -> 8.2812384 | Q46: =K46*1/1000 -> 2.7604128 | R46: 1 | S46: 1 | Y46: 1
A47: RRAS 7 | B47: Baixada Santista | C47: Baixada Santista | D47: Santos | E47: 3733 | F47: 65.73 | G47: 31 | H47: 27.07 | I47: 52.34 | J47: =(E47*(1-F47/100)*1.1) -> 1407.229 | K47: =E47*(1-F47/100) -> 1279.2991 | L47: =((J47*2.5)/(365*0.9))*1.21 -> 12.958502 | M47: =L47*30/100 -> 3.8875505 | N47: =(L47*6/100) -> 0.77751009 | O47: =K47*2/1000 -> 2.5585982 | P47: =K47*3/1000 -> 3.8378973 | Q47: =K47*1/1000 -> 1.2792991 | R47: 1 | T47: 1 | U47: 1 | Y47: 2
A48: RRAS 7 | B48: Baixada Santista | C48: Baixada Santista | D48: São Vicente | E48: 3661 | F48: 38.38 | G48: 24 | H48: 27.35 | I48: 39.57 | J48: =(E48*(1-F48/100)*1.1) -> 2481.499 | K48: =E48*(1-F48/100) -> 2255.9082 | L48: =((J48*2.5)/(365*0.9))*1.21 -> 22.850942 | M48: =L48*30/100 -> 6.8552827 | N48: =(L48*6/100) -> 1.3710565 | O48: =K48*2/1000 -> 4.5118164 | P48: =K48*3/1000 -> 6.7677246 | Q48: =K48*1/1000 -> 2.2559082
A49: RRAS 7 | B49: Registro | C49: Vale do Ribeira | D49: Barra do Turvo | E49: 78 | F49: 2.45 | G49: 4 | H49: 100 | I49: 100 | J49: =(E49*(1-F49/100)*1.1) -> 83.6979 | K49: =E49*(1-F49/100) -> 76.089 | L49: =((J49*2.5)/(365*0.9))*1.21 -> 0.77073409 | M49: =L49*30/100 -> 0.23122023 | N49: =(L49*6/100) -> 0.046244045 | O49: =K49*2/1000 -> 0.152178 | P49: =K49*3/1000 -> 0.228267 | Q49: =K49*1/1000 -> 0.076089 | V49: 10
A50: RRAS 7 | B50: Registro | C50: Vale do Ribeira | D50: Cajati | E50: 411 | F50: 17.23 | G50: 8 | H50: 96.68 | I50: 100 | J50: =(E50*(1-F50/100)*1.1) -> 374.20317 | K50: =E50*(1-F50/100) -> 340.1847 | L50: =((J50*2.5)/(365*0.9))*1.21 -> 3.4458587 | M50: =L50*30/100 -> 1.0337576 | N50: =(L50*6/100) -> 0.20675152 | O50: =K50*2/1000 -> 0.6803694 | P50: =K50*3/1000 -> 1.0205541 | Q50: =K50*1/1000 -> 0.3401847
A51: RRAS 7 | B51: Registro | C51: Vale do Ribeira | D51: Cananeia | E51: 158 | F51: 5.94 | G51: 5 | H51: 100 | I51: 100 | J51: =(E51*(1-F51/100)*1.1) -> 163.47628 | K51: =E51*(1-F51/100) -> 148.6148 | L51: =((J51*2.5)/(365*0.9))*1.21 -> 1.5053752 | M51: =L51*30/100 -> 0.45161255 | N51: =(L51*6/100) -> 0.090322511 | O51: =K51*2/1000 -> 0.2972296 | P51: =K51*3/1000 -> 0.4458444 | Q51: =K51*1/1000 -> 0.1486148
A52: RRAS 7 | B52: Registro | C52: Vale do Ribeira | D52: Eldorado | E52: 165 | F52: 4.83 | G52: 9 | H52: 66.8 | I52: 86.16 | J52: =(E52*(1-F52/100)*1.1) -> 172.73355 | K52: =E52*(1-F52/100) -> 157.0305 | L52: =((J52*2.5)/(365*0.9))*1.21 -> 1.590621 | M52: =L52*30/100 -> 0.47718629 | N52: =(L52*6/100) -> 0.095437258 | O52: =K52*2/1000 -> 0.314061 | P52: =K52*3/1000 -> 0.4710915 | Q52: =K52*1/1000 -> 0.1570305
A53: RRAS 7 | B53: Registro | C53: Vale do Ribeira | D53: Iguape | E53: 285 | F53: 4.56 | G53: 9 | H53: 78.26 | I53: 78.26 | J53: =(E53*(1-F53/100)*1.1) -> 299.2044 | K53: =E53*(1-F53/100) -> 272.004 | L53: =((J53*2.5)/(365*0.9))*1.21 -> 2.7552308 | M53: =L53*30/100 -> 0.82656923 | N53: =(L53*6/100) -> 0.16531385 | O53: =K53*2/1000 -> 0.544008 | P53: =K53*3/1000 -> 0.816012 | Q53: =K53*1/1000 -> 0.272004
A54: RRAS 7 | B54: Registro | C54: Vale do Ribeira | D54: Ilha Comprida | E54: 140 | F54: 3.74 | G54: 7 | H54: 100 | I54: 100 | J54: =(E54*(1-F54/100)*1.1) -> 148.2404 | K54: =E54*(1-F54/100) -> 134.764 | L54: =((J54*2.5)/(365*0.9))*1.21 -> 1.3650752 | M54: =L54*30/100 -> 0.40952257 | N54: =(L54*6/100) -> 0.081904513 | O54: =K54*2/1000 -> 0.269528 | P54: =K54*3/1000 -> 0.404292 | Q54: =K54*1/1000 -> 0.134764
A55: RRAS 7 | B55: Registro | C55: Vale do Ribeira | D55: Iporanga | E55: 48 | F55: 1.56 | G55: 2 | H55: 100 | I55: 100 | J55: =(E55*(1-F55/100)*1.1) -> 51.97632 | K55: =E55*(1-F55/100) -> 47.2512 | L55: =((J55*2.5)/(365*0.9))*1.21 -> 0.47862517 | M55: =L55*30/100 -> 0.14358755 | N55: =(L55*6/100) -> 0.02871751 | O55: =K55*2/1000 -> 0.0945024 | P55: =K55*3/1000 -> 0.1417536 | Q55: =K55*1/1000 -> 0.0472512
A56: RRAS 7 | B56: Registro | C56: Vale do Ribeira | D56: Itariri | E56: 151 | F56: 5.9 | G56: 5 | H56: 79.15 | I56: 100 | J56: =(E56*(1-F56/100)*1.1) -> 156.3001 | K56: =E56*(1-F56/100) -> 142.091 | L56: =((J56*2.5)/(365*0.9))*1.21 -> 1.4392932 | M56: =L56*30/100 -> 0.43178795 | N56: =(L56*6/100) -> 0.086357589 | O56: =K56*2/1000 -> 0.284182 | P56: =K56*3/1000 -> 0.426273 | Q56: =K56*1/1000 -> 0.142091
...

Sheet RRAS 6 - Tabela 1 APS + Leitos 
A1: RRAS | B1: COORDENADORIA DE SAÚDE | C1: SUPERVISÃO DE SAÚDE | D1: MUNICÍPIO DA RRAS | E1: DRS | F1: NASCIDOS VIVOS | G1: COBERTURA ANS (%) | H1: Nº DE UBS | I1: COBERTURA ESF (%) | J1: COBERTURA AB (%) | K1: GESTANTES SUSDEPENDENTES ESTIMADAS/ANO | L1: NASCIDOS VIVOS SUSDEPENDENTES ESTIMADOS/ANO | M1: LEITOS OBSTÉTRICOS | N1: LEITOS GAR PARA ATENDER AS GESTANTES SUSDEPENDENTES DO MUNICÍPIO - RRAS | O1: LEITOS UTI ADULTO | P1: LEITOS UTIN | Q1: LEITOS UCINCO | R1: LEITOS UCINCA | S1: CPN I: 3 LEITOS | T1: CPN I: 5 LEITOS | U1: CPN II: 3 LEITOS | V1: CPN II: 5 LEITOS | W1: CGBP: 10 LEITOS | X1: CGBP: 15 LEITOS | Y1: CGBP: 20 LEITOS | Z1: BLH
A2: RRAS 6 | B2: CRS NORTE | C2: Casa Verde / Cachoeirinha | D2: São Paulo | E2: Grande São Paulo | F2: 3521 | G2: 49.26 | H2: 14 | J2: 70.61 | K2: =(F2*(1-G2/100)*1.1) -> 1965.2109 | L2: =F2*(1-G2/100) -> 1786.5554 | M2: =((K2*2.5)/(365*0.9))*1.21 -> 18.096691 | N2: =M2*30/100 -> 5.4290074 | O2: =(M2*6/100) -> 1.0858015 | P2: =L2*2/1000 -> 3.5731108 | Q2: =L2*3/1000 -> 5.3596662 | R2: =L2*1/1000 -> 1.7865554
A3: RRAS 6 | B3: CRS NORTE | C3: Freguesia do Ó / Brasilândia | D3: São Paulo | E3: Grande São Paulo | F3: 4571 | G3: 49.26 | H3: 21 | J3: 70.61 | K3: =(F3*(1-G3/100)*1.1) -> 2551.2579 | L3: =F3*(1-G3/100) -> 2319.3254 | M3: =((K3*2.5)/(365*0.9))*1.21 -> 23.493319 | N3: =M3*30/100 -> 7.0479957 | O3: =(M3*6/100) -> 1.4095991 | P3: =L3*2/1000 -> 4.6386508 | Q3: =L3*3/1000 -> 6.9579762 | R3: =L3*1/1000 -> 2.3193254
A4: RRAS 6 | B4: CRS NORTE | C4: Perus | D4: São Paulo | E4: Grande São Paulo | F4: 1996 | G4: 49.26 | H4: 7 | J4: 70.61 | K4: =(F4*(1-G4/100)*1.1) -> 1114.0474 | L4: =F4*(1-G4/100) -> 1012.7704 | M4: =((K4*2.5)/(365*0.9))*1.21 -> 10.258732 | N4: =M4*30/100 -> 3.0776196 | O4: =(M4*6/100) -> 0.61552393 | P4: =L4*2/1000 -> 2.0255408 | Q4: =L4*3/1000 -> 3.0383112 | R4: =L4*1/1000 -> 1.0127704
A5: RRAS 6 | B5: CRS NORTE | C5: Pirituba | D5: São Paulo | E5: Grande São Paulo | F5: 5317 | G5: 49.26 | H5: 22 | J5: 70.61 | K5: =(F5*(1-G5/100)*1.1) -> 2967.6304 | L5: =F5*(1-G5/100) -> 2697.8458 | M5: =((K5*2.5)/(365*0.9))*1.21 -> 27.327494 | N5: =M5*30/100 -> 8.1982483 | O5: =(M5*6/100) -> 1.6396497 | P5: =L5*2/1000 -> 5.3956916 | Q5: =L5*3/1000 -> 8.0935374 | R5: =L5*1/1000 -> 2.6978458
A6: RRAS 6 | B6: CRS NORTE | C6: Santana / Jaçanã | D6: São Paulo | E6: Grande São Paulo | F6: 6300 | G6: 49.26 | H6: 20 | J6: 70.61 | K6: =(F6*(1-G6/100)*1.1) -> 3516.282 | L6: =F6*(1-G6/100) -> 3196.62 | M6: =((K6*2.5)/(365*0.9))*1.21 -> 32.379766 | N6: =M6*30/100 -> 9.7139297 | O6: =(M6*6/100) -> 1.9427859 | P6: =L6*2/1000 -> 6.39324 | Q6: =L6*3/1000 -> 9.58986 | R6: =L6*1/1000 -> 3.19662
A7: RRAS 6 | B7: CRS NORTE | C7: Vila Maria / Vila Guilherme | D7: São Paulo | E7: Grande São Paulo | F7: 3682 | G7: 49.26 | H7: 13 | J7: 70.61 | K7: =(F7*(1-G7/100)*1.1) -> 2055.0715 | L7: =F7*(1-G7/100) -> 1868.2468 | M7: =((K7*2.5)/(365*0.9))*1.21 -> 18.924174 | N7: =M7*30/100 -> 5.6772523 | O7: =(M7*6/100) -> 1.1354505 | P7: =L7*2/1000 -> 3.7364936 | Q7: =L7*3/1000 -> 5.6047404 | R7: =L7*1/1000 -> 1.8682468
A8: RRAS 6 | B8: CRS SUL | C8: Capela do Socorro | D8: São Paulo | E8: Grande São Paulo | F8: 7472 | G8: 38.2 | H8: 26 | J8: 0.815 | K8: =(F8*(1-G8/100)*1.1) -> 5079.4656 | L8: =F8*(1-G8/100) -> 4617.696 | M8: =((K8*2.5)/(365*0.9))*1.21 -> 46.774379 | N8: =M8*30/100 -> 14.032314 | O8: =(M8*6/100) -> 2.8064627 | P8: =L8*2/1000 -> 9.235392 | Q8: =L8*3/1000 -> 13.853088 | R8: =L8*1/1000 -> 4.617696
A9: RRAS 6 | B9: CRS SUL | C9: Parelheiros | D9: São Paulo | E9: Grande São Paulo | F9: 2290 | G9: 25.3 | H9: 19 | J9: 1.116 | K9: =(F9*(1-G9/100)*1.1) -> 1881.693 | L9: =F9*(1-G9/100) -> 1710.63 | M9: =((K9*2.5)/(365*0.9))*1.21 -> 17.327614 | N9: =M9*30/100 -> 5.1982843 | O9: =(M9*6/100) -> 1.0396569 | P9: =L9*2/1000 -> 3.42126 | Q9: =L9*3/1000 -> 5.13189 | R9: =L9*1/1000 -> 1.71063
A10: RRAS 6 | B10: CRS SUL | C10: Santo Amaro / Cidade Ademar | D10: São Paulo | E10: Grande São Paulo | F10: 7395 | G10: 42.7 | H10: 27 | J10: 0.712 | K10: =(F10*(1-G10/100)*1.1) -> 4661.0685 | L10: =F10*(1-G10/100) -> 4237.335 | M10: =((K10*2.5)/(365*0.9))*1.21 -> 42.921559 | N10: =M10*30/100 -> 12.876468 | O10: =(M10*6/100) -> 2.5752936 | P10: =L10*2/1000 -> 8.47467 | Q10: =L10*3/1000 -> 12.712005 | R10: =L10*1/1000 -> 4.237335
A11: RRAS 6 | B11: CRS SUL | C11: M Boi Mirim | D11: São Paulo | E11: Grande São Paulo | F11: 7328 | G11: 30.6 | H11: 30 | J11: 1.112 | K11: =(F11*(1-G11/100)*1.1) -> 5594.1952 | L11: =F11*(1-G11/100) -> 5085.632 | M11: =((K11*2.5)/(365*0.9))*1.21 -> 51.514278 | N11: =M11*30/100 -> 15.454284 | O11: =(M11*6/100) -> 3.0908567 | P11: =L11*2/1000 -> 10.171264 | Q11: =L11*3/1000 -> 15.256896 | R11: =L11*1/1000 -> 5.085632
A12: RRAS 6 | B12: CRS SUL | C12: Campo Limpo | D12: São Paulo | E12: Grande São Paulo | F12: 7942 | G12: 39.6 | H12: 26 | J12: 0.934 | K12: =(F12*(1-G12/100)*1.1) -> 5276.6648 | L12: =F12*(1-G12/100) -> 4796.968 | M12: =((K12*2.5)/(365*0.9))*1.21 -> 48.590292 | N12: =M12*30/100 -> 14.577088 | O12: =(M12*6/100) -> 2.9154175 | P12: =L12*2/1000 -> 9.593936 | Q12: =L12*3/1000 -> 14.390904 | R12: =L12*1/1000 -> 4.796968
A13: RRAS 6 | B13: CRS LESTE | C13: Cidade Tiradentes | D13: São Paulo | E13: Grande São Paulo | F13: 2684 | G13: 50.74 | H13: 13 | J13: 70.3 | K13: =(F13*(1-G13/100)*1.1) -> 1454.3522 | L13: =F13*(1-G13/100) -> 1322.1384 | M13: =((K13*2.5)/(365*0.9))*1.21 -> 13.392437 | N13: =M13*30/100 -> 4.0177311 | O13: =(M13*6/100) -> 0.80354621 | P13: =L13*2/1000 -> 2.6442768 | Q13: =L13*3/1000 -> 3.9664152 | R13: =L13*1/1000 -> 1.3221384
... A28: RRAS 6 | B28: CRS SUDESTE | C28: Penha | D28: São Paulo | E28: Grande São Paulo | F28: 5004 | G28: 45.4 | H28: 20 | J28: 61.4 | K28: =(F28*(1-G28/100)*1.1) -> 3005.4024 | L28: =F28*(1-G28/100) -> 2732.184 | M28: =((K28*2.5)/(365*0.9))*1.21 -> 27.675319 | N28: =M28*30/100 -> 8.3025957 | O28: =(M28*6/100) -> 1.6605191 | P28: =L28*2/1000 -> 5.464368 | Q28: =L28*3/1000 -> 8.196552 | R28: =L28*1/1000 -> 2.732184

Sheet Tabela 1 APS - Ref. AAE + BR
A1: RRAS | B1: DRS | C1: REGIÃO DE SAÚDE | D1: MUNICÍPIO DA RRAS | E1: CNES | F1: NOME DO ESTABELECIMENTO | G1: MUNICÍPIO DO ESTABELECIMENTO | H1: TIPO DE ATENDIMENTO
A2: RRAS 1 | B2: Grande São Paulo | C2: Grande ABC | D2: Diadema | E2: 5851084 | F2: Quarteirão da Saúde - Eng. Osvaldo Misso | G2: Diadema | H2: AAE
A3: RRAS 1 | B3: Grande São Paulo | C3: Grande ABC | D3: Mauá | E3: 2082349 | F3: Hospital de Clínicas Dr. Radamés Nardini | G3: Mauá | H3: AAE
A4: RRAS 1 | B4: Grande São Paulo | C4: Grande ABC | D4: Ribeirão Pires | E4: 2906562 | F4: CAISM - Centro de Atenção Integral a Saúde da Mulher | G4: Ribeirão Pires | H4: AAE
A5: RRAS 1 | B5: Grande São Paulo | C5: Grande ABC | D5: Rio Grande da Serra | E5: 2906562 | F5: CAISM - Centro de Atenção Integral a Saúde da Mulher | G5: Ribeirão Pires | H5: AAE
A6: RRAS 1 | B6: Grande São Paulo | C6: Grande ABC | D6: Santo André | E6: 6020917 | F6: Hospital da Mulher - Maria José dos Santos Stein | G6: Santo André | H6: AAE
A7: RRAS 1 | B7: Grande São Paulo | C7: Grande ABC | D7: São Bernardo do Campo | E7: 2035081 | F7: CAISM - Centro de Atenção Integral a Saúde da Mulher | G7: São Bernardo do Campo | H7: AAE
A8: RRAS 1 | B8: Grande São Paulo | C8: Grande ABC | D8: São Caetano do Sul | E8: 2038196 | F8: CAISM - Centro de Atenção Integral a Saúde da Mulher Sc do Sul | G8: São Caetano do Sul | H8: AAE
A9: RRAS 2 | B9: Grande São Paulo | C9: Alto Tietê | D9: Arujá | E9: 9001808 | F9: UBS Fazenda Rincão | G9: Arujá | H9: AAE
A10: RRAS 2 | B10: Grande São Paulo | C10: Alto Tietê | D10: Arujá | E10: 2059304 | F10: USF Jd. Emília | G10: Arujá | H10: AAE
A11: RRAS 2 | B11: Grande São Paulo | C11: Alto Tietê | D11: Arujá | E11: 2773848 | F11: USF Mirante | G11: Arujá | H11: AAE
A12: RRAS 2 | B12: Grande São Paulo | C12: Alto Tietê | D12: Arujá | E12: 2773228 | F12: UBS Vila Pilar | G12: Arujá | H12: AAE
A13: RRAS 2 | B13: Grande São Paulo | C13: Alto Tietê | D13: Arujá | E13: 2773856 | F13: USF Barreto Arujá | G13: Arujá | H13: AAE
... A52: RRAS 4 | B52: Grande São Paulo | C52: Mananciais | D52: Vargem Grande Paulista | E52: 7079877 | F52: Centro de Referência da Mulher de Vargem Grande Paulista | G52: Vargem Grande Paulista | H52: AAE
A53: RRAS 5 | B53: Grande São Paulo | C53: Rota dos Bandeirantes | D53: Barueri | E53: 04 | F53: UBS Referência | G53: Barueri | H53: AAE
A54: RRAS 5 | B54: Grande São Paulo | C54: Rota dos Bandeirantes | D54: Carapicuíba | E54: 2792168 | F54: Hospital Geral de Carapicuíba | G54: Carapicuíba | H54: AAE
A55: RRAS 5 | B55: Grande São Paulo | C55: Rota dos Bandeirantes | D55: Itapevi | E55: 9102159 | F55: Centro de Referência da Saúde da Mulher Thereza Farias Santos | G55: Itapevi | H55: AAE
A56: RRAS 5 | B56: Grande São Paulo | C56: Rota dos Bandeirantes | D56: Itapevi | E56: 9454276 | F56: CIS Centro Integrado de Saúde | G56: Itapevi | H56: AAE
A57: RRAS 5 | B57: Grande São Paulo | C57: Rota dos Bandeirantes | D57: Jandira | E57: 5437350 | F57: Centro de Referência da Mulher | G57: Jandira | H57: AAE
A58: RRAS 5 | B58: Grande São Paulo | C58: Rota dos Bandeirantes | D58: Osasco | E58: 3815919 | F58: Casa da Mulher Dinalva Souza Barcellos | G58: Osasco | H58: AAE
A59: RRAS 5 | B59: Grande São Paulo | C59: Rota dos Bandeirantes | D59: Pirapora do Bom Jesus | E59: 2792168 | F59: Hospital Geral de Carapicuíba | G59: Carapicuíba | H59: AAE
A60: RRAS 5 | B60: Grande São Paulo | C60: Rota dos Bandeirantes | D60: Santana de Parnaíba | E60: 7444249 | F60: Centro de Saúde da Mulher Parnaibana | G60: Santana de Parnaíba | H60: AAE
A61: RRAS 7 | B61: Baixada Santista | C61: Baixada Santista | D61: Bertioga | E61: 2079720 | F61: Hospital Guilherme Alvaro Santos | G61: Santos / Bertioga | H61: AAE
A62: RRAS 7 | B62: Baixada Santista | C62: Baixada Santista | D62: Bertioga | E62: 473405 | F62: Centro Especializado em Saúde da Mulher | G62: Santos / Bertioga | H62: AAE
A63: RRAS 7 | B63: Baixada Santista | C63: Baixada Santista | D63: Cubatão | E63: 2071843 | F63: SAISM - Serviço de Atenção Integral à Saúde da Mulher | G63: Cubatão | H63: AAE
A64: RRAS 7 | B64: Baixada Santista | C64: Baixada Santista | D64: Guarujá | E64: 9663851 | F64: Instituto da Mulher Casa Rosa | G64: Guarujá | H64: AAE
A65: RRAS 7 | B65: Baixada Santista | C65: Baixada Santista | D65: Itanhaém | E65: 6345581 | F65: Centro Especializado na Saúde da Criança e da Mulher Paula V – CESCRIM | G65: Itanhaém / Praia Grande | H65: AAE
... A139: RRAS 9 | B139: Bauru | C139: Polo Cuesta | D139: Torre de Pedra | E139: 2748223 | F139: HC da FM de Botucatu | G139: Botucatu | H139: AAE
A140: RRAS 9 | B140: Bauru | C140: Vale do Jurumirim | D140: Águas de Santa Bárbara | E140: 2748223 | F140: HC da FM de Botucatu | G140: Botucatu / Avaré | H140: AAE
A141: RRAS 9 | B141: Bauru | C141: Vale do Jurumirim | D141: Águas de Santa Bárbara | E141: 2831503 | F141: AME Vale do Jurumirim | G141: Botucatu / Avaré | H141: AAE
A142: RRAS 9 | B142: Bauru | C142: Vale do Jurumirim | D142: Arandu | E142: 2748223 | F142: HC da FM de Botucatu | G142: Botucatu / Avaré | H142: AAE
A143: RRAS 9 | B143: Bauru | C143: Vale do Jurumirim | D143: Arandu | E143: 2831503 | F143: AME Vale do Jurumirim | G143: Botucatu / Avaré | H143: AAE
A144: RRAS 9 | B144: Bauru | C144: Vale do Jurumirim | D144: Avaré | E144: 2748223 | F144: HC da FM de Botucatu | G144: Botucatu / Avaré | H144: AAE
A145: RRAS 9 | B145: Bauru | C145: Vale do Jurumirim | D145: Avaré | E145: 2831503 | F145: AME Vale do Jurumirim | G145: Botucatu / Avaré | H145: AAE
A146: RRAS 9 | B146: Bauru | C146: Vale do Jurumirim | D146: Barão de Antonina | E146: 2748223 | F146: HC da FM de Botucatu | G146: Botucatu | H146: AAE
A147: RRAS 9 | B147: Bauru | C147: Vale do Jurumirim | D147: Cerqueira César | E147: 2748223 | F147: HC da FM de Botucatu | G147: Botucatu / Avaré | H147: AAE
A148: RRAS 9 | B148: Bauru | C148: Vale do Jurumirim | D148: Cerqueira César | E148: 2831503 | F148: AME Vale do Jurumirim | G148: Botucatu / Avaré | H148: AAE
A149: RRAS 9 | B149: Bauru | C149: Vale do Jurumirim | D149: Coronel Macedo | E149: 2748223 | F149: HC da FM de Botucatu | G149: Botucatu / Avaré | H149: AAE
A150: RRAS 9 | B150: Bauru | C150: Vale do Jurumirim | D150: Coronel Macedo | E150: 2831503 | F150: AME Vale do Jurumirim | G150: Botucatu / Avaré | H150: AAE
A151: RRAS 9 | B151: Bauru | C151: Vale do Jurumirim | D151: Fartura | E151: 2748223 | F151: HC da FM de Botucatu | G151: Botucatu / Avaré | H151: AAE
...

Sheet RRAS 6 - Tabela 1 Ref. AAE + BR
A1: RRAS | B1: COORDENADORIA DE SAÚDE | C1: SUPERVISÃO DE SAÚDE | D1: MUNICÍPIO DA RRAS | E1: DRS | F1: CNES | G1: NOME DO ESTABELECIMENTO | H1: MUNICÍPIO DO ESTABELECIMENTO | I1: TIPO DE ATENDIMENTO
A2: RRAS 6 | B2: CRS NORTE | C2: Casa Verde / Cachoeirinha | D2: São Paulo | E2: Grande São Paulo | F2: 2077574 | G2: Conjunto Hospitalar do Mandaqui São Paulo | H2: São Paulo | I2: AAE
A3: RRAS 6 | B3: CRS NORTE | C3: Casa Verde / Cachoeirinha | D3: São Paulo | E3: Grande São Paulo | F3: 2079186 | G3: Hospital Municipal Maternidade Esc. Dr. Mario de Moraes A. Silva | H3: São Paulo | I3: AAE
A4: RRAS 6 | B4: CRS NORTE | C4: Freguesia do Ó / Brasilândia | D4: São Paulo | E4: Grande São Paulo | F4: 2082225 | G4: Hospital Kátia de Souza Rodrigues Taipas São Paulo | H4: São Paulo | I4: AAE
A5: RRAS 6 | B5: CRS NORTE | C5: Freguesia do Ó / Brasilândia | D5: São Paulo | E5: Grande São Paulo | F5: 2079186 | G5: Hospital Municipal Maternidade Esc. Dr. Mario de Moraes A. Silva | H5: São Paulo | I5: AAE
A6: RRAS 6 | B6: CRS NORTE | C6: Perus | D6: São Paulo | E6: Grande São Paulo | F6: 2082225 | G6: Hospital Kátia de Souza Rodrigues Taipas São Paulo | H6: São Paulo | I6: AAE
A7: RRAS 6 | B7: CRS NORTE | C7: Pirituba | D7: São Paulo | E7: Grande São Paulo | F7: 2082225 | G7: Hospital Kátia de Souza Rodrigues Taipas São Paulo | H7: São Paulo | I7: AAE
A8: RRAS 6 | B8: CRS NORTE | C8: Pirituba | D8: São Paulo | E8: Grande São Paulo | F8: 2079186 | G8: Hospital Municipal Maternidade Esc. Dr. Mario de Moraes A. Silva | H8: São Paulo | I8: AAE
A9: RRAS 6 | B9: CRS NORTE | C9: Santana / Jaçanã | D9: São Paulo | E9: Grande São Paulo | F9: 2077574 | G9: Conjunto Hospitalar do Mandaqui São Paulo | H9: São Paulo | I9: AAE
A10: RRAS 6 | B10: CRS NORTE | C10: Santana / Jaçanã | D10: São Paulo | E10: Grande São Paulo | F10: 2076896 | G10: Hospital São Luiz Gonzaga | H10: São Paulo | I10: AAE
A11: RRAS 6 | B11: CRS NORTE | C11: Vila Maria / Vila Guilherme | D11: São Paulo | E11: Grande São Paulo | F11: 3212130 | G11: Hospital Municipal Vereador José Storopolli | H11: São Paulo | I11: AAE
A12: RRAS 6 | B12: CRS SUL | C12: Capela do Socorro | D12: São Paulo | E12: Grande São Paulo | F12: 2065665 | G12: Hospital Maternidade Interlagos | H12: São Paulo | I12: AAE
A13: RRAS 6 | B13: CRS SUL | C13: Capela do Socorro | D13: São Paulo | E13: Grande São Paulo | F13: 2751887 | G13: UBS Jd. Cliper | H13: São Paulo | I13: AAE
... A100: RRAS 6 | B100: CRS SUDESTE | C100: Penha | D100: São Paulo | E100: Grande São Paulo | F100: 2077701 | G100: Hospital e Maternidade Leonor Mendes de Barros | H100: São Paulo | I100: BR

Sheet Tabela 1 APS + Leitos Nec. TOTA
A1: RRAS | B1: NASCIDOS VIVOS | C1: COBERTURA ANS (%) | D1: Nº DE UBS | E1: COBERTURA ESF (%) | F1: COBERTURA AB (%) | G1: GESTANTES SUSDEPENDENTES ESTIMADAS/ANO | H1: NASCIDOS VIVOS SUSDEPENDENTES ESTIMADOS/ANO | I1: LEITOS OBSTÉTRICOS | J1: LEITOS GAR PARA ATENDER AS GESTANTES SUSDEPENDENTES DO MUNICÍPIO - RRAS | K1: LEITOS UTI ADULTO | L1: LEITOS UTIN | M1: LEITOS UCINCO | N1: LEITOS UCINCA | O1: CPN I: 3 LEITOS | P1: CPN I: 5 LEITOS | Q1: CPN II: 3 LEITOS | R1: CPN II: 5 LEITOS | S1: CGBP: 10 LEITOS | T1: CGBP: 15 LEITOS | U1: CGBP: 20 LEITOS | V1: BLH
A2: RRAS 1 | B2: =SUM('Tabela 1 APS + Leitos Nec.'!E2:E8) -> 26678 | C2: 52.99 | D2: =SUM('Tabela 1 APS + Leitos Nec.'!G2:G8) -> 142 | E2: 47.73 | F2: 62.48 | G2: =(B2*(1-C2/100)*1.1) -> 13795.461 | H2: =B2*(1-C2/100) -> 12541.328 | I2: =((G2*2.5)/(365*0.9))*1.21 -> 127.03582 | J2: =I2*30/100 -> 38.110747 | K2: =(I2*6/100) -> 7.6221495 | L2: =H2*2/1000 -> 25.082656 | M2: =H2*3/1000 -> 37.623983 | N2: =H2*1/1000 -> 12.541328 | O2: =SUM('Tabela 1 APS + Leitos Nec.'!R2:R8) -> 2 | P2: =SUM('Tabela 1 APS + Leitos Nec.'!S2:S8) -> 0 | Q2: =SUM('Tabela 1 APS + Leitos Nec.'!T2:T8) -> 0 | R2: =SUM('Tabela 1 APS + Leitos Nec.'!U2:U8) -> 2 | S2: =SUM('Tabela 1 APS + Leitos Nec.'!V2:V8) -> 1 | T2: =SUM('Tabela 1 APS + Leitos Nec.'!W2:W8) -> 0 | U2: =SUM('Tabela 1 APS + Leitos Nec.'!X2:X8) -> 1 | V2: =SUM('Tabela 1 APS + Leitos Nec.'!Y2:Y8) -> 0
A3: RRAS 2 | B3: =SUM('Tabela 1 APS + Leitos Nec.'!E9:E19) -> 37990 | C3: 32.75 | D3: =SUM('Tabela 1 APS + Leitos Nec.'!G9:G19) -> 200 | E3: 25.83 | F3: 44.02 | G3: =(B3*(1-C3/100)*1.1) -> 28103.103 | H3: =B3*(1-C3/100) -> 25548.275 | I3: =((G3*2.5)/(365*0.9))*1.21 -> 258.78808 | J3: =I3*30/100 -> 77.636425 | K3: =(I3*6/100) -> 15.527285 | L3: =H3*2/1000 -> 51.09655 | M3: =H3*3/1000 -> 76.644825 | N3: =H3*1/1000 -> 25.548275 | O3: =SUM('Tabela 1 APS + Leitos Nec.'!R9:R19) -> 0 | P3: =SUM('Tabela 1 APS + Leitos Nec.'!S9:S19) -> 0 | Q3: =SUM('Tabela 1 APS + Leitos Nec.'!T9:T19) -> 0 | R3: =SUM('Tabela 1 APS + Leitos Nec.'!U9:U19) -> 0 | S3: =SUM('Tabela 1 APS + Leitos Nec.'!V9:V19) -> 0 | T3: =SUM('Tabela 1 APS + Leitos Nec.'!W9:W19) -> 0 | U3: =SUM('Tabela 1 APS + Leitos Nec.'!X9:X19) -> 0 | V3: =SUM('Tabela 1 APS + Leitos Nec.'!Y9:Y19) -> 2
A4: RRAS 3 | B4: =SUM('Tabela 1 APS + Leitos Nec.'!E20:E24) -> 7682 | C4: 29.92 | D4: =SUM('Tabela 1 APS + Leitos Nec.'!G20:G24) -> 69 | E4: 41.94 | F4: 63.74 | G4: =(B4*(1-C4/100)*1.1) -> 5921.9002 | H4: =B4*(1-C4/100) -> 5383.5456 | I4: =((G4*2.5)/(365*0.9))*1.21 -> 54.531957 | J4: =I4*30/100 -> 16.359587 | K4: =(I4*6/100) -> 3.2719174 | L4: =H4*2/1000 -> 10.767091 | M4: =H4*3/1000 -> 16.150637 | N4: =H4*1/1000 -> 5.3835456 | O4: =SUM('Tabela 1 APS + Leitos Nec.'!R20:R24) -> 0 | P4: =SUM('Tabela 1 APS + Leitos Nec.'!S20:S24) -> 0 | Q4: =SUM('Tabela 1 APS + Leitos Nec.'!T20:T24) -> 0 | R4: =SUM('Tabela 1 APS + Leitos Nec.'!U20:U24) -> 0 | S4: =SUM('Tabela 1 APS + Leitos Nec.'!V20:V24) -> 0 | T4: =SUM('Tabela 1 APS + Leitos Nec.'!W20:W24) -> 0 | U4: =SUM('Tabela 1 APS + Leitos Nec.'!X20:X24) -> 0 | V4: =SUM('Tabela 1 APS + Leitos Nec.'!Y20:Y24) -> 0
A5: RRAS 4 | B5: =SUM('Tabela 1 APS + Leitos Nec.'!E25:E32) -> 14182 | C5: 29.3 | D5: =SUM('Tabela 1 APS + Leitos Nec.'!G25:G32) -> 99 | E5: 23.84 | F5: 52.04 | G5: =(B5*(1-C5/100)*1.1) -> 11029.341 | H5: =B5*(1-C5/100) -> 10026.674 | I5: =((G5*2.5)/(365*0.9))*1.21 -> 101.56395 | J5: =I5*30/100 -> 30.469185 | K5: =(I5*6/100) -> 6.093837 | L5: =H5*2/1000 -> 20.053348 | M5: =H5*3/1000 -> 30.080022 | N5: =H5*1/1000 -> 10.026674 | O5: =SUM('Tabela 1 APS + Leitos Nec.'!R25:R32) -> 0 | P5: =SUM('Tabela 1 APS + Leitos Nec.'!S25:S32) -> 0 | Q5: =SUM('Tabela 1 APS + Leitos Nec.'!T25:T32) -> 0 | R5: =SUM('Tabela 1 APS + Leitos Nec.'!U25:U32) -> 0 | S5: =SUM('Tabela 1 APS + Leitos Nec.'!V25:V32) -> 0 | T5: =SUM('Tabela 1 APS + Leitos Nec.'!W25:W32) -> 0 | U5: =SUM('Tabela 1 APS + Leitos Nec.'!X25:X32) -> 0 | V5: =SUM('Tabela 1 APS + Leitos Nec.'!Y25:Y32) -> 0
A6: RRAS 5 | B6: =SUM('Tabela 1 APS + Leitos Nec.'!E33:E39) -> 25483 | C6: 40.78 | D6: =SUM('Tabela 1 APS + Leitos Nec.'!G33:G39) -> 112 | E6: 14.2 | F6: 48.46 | G6: =(B6*(1-C6/100)*1.1) -> 16600.136 | H6: =B6*(1-C6/100) -> 15091.033 | I6: =((G6*2.5)/(365*0.9))*1.21 -> 152.86274 | J6: =I6*30/100 -> 45.858823 | K6: =(I6*6/100) -> 9.1717646 | L6: =H6*2/1000 -> 30.182065 | M6: =H6*3/1000 -> 45.273098 | N6: =H6*1/1000 -> 15.091033 | O6: =SUM('Tabela 1 APS + Leitos Nec.'!R33:R39) -> 0 | P6: =SUM('Tabela 1 APS + Leitos Nec.'!S33:S39) -> 0 | Q6: =SUM('Tabela 1 APS + Leitos Nec.'!T33:T39) -> 0 | R6: =SUM('Tabela 1 APS + Leitos Nec.'!U33:U39) -> 0 | S6: =SUM('Tabela 1 APS + Leitos Nec.'!V33:V39) -> 0 | T6: =SUM('Tabela 1 APS + Leitos Nec.'!W33:W39) -> 0 | U6: =SUM('Tabela 1 APS + Leitos Nec.'!X33:X39) -> 0 | V6: =SUM('Tabela 1 APS + Leitos Nec.'!Y33:Y39) -> 0
A7: RRAS 6 | B7: =SUM('RRAS 6 - Tabela 1 APS + Leitos '!F2:F28) -> 128654 | C7: 51 | D7: =SUM('RRAS 6 - Tabela 1 APS + Leitos '!H2:H28) -> 475 | F7: 70.6 | G7: =(B7*(1-C7/100)*1.1) -> 69344.506 | H7: =B7*(1-C7/100) -> 63040.46 | I7: =((G7*2.5)/(365*0.9))*1.21 -> 638.56052 | J7: =I7*30/100 -> 191.56816 | K7: =(I7*6/100) -> 38.313631 | L7: =H7*2/1000 -> 126.08092 | M7: =H7*3/1000 -> 189.12138 | N7: =H7*1/1000 -> 63.04046 | O7: =SUM('Tabela 1 APS + Leitos Nec.'!R34:R40) -> 0 | P7: =SUM('Tabela 1 APS + Leitos Nec.'!S34:S40) -> 0 | Q7: =SUM('Tabela 1 APS + Leitos Nec.'!T34:T40) -> 0 | R7: =SUM('Tabela 1 APS + Leitos Nec.'!U34:U40) -> 0 | S7: =SUM('Tabela 1 APS + Leitos Nec.'!V34:V40) -> 0 | T7: =SUM('Tabela 1 APS + Leitos Nec.'!W34:W40) -> 0 | U7: =SUM('Tabela 1 APS + Leitos Nec.'!X34:X40) -> 0 | V7: =SUM('Tabela 1 APS + Leitos Nec.'!Y34:Y40) -> 0
A8: RRAS 7 - BAIXADA SANTISTA | B8: =SUM('Tabela 1 APS + Leitos Nec.'!E40:E48) -> 20163 | C8: 40.11 | D8: =SUM('Tabela 1 APS + Leitos Nec.'!G40:G48) -> 181 | E8: 44.76 | F8: 60.87 | G8: =(B8*(1-C8/100)*1.1) -> 13283.183 | H8: =B8*(1-C8/100) -> 12075.621 | I8: =((G8*2.5)/(365*0.9))*1.21 -> 122.3185 | J8: =I8*30/100 -> 36.695551 | K8: =(I8*6/100) -> 7.3391101 | L8: =H8*2/1000 -> 24.151241 | M8: =H8*3/1000 -> 36.226862 | N8: =H8*1/1000 -> 12.075621 | O8: =SUM('Tabela 1 APS + Leitos Nec.'!R40:R48) -> 2 | P8: =SUM('Tabela 1 APS + Leitos Nec.'!S40:S48) -> 3 | Q8: =SUM('Tabela 1 APS + Leitos Nec.'!T40:T48) -> 1 | R8: =SUM('Tabela 1 APS + Leitos Nec.'!U40:U48) -> 1 | S8: =SUM('Tabela 1 APS + Leitos Nec.'!V40:V48) -> 0 | T8: =SUM('Tabela 1 APS + Leitos Nec.'!W40:W48) -> 0 | U8: =SUM('Tabela 1 APS + Leitos Nec.'!X40:X48) -> 0 | V8: =SUM('Tabela 1 APS + Leitos Nec.'!Y40:Y48) -> 3
A9: RRAS 7 - REGISTRO | B9: =SUM('Tabela 1 APS + Leitos Nec.'!E49:E63) -> 3340 | C9: 9.19 | D9: =SUM('Tabela 1 APS + Leitos Nec.'!G49:G63) -> 107 | E9: 93.16 | F9: 96.89 | G9: =(B9*(1-C9/100)*1.1) -> 3336.3594 | H9: =B9*(1-C9/100) -> 3033.054 | I9: =((G9*2.5)/(365*0.9))*1.21 -> 30.722944 | J9: =I9*30/100 -> 9.2168833 | K9: =(I9*6/100) -> 1.8433767 | L9: =H9*2/1000 -> 6.066108 | M9: =H9*3/1000 -> 9.099162 | N9: =H9*1/1000 -> 3.033054 | O9: =SUM('Tabela 1 APS + Leitos Nec.'!R49:R63) -> 0 | P9: =SUM('Tabela 1 APS + Leitos Nec.'!S49:S63) -> 0 | Q9: =SUM('Tabela 1 APS + Leitos Nec.'!T49:T63) -> 0 | R9: =SUM('Tabela 1 APS + Leitos Nec.'!U49:U63) -> 0 | S9: =SUM('Tabela 1 APS + Leitos Nec.'!V49:V63) -> 10 | T9: =SUM('Tabela 1 APS + Leitos Nec.'!W49:W63) -> 0 | U9: =SUM('Tabela 1 APS + Leitos Nec.'!X49:X63) -> 0 | V9: =SUM('Tabela 1 APS + Leitos Nec.'!Y49:Y63) -> 0
A10: RRAS 8 | B10: =SUM('Tabela 1 APS + Leitos Nec.'!E64:E111) -> 30995 | C10: 31.2 | D10: =SUM('Tabela 1 APS + Leitos Nec.'!G64:G111) -> 333 | E10: 28.47 | F10: 53.5 | G10: =(B10*(1-C10/100)*1.1) -> 23457.016 | H10: =B10*(1-C10/100) -> 21324.56 | I10: =((G10*2.5)/(365*0.9))*1.21 -> 216.00449 | J10: =I10*30/100 -> 64.801346 | K10: =(I10*6/100) -> 12.960269 | L10: =H10*2/1000 -> 42.64912 | M10: =H10*3/1000 -> 63.97368 | N10: =H10*1/1000 -> 21.32456 | O10: =SUM('Tabela 1 APS + Leitos Nec.'!R64:R111) -> 0 | P10: =SUM('Tabela 1 APS + Leitos Nec.'!S64:S111) -> 0 | Q10: =SUM('Tabela 1 APS + Leitos Nec.'!T64:T111) -> 0 | R10: =SUM('Tabela 1 APS + Leitos Nec.'!U64:U111) -> 0 | S10: =SUM('Tabela 1 APS + Leitos Nec.'!V64:V111) -> 0 | T10: =SUM('Tabela 1 APS + Leitos Nec.'!W64:W111) -> 0 | U10: =SUM('Tabela 1 APS + Leitos Nec.'!X64:X111) -> 0 | V10: =SUM('Tabela 1 APS + Leitos Nec.'!Y64:Y111) -> 0
A11: RRAS 9 | B11: =SUM('Tabela 1 APS + Leitos Nec.'!E112:E179) -> 19277 | C11: 25.29 | D11: =SUM('Tabela 1 APS + Leitos Nec.'!G112:G179) -> 333 | E11: 39.23 | F11: 64.13 | G11: =(B11*(1-C11/100)*1.1) -> 15842.031 | H11: =B11*(1-C11/100) -> 14401.847 | I11: =((G11*2.5)/(365*0.9))*1.21 -> 145.88172 | J11: =I11*30/100 -> 43.764516 | K11: =(I11*6/100) -> 8.7529032 | L11: =H11*2/1000 -> 28.803693 | M11: =H11*3/1000 -> 43.20554 | N11: =H11*1/1000 -> 14.401847 | O11: =SUM('Tabela 1 APS + Leitos Nec.'!R112:R179) -> 0 | P11: =SUM('Tabela 1 APS + Leitos Nec.'!S112:S179) -> 0 | Q11: =SUM('Tabela 1 APS + Leitos Nec.'!T112:T179) -> 0 | R11: =SUM('Tabela 1 APS + Leitos Nec.'!U112:U179) -> 0 | S11: =SUM('Tabela 1 APS + Leitos Nec.'!V112:V179) -> 0 | T11: =SUM('Tabela 1 APS + Leitos Nec.'!W112:W179) -> 0 | U11: =SUM('Tabela 1 APS + Leitos Nec.'!X112:X179) -> 0 | V11: =SUM('Tabela 1 APS + Leitos Nec.'!Y112:Y179) -> 0
A12: RRAS 10 | B12: =SUM('Tabela 1 APS + Leitos Nec.'!E180:E241) -> 11660 | C12: 22.71 | D12: =SUM('Tabela 1 APS + Leitos Nec.'!G180:G241) -> 272 | E12: 53.76 | F12: 77.36 | G12: =(B12*(1-C12/100)*1.1) -> 9913.2154 | H12: =B12*(1-C12/100) -> 9012.014 | I12: =((G12*2.5)/(365*0.9))*1.21 -> 91.286078 | J12: =I12*30/100 -> 27.385823 | K12: =(I12*6/100) -> 5.4771647 | L12: =H12*2/1000 -> 18.024028 | M12: =H12*3/1000 -> 27.036042 | N12: =H12*1/1000 -> 9.012014 | O12: =SUM('Tabela 1 APS + Leitos Nec.'!R180:R241) -> 0 | P12: =SUM('Tabela 1 APS + Leitos Nec.'!S180:S241) -> 0 | Q12: =SUM('Tabela 1 APS + Leitos Nec.'!T180:T241) -> 0 | R12: =SUM('Tabela 1 APS + Leitos Nec.'!U180:U241) -> 0 | S12: =SUM('Tabela 1 APS + Leitos Nec.'!V180:V241) -> 0 | T12: =SUM('Tabela 1 APS + Leitos Nec.'!W180:W241) -> 0 | U12: =SUM('Tabela 1 APS + Leitos Nec.'!X180:X241) -> 0 | V12: =SUM('Tabela 1 APS + Leitos Nec.'!Y180:Y241) -> 0
A13: RRAS 11 | B13: =SUM('Tabela 1 APS + Leitos Nec.'!E242:E286) -> 7764 | C13: 25.53 | D13: =SUM('Tabela 1 APS + Leitos Nec.'!G242:G286) -> 221 | E13: 63.54 | F13: 72.74 | G13: =(B13*(1-C13/100)*1.1) -> 6360.0359 | H13: =B13*(1-C13/100) -> 5781.8508 | I13: =((G13*2.5)/(365*0.9))*1.21 -> 58.56654 | J13: =I13*30/100 -> 17.569962 | K13: =(I13*6/100) -> 3.5139924 | L13: =H13*2/1000 -> 11.563702 | M13: =H13*3/1000 -> 17.345552 | N13: =H13*1/1000 -> 5.7818508 | O13: 0 | P13: 0 | Q13: 0 | R13: 1 | S13: 1 | T13: 0 | U13: 0 | V13: 1
A14: RRAS 12 - ARAÇATUBA | B14: =SUM('Tabela 1 APS + Leitos Nec.'!E287:E326) -> 7449 | C14: 24.94 | D14: =SUM('Tabela 1 APS + Leitos Nec.'!G287:G326) -> 118 | E14: 73.28 | F14: 85.53 | G14: =(B14*(1-C14/100)*1.1) -> 6150.3413 | H14: =B14*(1-C14/100) -> 5591.2194 | I14: =((G14*2.5)/(365*0.9))*1.21 -> 56.635563 | J14: =I14*30/100 -> 16.990669 | K14: =(I14*6/100) -> 3.3981338 | L14: =H14*2/1000 -> 11.182439 | M14: =H14*3/1000 -> 16.773658 | N14: =H14*1/1000 -> 5.5912194 | O14: 1 | P14: 0 | Q14: 0 | R14: 1 | S14: 1 | T14: 0 | U14: 0 | V14: 2
A15: RRAS 12 - SÃO JOSÉ DO RIO PRETO | B15: =SUM('Tabela 1 APS + Leitos Nec.'!E327:E428) -> 17021 | C15: 32.42 | D15: =SUM('Tabela 1 APS + Leitos Nec.'!G327:G428) -> 321 | E15: 49.7 | F15: 69.31 | G15: =(B15*(1-C15/100)*1.1) -> 12653.071 | H15: =B15*(1-C15/100) -> 11502.792 | I15: =((G15*2.5)/(365*0.9))*1.21 -> 116.5161 | J15: =I15*30/100 -> 34.954831 | K15: =(I15*6/100) -> 6.9909662 | L15: =H15*2/1000 -> 23.005584 | M15: =H15*3/1000 -> 34.508375 | N15: =H15*1/1000 -> 11.502792 | O15: 3 | P15: 0 | Q15: 0 | R15: 0 | S15: 1 | T15: 0 | U15: 1 | V15: 4
A16: RRAS 13 - BARRETOS | B16: =SUM('Tabela 1 APS + Leitos Nec.'!E429:E446) -> 4663 | C16: 30.63 | D16: =SUM('Tabela 1 APS + Leitos Nec.'!G429:G446) -> 95 | E16: 57.72 | F16: 73.93 | G16: =(B16*(1-C16/100)*1.1) -> 3558.1954 | H16: =B16*(1-C16/100) -> 3234.7231 | I16: =((G16*2.5)/(365*0.9))*1.21 -> 32.765726 | J16: =I16*30/100 -> 9.8297179 | K16: =(I16*6/100) -> 1.9659436 | L16: =H16*2/1000 -> 6.4694462 | M16: =H16*3/1000 -> 9.7041693 | N16: =H16*1/1000 -> 3.2347231 | O16: 0 | P16: =SUM(P15) -> 0 | Q16: =SUM(Q15) -> 0 | R16: 0 | S16: 0 | T16: =SUM(T15) -> 0 | U16: 0 | V16: 0
A17: RRAS 13 - FRANCA | B17: =SUM('Tabela 1 APS + Leitos Nec.'!E447:E468) -> 7926 | C17: 33.45 | D17: =SUM('Tabela 1 APS + Leitos Nec.'!G447:G468) -> 125 | E17: 35.3 | F17: 49.18 | G17: =(B17*(1-C17/100)*1.1) -> 5802.2283 | H17: =B17*(1-C17/100) -> 5274.753 | I17: =((G17*2.5)/(365*0.9))*1.21 -> 53.429956 | J17: =I17*30/100 -> 16.028987 | K17: =(I17*6/100) -> 3.2057974 | L17: =H17*2/1000 -> 10.549506 | M17: =H17*3/1000 -> 15.824259 | N17: =H17*1/1000 -> 5.274753 | O17: 0 | P17: =SUM(P15:P16) -> 0 | Q17: =SUM(Q15:Q16) -> 0 | R17: 0 | S17: 0 | T17: =SUM(T15:T16) -> 0 | U17: 0 | V17: 0
A18: RRAS 13 - RIBEIRÃO PRETO | B18: =SUM('Tabela 1 APS + Leitos Nec.'!E469:E494) -> 15654 | C18: 40.82 | D18: =SUM('Tabela 1 APS + Leitos Nec.'!G469:G494) -> 183 | E18: 28.54 | F18: 65.88 | G18: =(B18*(1-C18/100)*1.1) -> 10190.441 | H18: =B18*(1-C18/100) -> 9264.0372 | I18: =((G18*2.5)/(365*0.9))*1.21 -> 93.838916 | J18: =I18*30/100 -> 28.151675 | K18: =(I18*6/100) -> 5.6303349 | L18: =H18*2/1000 -> 18.528074 | M18: =H18*3/1000 -> 27.792112 | N18: =H18*1/1000 -> 9.2640372 | O18: 0 | P18: =SUM(P17) -> 0 | Q18: =SUM(Q17) -> 0 | R18: 0 | S18: 0 | T18: =SUM(T17) -> 0 | U18: 0 | V18: 0
A19: RRAS 14 | B19: =SUM('Tabela 1 APS + Leitos Nec.'!E495:E520) -> 16935 | C19: 44.54 | D19: =SUM('Tabela 1 APS + Leitos Nec.'!G495:G520) -> 257 | E19: 35.66 | F19: 53.4 | G19: =(B19*(1-C19/100)*1.1) -> 10331.366 | H19: =B19*(1-C19/100) -> 9392.151 | I19: =((G19*2.5)/(365*0.9))*1.21 -> 95.136628 | J19: =I19*30/100 -> 28.540989 | K19: =(I19*6/100) -> 5.7081977 | L19: =H19*2/1000 -> 18.784302 | M19: =H19*3/1000 -> 28.176453 | N19: =H19*1/1000 -> 9.392151 | O19: 0 | P19: =SUM(P18) -> 0 | Q19: =SUM(Q18) -> 0 | R19: 0 | S19: 0 | T19: =SUM(T18) -> 0 | U19: 0 | V19: 0
A20: RRAS 15 - CAMPINAS | B20: =SUM('Tabela 1 APS + Leitos Nec.'!E521:E544) -> 36355 | C20: 45.4 | D20: =SUM('Tabela 1 APS + Leitos Nec.'!G521:G544) -> 321 | E20: 39.08 | F20: 59.8 | G20: =(B20*(1-C20/100)*1.1) -> 21834.813 | H20: =B20*(1-C20/100) -> 19849.83 | I20: =((G20*2.5)/(365*0.9))*1.21 -> 201.06639 | J20: =I20*30/100 -> 60.319917 | K20: =(I20*6/100) -> 12.063983 | L20: =H20*2/1000 -> 39.69966 | M20: =H20*3/1000 -> 59.54949 | N20: =H20*1/1000 -> 19.84983 | O20: 0 | P20: =SUM(P19) -> 0 | Q20: =SUM(Q19) -> 0 | R20: 0 | S20: 0 | T20: =SUM(T19) -> 0 | U20: 0 | V20: 0
A21: RRAS 15 - SÃO JOÃO DA BOA VISTA | B21: =SUM('Tabela 1 APS + Leitos Nec.'!E545:E564) -> 8477 | C21: 31.45 | D21: =SUM('Tabela 1 APS + Leitos Nec.'!G545:G564) -> 152 | E21: 39.16 | F21: 57.55 | G21: =(B21*(1-C21/100)*1.1) -> 6392.0818 | H21: =B21*(1-C21/100) -> 5810.9835 | I21: =((G21*2.5)/(365*0.9))*1.21 -> 58.861637 | J21: =I21*30/100 -> 17.658491 | K21: =(I21*6/100) -> 3.5316982 | L21: =H21*2/1000 -> 11.621967 | M21: =H21*3/1000 -> 17.432951 | N21: =H21*1/1000 -> 5.8109835 | O21: 0 | P21: =SUM(P20) -> 0 | Q21: =SUM(Q20) -> 0 | R21: 0 | S21: 0 | T21: =SUM(T20) -> 0 | U21: 0 | V21: 0
A22: RRAS 16 | B22: =SUM('Tabela 1 APS + Leitos Nec.'!E565:E582) -> 16244 | C22: 44.27 | D22: =SUM('Tabela 1 APS + Leitos Nec.'!G565:G582) -> 163 | E22: 19.18 | F22: 53.96 | G22: =(B22*(1-C22/100)*1.1) -> 9958.0593 | H22: =B22*(1-C22/100) -> 9052.7812 | I22: =((G22*2.5)/(365*0.9))*1.21 -> 91.699024 | J22: =I22*30/100 -> 27.509707 | K22: =(I22*6/100) -> 5.5019415 | L22: =H22*2/1000 -> 18.105562 | M22: =H22*3/1000 -> 27.158344 | N22: =H22*1/1000 -> 9.0527812 | O22: 0 | P22: =SUM(P21) -> 0 | Q22: =SUM(Q21) -> 0 | R22: 0 | S22: 0 | T22: =SUM(T21) -> 0 | U22: 0 | V22: 0
A23: RRAS 17 | B23: =SUM('Tabela 1 APS + Leitos Nec.'!E583:E621) -> 28864 | C23: 31.37 | D23: =SUM('Tabela 1 APS + Leitos Nec.'!G583:G621) -> 412 | E23: 44.55 | F23: 68.03 | G23: =(B23*(1-C23/100)*1.1) -> 21790.3 | H23: =B23*(1-C23/100) -> 19809.363 | I23: =((G23*2.5)/(365*0.9))*1.21 -> 200.65649 | J23: =I23*30/100 -> 60.196946 | K23: =(I23*6/100) -> 12.039389 | L23: =H23*2/1000 -> 39.618726 | M23: =H23*3/1000 -> 59.42809 | N23: =H23*1/1000 -> 19.809363 | O23: 0 | P23: =SUM(P22) -> 0 | Q23: =SUM(Q22) -> 0 | R23: 0 | S23: 0 | T23: =SUM(T22) -> 0 | U23: 0 | V23: 0
A24: RRAS 18 | B24: =SUM('Tabela 1 APS + Leitos Nec.'!E622:E645) -> 10385.667 | C24: 40.14 | D24: =SUM('Tabela 1 APS + Leitos Nec.'!G622:G645) -> 182 | E24: 30.96 | F24: 59.35 | G24: =(B24*(1-C24/100)*1.1) -> 6838.5461 | H24: =B24*(1-C24/100) -> 6216.8601 | I24: =((G24*2.5)/(365*0.9))*1.21 -> 62.972913 | J24: =I24*30/100 -> 18.891874 | K24: =(I24*6/100) -> 3.7783748 | L24: =H24*2/1000 -> 12.43372 | M24: =H24*3/1000 -> 18.65058 | N24: =H24*1/1000 -> 6.2168601 | O24: 0 | P24: =SUM(P23) -> 0 | Q24: =SUM(Q23) -> 0 | R24: 0 | S24: 0 | T24: =SUM(T23) -> 0 | U24: 0 | V24: 0

Sheet Descr. Tabela 1 APS + Leitos Ne
A1: Tabela 1 APS - Cobertura de Acesso e Capacidade Instalada na Atenção Primária à Saúde (APS) Para a Gestação de Baixo Risco | L1: Número de Leitos Necessários Para a Rede Materna e Infantil
L2: OBSTÉTRICOS (Taxa de ocupação de 90% - Rede Alyne) | M2: Leitos GAR para atender as gestantes susdependentes do município - RRAS (30% - Rede Alyne) | N2: UTI ADULTO | O2: UTIN | P2: UCINCO (x3 Portaria 2015) | Q2: UCINCA | R2: CPN I | T2: CPN II | V2: CGBP | Y2: BLH
A3: RRAS | B3: DRS | C3: REGIÃO DE SAÚDE | D3: MUNICÍPIO DA RRAS | E3: NASCIDOS VIVOS | F3: COBERTURA ANS (%) | G3: Nº DE UBS | H3: COBERTURA ESF (%) | I3: COBERTURA AB (%) | J3: GESTANTES SUSDEPENDENTES ESTIMADAS/ANO | K3: NASCIDOS VIVOS SUSDEPENDENTES ESTIMADOS/ANO | R3: 3 Leitos | S3: 5 Leitos | T3: 3 Leitos | U3: 5 Leitos | V3: 10 Leitos | W3: 15 Leitos | X3: 20 Leitos
A4: RRAS 1 | B4: Grande São Paulo | C4: Grande ABC | D4: Diadema | E4: 4230 | F4: 45.08 | G4: 20 | H4: 74.07 | I4: 80.43 | J4: =(E4*(1-F4/100)*1.1) -> 2555.4276 | K4: =E4*(1-F4/100) -> 2323.116 | L4: =((J4*2.5)/(365*0.9))*1.21 -> 23.531715 | M4: =L4*30/100 -> 7.0595146 | N4: =(L4*6/100) -> 1.4119029 | O4: =K4*2/1000 -> 4.646232 | P4: =K4*3/1000 -> 6.969348 | Q4: =K4*1/1000 -> 2.323116 | U4: 1
A5: RRAS 1 | B5: Grande São Paulo | C5: Grande ABC | D5: Mauá | E5: 4404 | F5: 47.01 | G5: 23 | H5: 29.18 | I5: 41.23 | J5: =(E5*(1-F5/100)*1.1) -> 2567.0476 | K5: =E5*(1-F5/100) -> 2333.6796 | L5: =((J5*2.5)/(365*0.9))*1.21 -> 23.638718 | M5: =L5*30/100 -> 7.0916154 | N5: =(L5*6/100) -> 1.4183231 | O5: =K5*2/1000 -> 4.6673592 | P5: =K5*3/1000 -> 7.0010388 | Q5: =K5*1/1000 -> 2.3336796
A6: RRAS 1 | B6: Grande São Paulo | C6: Grande ABC | D6: Ribeirão Pires | E6: 1041 | F6: 48.59 | G6: 10 | H6: 39.14 | I6: 46.44 | J6: =(E6*(1-F6/100)*1.1) -> 588.69591 | K6: =E6*(1-F6/100) -> 535.1781 | L6: =((J6*2.5)/(365*0.9))*1.21 -> 5.4210202 | M6: =L6*30/100 -> 1.6263061 | N6: =(L6*6/100) -> 0.32526121 | O6: =K6*2/1000 -> 1.0703562 | P6: =K6*3/1000 -> 1.6055343 | Q6: =K6*1/1000 -> 0.5351781
A7: RRAS 1 | B7: Grande São Paulo | C7: Grande ABC | D7: Rio Grande da Serra | E7: 465 | F7: 34.24 | G7: 8 | H7: 47.5 | I7: 53.4 | J7: =(E7*(1-F7/100)*1.1) -> 336.3624 | K7: =E7*(1-F7/100) -> 305.784 | L7: =((J7*2.5)/(365*0.9))*1.21 -> 3.0974011 | M7: =L7*30/100 -> 0.92922033 | N7: =(L7*6/100) -> 0.18584407 | O7: =K7*2/1000 -> 0.611568 | P7: =K7*3/1000 -> 0.917352 | Q7: =K7*1/1000 -> 0.305784 | X7: 1
A8: RRAS 1 | B8: Grande São Paulo | C8: Grande ABC | D8: Santo André | E8: 7378 | F8: 57.35 | G8: 35 | H8: 24.48 | I8: 46.5 | J8: =(E8*(1-F8/100)*1.1) -> 3461.3887 | K8: =E8*(1-F8/100) -> 3146.717 | L8: =((J8*2.5)/(365*0.9))*1.21 -> 31.87428 | M8: =L8*30/100 -> 9.5622839 | N8: =(L8*6/100) -> 1.9124568 | O8: =K8*2/1000 -> 6.293434 | P8: =K8*3/1000 -> 9.440151 | Q8: =K8*1/1000 -> 3.146717 | U8: 1
A9: RRAS 1 | B9: Grande São Paulo | C9: Grande ABC | D9: São Bernardo do Campo | E9: 7815 | F9: 55.67 | G9: 34 | H9: 63.33 | I9: 74.77 | J9: =(E9*(1-F9/100)*1.1) -> 3810.8284 | K9: =E9*(1-F9/100) -> 3464.3895 | L9: =((J9*2.5)/(365*0.9))*1.21 -> 35.092104 | M9: =L9*30/100 -> 10.527631 | N9: =(L9*6/100) -> 2.1055262 | O9: =K9*2/1000 -> 6.928779 | P9: =K9*3/1000 -> 10.393168 | Q9: =K9*1/1000 -> 3.4643895 | R9: 1 | V9: 1
A10: RRAS 1 | B10: Grande São Paulo | C10: Grande ABC | D10: São Caetano do Sul | E10: 1345 | F10: 62.1 | G10: 12 | H10: 62.09 | I10: 100 | J10: =(E10*(1-F10/100)*1.1) -> 560.7305 | K10: =E10*(1-F10/100) -> 509.755 | L10: =((J10*2.5)/(365*0.9))*1.21 -> 5.1635 | M10: =L10*30/100 -> 1.54905 | N10: =(L10*6/100) -> 0.30981 | O10: =K10*2/1000 -> 1.01951 | P10: =K10*3/1000 -> 1.529265 | Q10: =K10*1/1000 -> 0.509755 | R10: 1
A11: RRAS 2 | B11: Grande São Paulo | C11: Alto Tietê | D11: Arujá | E11: 1290 | F11: 42.29 | G11: 7 | H11: 38.41 | I11: 65.53 | J11: =(E11*(1-F11/100)*1.1) -> 818.9049 | K11: =E11*(1-F11/100) -> 744.459 | L11: =((J11*2.5)/(365*0.9))*1.21 -> 7.5409051 | M11: =L11*30/100 -> 2.2622715 | N11: =(L11*6/100) -> 0.45245431 | O11: =K11*2/1000 -> 1.488918 | P11: =K11*3/1000 -> 2.233377 | Q11: =K11*1/1000 -> 0.744459
A12: RRAS 2 | B12: Grande São Paulo | C12: Alto Tietê | D12: Biritiba Mirim | E12: 336 | F12: 11.25 | G12: 7 | H12: 21.17 | I12: 30.37 | J12: =(E12*(1-F12/100)*1.1) -> 328.02 | K12: =E12*(1-F12/100) -> 298.2 | L12: =((J12*2.5)/(365*0.9))*1.21 -> 3.0205799 | M12: =L12*30/100 -> 0.90617397 | N12: =(L12*6/100) -> 0.18123479 | O12: =K12*2/1000 -> 0.5964 | P12: =K12*3/1000 -> 0.8946 | Q12: =K12*1/1000 -> 0.2982
A13: RRAS 2 | B13: Grande São Paulo | C13: Alto Tietê | D13: Ferraz de Vasconcelos | E13: 2279 | F13: 23.22 | G13: 14 | H13: 35.52 | I13: 57.98 | J13: =(E13*(1-F13/100)*1.1) -> 1924.7978 | K13: =E13*(1-F13/100) -> 1749.8162 | L13: =((J13*2.5)/(365*0.9))*1.21 -> 17.724546 | M13: =L13*30/100 -> 5.3173638 | N13: =(L13*6/100) -> 1.0634728 | O13: =K13*2/1000 -> 3.4996324 | P13: =K13*3/1000 -> 5.2494486 | Q13: =K13*1/1000 -> 1.7498162
A14: RRAS 2 | B14: Grande São Paulo | C14: Alto Tietê | D14: Guararema | E14: 327 | F14: 21.32 | G14: 1 | H14: 0 | I14: 58.39 | J14: =(E14*(1-F14/100)*1.1) -> 283.01196 | K14: =E14*(1-F14/100) -> 257.2836 | L14: =((J14*2.5)/(365*0.9))*1.21 -> 2.6061223 | M14: =L14*30/100 -> 0.78183669 | N14: =(L14*6/100) -> 0.15636734 | O14: =K14*2/1000 -> 0.5145672 | P14: =K14*3/1000 -> 0.7718508 | Q14: =K14*1/1000 -> 0.2572836
A15: RRAS 2 | B15: Grande São Paulo | C15: Alto Tietê | D15: Guarulhos | E15: 17501 | F15: 47.05 | G15: 69 | H15: 31.27 | I15: 40.23 | J15: =(E15*(1-F15/100)*1.1) -> 10193.457 | K15: =E15*(1-F15/100) -> 9266.7795 | L15: =((J15*2.5)/(365*0.9))*1.21 -> 93.866693 | M15: =L15*30/100 -> 28.160008 | N15: =(L15*6/100) -> 5.6320016 | O15: =K15*2/1000 -> 18.533559 | P15: =K15*3/1000 -> 27.800338 | Q15: =K15*1/1000 -> 9.2667795 | Y15: 1
A16: RRAS 2 | B16: Grande São Paulo | C16: Alto Tietê | D16: Itaquaquecetuba | E16: 5077 | F16: 26.14 | G16: 17 | H16: 18.61 | I16: 34.1 | J16: =(E16*(1-F16/100)*1.1) -> 4124.8594 | K16: =E16*(1-F16/100) -> 3749.8722 | L16: =((J16*2.5)/(365*0.9))*1.21 -> 37.983865 | M16: =L16*30/100 -> 11.39516 | N16: =(L16*6/100) -> 2.2790319 | O16: =K16*2/1000 -> 7.4997444 | P16: =K16*3/1000 -> 11.249617 | Q16: =K16*1/1000 -> 3.7498722
A17: RRAS 2 | B17: Grande São Paulo | C17: Alto Tietê | D17: Mogi das Cruzes | E17: 5222 | F17: 35.92 | G17: 36 | H17: 10.83 | I17: 50.84 | J17: =(E17*(1-F17/100)*1.1) -> 3680.8834 | K17: =E17*(1-F17/100) -> 3346.2576 | L17: =((J17*2.5)/(365*0.9))*1.21 -> 33.895501 | M17: =L17*30/100 -> 10.16865 | N17: =(L17*6/100) -> 2.0337301 | O17: =K17*2/1000 -> 6.6925152 | P17: =K17*3/1000 -> 10.038773 | Q17: =K17*1/1000 -> 3.3462576 | Y17: 1
A18: RRAS 2 | B18: Grande São Paulo | C18: Alto Tietê | D18: Poá | E18: 1249 | F18: 32.1 | G18: 12 | H18: 26.44 | I18: 31.54 | J18: =(E18*(1-F18/100)*1.1) -> 932.8781 | K18: =E18*(1-F18/100) -> 848.071 | L18: =((J18*2.5)/(365*0.9))*1.21 -> 8.59043 | M18: =L18*30/100 -> 2.577129 | N18: =(L18*6/100) -> 0.5154258 | O18: =K18*2/1000 -> 1.696142 | P18: =K18*3/1000 -> 2.544213 | Q18: =K18*1/1000 -> 0.848071
A19: RRAS 2 | B19: Grande São Paulo | C19: Alto Tietê | D19: Salesópolis | E19: 179 | F19: 11.9 | G19: 2 | H19: 0 | I19: 52.51 | J19: =(E19*(1-F19/100)*1.1) -> 173.4689 | K19: =E19*(1-F19/100) -> 157.699 | L19: =((J19*2.5)/(365*0.9))*1.21 -> 1.5973925 | M19: =L19*30/100 -> 0.47921774 | N19: =(L19*6/100) -> 0.095843547 | O19: =K19*2/1000 -> 0.315398 | P19: =K19*3/1000 -> 0.473097 | Q19: =K19*1/1000 -> 0.157699
A20: RRAS 2 | B20: Grande São Paulo | C20: Alto Tietê | D20: Santa Isabel | E20: 588 | F20: 25.52 | G20: 11 | H20: 30.06 | I20: 50.97 | J20: =(E20*(1-F20/100)*1.1) -> 481.73664 | K20: =E20*(1-F20/100) -> 437.9424 | L20: =((J20*2.5)/(365*0.9))*1.21 -> 4.4360832 | M20: =L20*30/100 -> 1.330825 | N20: =(L20*6/100) -> 0.26616499 | O20: =K20*2/1000 -> 0.8758848 | P20: =K20*3/1000 -> 1.3138272 | Q20: =K20*1/1000 -> 0.4379424
A21: RRAS 2 | B21: Grande São Paulo | C21: Alto Tietê | D21: Suzano | E21: 3942 | F21: 30.8 | G21: 24 | H21: 25.5 | I21: 51.28 | J21: =(E21*(1-F21/100)*1.1) -> 3000.6504 | K21: =E21*(1-F21/100) -> 2727.864 | L21: =((J21*2.5)/(365*0.9))*1.21 -> 27.63156 | M21: =L21*30/100 -> 8.289468 | N21: =(L21*6/100) -> 1.6578936 | O21: =K21*2/1000 -> 5.455728 | P21: =K21*3/1000 -> 8.183592 | Q21: =K21*1/1000 -> 2.727864
A22: RRAS 3 | B22: Grande São Paulo | C22: Franco da Rocha | D22: Caieiras | E22: 1147 | F22: 37.01 | G22: 14 | H22: 6.8 | I22: 62.24 | J22: =(E22*(1-F22/100)*1.1) -> 794.74483 | K22: =E22*(1-F22/100) -> 722.4953 | L22: =((J22*2.5)/(365*0.9))*1.21 -> 7.3184265 | M22: =L22*30/100 -> 2.195528 | N22: =(L22*6/100) -> 0.43910559 | O22: =K22*2/1000 -> 1.4449906 | P22: =K22*3/1000 -> 2.1674859 | Q22: =K22*1/1000 -> 0.7224953
A23: RRAS 3 | B23: Grande São Paulo | C23: Franco da Rocha | D23: Cajamar | E23: 1304 | F23: 45 | G23: 11 | H23: 53.91 | I23: 76.99 | J23: =(E23*(1-F23/100)*1.1) -> 788.92 | K23: =E23*(1-F23/100) -> 717.2 | L23: =((J23*2.5)/(365*0.9))*1.21 -> 7.2647884 | M23: =L23*30/100 -> 2.1794365 | N23: =(L23*6/100) -> 0.43588731 | O23: =K23*2/1000 -> 1.4344 | P23: =K23*3/1000 -> 2.1516 | Q23: =K23*1/1000 -> 0.7172
A24: RRAS 3 | B24: Grande São Paulo | C24: Franco da Rocha | D24: Francisco Morato | E24: 2488 | F24: 24.22 | G24: 13 | H24: 47.09 | I24: 50.5 | J24: =(E24*(1-F24/100)*1.1) -> 2073.947 | K24: =E24*(1-F24/100) -> 1885.4064 | L24: =((J24*2.5)/(365*0.9))*1.21 -> 19.09799 | M24: =L24*30/100 -> 5.7293971 | N24: =(L24*6/100) -> 1.1458794 | O24: =K24*2/1000 -> 3.7708128 | P24: =K24*3/1000 -> 5.6562192 | Q24: =K24*1/1000 -> 1.8854064
A25: RRAS 3 | B25: Grande São Paulo | C25: Franco da Rocha | D25: Franco da Rocha | E25: 1833 | F25: 27.18 | G25: 14 | H25: 55.83 | I25: 76.37 | J25: =(E25*(1-F25/100)*1.1) -> 1468.2697 | K25: =E25*(1-F25/100) -> 1334.7906 | L25: =((J25*2.5)/(365*0.9))*1.21 -> 13.520596 | M25: =L25*30/100 -> 4.0561787 | N25: =(L25*6/100) -> 0.81123575 | O25: =K25*2/1000 -> 2.6695812 | P25: =K25*3/1000 -> 4.0043718 | Q25: =K25*1/1000 -> 1.3347906
A26: RRAS 3 | B26: Grande São Paulo | C26: Franco da Rocha | D26: Mairiporã | E26: 910 | F26: 21.73 | G26: 17 | H26: 37.88 | I26: 58.84 | J26: =(E26*(1-F26/100)*1.1) -> 783.4827 | K26: =E26*(1-F26/100) -> 712.257 | L26: =((J26*2.5)/(365*0.9))*1.21 -> 7.2147189 | M26: =L26*30/100 -> 2.1644157 | N26: =(L26*6/100) -> 0.43288314 | O26: =K26*2/1000 -> 1.424514 | P26: =K26*3/1000 -> 2.136771 | Q26: =K26*1/1000 -> 0.712257
