Workbook

Sheet listas de opções
A1: RRAS | C1: DRS | E1: Região de Saúde | G1: STATUS | I1: HABILITAÇÃO MAB
A2: RRAS 01 | C2: Aracatuba | E2: Adamantina | G2: Existente | I2: MAB I
A3: RRAS 02 | C3: Araraquara | E3: Alta Anhanguera | G3: Novo | I3: MAB II
A4: RRAS 03 | C4: Baixada Santista | E4: Alta Mogiana | G4: Não existe | I4: MAB III
A5: RRAS 04 | C5: Barretos | E5: Alta Paulista | I5: SEM HABILITAÇÃO
A6: RRAS 05 | C6: Bauru | E6: Alta Sorocabana
A7: RRAS 06 | C7: Campinas | E7: Alto Capivari
A8: RRAS 07 | C8: Franca | E8: Alto do Tiete
A9: RRAS 08 | C9: Grande Sao Paulo | E9: Alto Vale do Paraiba
A10: RRAS 09 | C10: Marilia | E10: Aquifero Guarani
A11: RRAS 10 | C11: Piracicaba | E11: Araras
A12: RRAS 11 | C12: Presidente Prudente | E12: Assis
A13: RRAS 12 | C13: Registro | E13: Baixa Mogiana
A14: RRAS 13 | C14: Ribeirao Preto | E14: Baixada Santista
A15: RRAS 14 | C15: Sao Joao da Boa Vista | E15: Bauru
A16: RRAS 15 | C16: Sao Jose do Rio Preto | E16: Braganca
A17: RRAS 16 | C17: Sorocaba | E17: Catanduva
A18: RRAS 17 | C18: Taubate | E18: Central do DRS II
E19: Central do DRS III
E20: Centro Oeste do DRS III
E21: Circ. da Fe-V. Historico
E22: Circuito das Aguas
E23: Consorcio do DRS II
E24: Coracao do DRS III
E25: Extremo Oeste Paulista
E26: Fernandopolis
E27: Franco da Rocha
E28: Grande ABC
E29: Horizonte Verde
E30: Itapetininga
... E64: Votuporanga

Sheet Tabela 1 APS - Descr.
A1: RRAS:
A3: Planilha atualizada em: 04/11/2024
A6: A tabela 1 se refere a capacidade do municipio/territorio para atendimento a gestante de baixo risco e apontamento da pactuação do serviço que realiza o Pré-Natal de Alto Risco (AGAR), a entrada deve ser coerente com as referencias e Região de Saúde.
A8: NASCIDOS VIVOS: PARA ATUAL PLANO: CONSIDERAR ANO 2023
A9: ESTIMATIVA DE GESTANTES SUSDEPENDENTE (CÁLCULO) = NV + 10% - % Cobertura Saude Suplementar (por municipio)-fonte: https://tabnet.saude.sp.gov.br/tabcgi.exe?tabnet/ind47a_matriz.def
A10: COBERTURA ANS - REFERENCIA 2023 (Fonte/Tabnet:https://tabnet.saude.sp.gov.br/tabcgi.exe?tabnet/ind47a_matriz.def)
A11: Nº de UBS - Referência 2024. (Fonte: https://cnes2.datasus.gov.br/Mod_Ind_Unidade.asp?VEstado=35&VMun=351380&VComp=00&VUni=02)
A12: COBERTURA DA ESF/MUNICÍPIO - Referência 2020 (Fonte: https://tabnet.saude.sp.gov.br/tabcgi.exe?tabnet/ind33a_matriz.def)
A13: COBERTURA DA AB/MUNICÍPIO - Referência 2020 (Fonte: https://tabnet.saude.sp.gov.br/tabcgi.exe?tabnet/ind33a_matriz.def)
A15: GLOSSÁRIO
A16: AAE -Atenção Ambulatorial Especializada
A17: APS - ATENÇÃO PRIMÁRIA À SAÚDE
... A24: Tabela: 1 Cobertura de Acesso e capacidade instalada na Atenção Primária à Saúde (APS) para a gestação de baixo risco.
A26: DRS | B26: RS | C26: MUNICIPIO | D26: NASCIDOS VIVOS MUNICIPIO (MÉDIA) | E26: COBERTURA ANS % | F26: Nº DE UBS | G26: COBERTURA DA ESF/MUNICIPIO | H26: COBERTURA DA APS/MUNICIPIO | I26: TOTAL DE GESTANTES SUSDEPENDENTES ESTIMADAS/ANO | J26: TOTAL DE NASCIDOS VIVOS SUSDEPENDENTES ESTIMADOS/ANO | K26: CNES/ESTABELECIMENTO PARA REFERENCIA PARA AAE (AGAR) | L26: MUNICIPIO | M26: CNES/ESTABELECIMENTO DA REFERENCIA PARA PARTO (BX RISCO) | N26: MUNICIPIO
A27: III-ARARAQUARA | B27: CENTRAL | C27: Américo Brasiliense | D27: 368 | E27: 46.15 | F27: 4 | G27: 17.04 | H27: 39.26 | I27: =(D27*(1-E27/100)*1.1) -> 217.9848 | J27: =D27*(1-E27/100) -> 198.168 | K27: 9424377 | L27: Araraquara | M27: 6943284 | N27: Araraquara
A28: III-ARARAQUARA | B28: CENTRAL | C28: Araraquara | D28: 2527 | E28: 49.23 | F28: 38 | G28: 36.54 | H28: 60.64 | I28: =(D28*(1-E28/100)*1.1) -> 1411.2537 | J28: =D28*(1-E28/100) -> 1282.9579 | K28: 9424377 | L28: Araraquara | M28: 6943284 | N28: Araraquara
A29: III-ARARAQUARA | B29: CENTRAL | C29: Boa Esperança do Sul | D29: 149 | E29: 23.62 | F29: 4 | G29: 69.36 | H29: 100 | I29: =(D29*(1-E29/100)*1.1) -> 125.18682 | J29: =D29*(1-E29/100) -> 113.8062 | K29: 9424377 | L29: Araraquara | M29: 6943284 | N29: Araraquara
A30: III-ARARAQUARA | B30: CENTRAL | C30: Gavião Peixoto | D30: 73 | E30: 43.83 | F30: 2 | G30: 100 | H30: 100 | I30: =(D30*(1-E30/100)*1.1) -> 45.10451 | J30: =D30*(1-E30/100) -> 41.0041 | K30: 9424377 | L30: Araraquara | M30: 6943284 | N30: Araraquara
A31: III-ARARAQUARA | B31: CENTRAL | C31: Motuca | D31: 32 | E31: 37.61 | F31: 2 | G31: 72.51 | H31: 100 | I31: =(D31*(1-E31/100)*1.1) -> 21.96128 | J31: =D31*(1-E31/100) -> 19.9648 | K31: 9424377 | L31: Araraquara | M31: 6943284 | N31: Araraquara
A32: III-ARARAQUARA | B32: CENTRAL | C32: Rincão | D32: 81 | E32: 32.96 | F32: 3 | G32: 95.84 | H32: 100 | I32: =(D32*(1-E32/100)*1.1) -> 59.73264 | J32: =D32*(1-E32/100) -> 54.3024 | K32: 9424377 | L32: Araraquara | M32: 6943284 | N32: Araraquara
A33: III-ARARAQUARA | B33: CENTRAL | C33: Santa Lucia | D33: 78 | E33: 50.67 | F33: 2 | G33: 39.13 | H33: 39.13 | I33: =(D33*(1-E33/100)*1.1) -> 42.32514 | J33: =D33*(1-E33/100) -> 38.4774 | K33: 9424377 | L33: Araraquara | M33: 6943284 | N33: Araraquara
A34: III-ARARAQUARA | B34: CENTRAL | C34: Trabiju | D34: 17 | E34: 18.43 | F34: 1 | G34: 100 | H34: 100 | I34: =(D34*(1-E34/100)*1.1) -> 15.25359 | J34: =D34*(1-E34/100) -> 13.8669 | K34: 9424377 | L34: Araraquara | M34: 6943284 | N34: Araraquara
A35: III-ARARAQUARA | B35: CENTRO-OESTE | C35: Borborema | D35: 128 | E35: 13.32 | F35: 4 | G35: 64.5 | H35: 83.2 | I35: =(D35*(1-E35/100)*1.1) -> 122.04544 | J35: =D35*(1-E35/100) -> 110.9504 | K35: 2090961 | L35: Matão | M35: 2081989 | N35: Borborema
A36: III-ARARAQUARA | B36: CENTRO-OESTE | C36: Ibitinga | D36: 680 | E36: 19.7 | F36: 10 | G36: 22.99 | H36: 52.97 | I36: =(D36*(1-E36/100)*1.1) -> 600.644 | J36: =D36*(1-E36/100) -> 546.04 | K36: 2090961 | L36: Matão | M36: 2082640 | N36: Ibitinga
A37: III-ARARAQUARA | B37: CENTRO-OESTE | C37: Itápolis | D37: 375 | E37: 23.49 | F37: 7 | G37: 8 | H37: 8 | I37: =(D37*(1-E37/100)*1.1) -> 315.60375 | J37: =D37*(1-E37/100) -> 286.9125 | K37: 2090961 | L37: Matão | M37: 2079836 | N37: Itápolis
A38: III-ARARAQUARA | B38: CENTRO-OESTE | C38: Nova Europa | D38: 92 | E38: 46.18 | F38: 3 | G38: 61.68 | H38: 61.68 | I38: =(D38*(1-E38/100)*1.1) -> 54.46584 | J38: =D38*(1-E38/100) -> 49.5144 | K38: 2090961 | L38: Matão | M38: 2747685 | N38: Nova Europa
... A50: III-ARARAQUARA | B50: NORTE | C50: Taquaritinga | D50: 498 | E50: 30.62 | F50: 10 | G50: 30.17 | H50: 73.25 | I50: =(D50*(1-E50/100)*1.1) -> 380.06364 | J50: =D50*(1-E50/100) -> 345.5124 | K50: 2090961 | L50: Matão | M50: 2078295 | N50: Taquaritinga

Sheet Tabela 1 APS - Dados
A1: DRS | B1: REGIÃO DE SAÚDE | C1: MUNICÍPIO DA RRAS | D1: NASCIDOS VIVOS MUNICÍPIO | E1: COBERTURA ANS (%) | F1: Nº DE UBS | G1: COBERTURA DA ESF (%) | H1: COBERTURA DA AB (%) | I1: GESTANTES SUSDEPENDENTES ESTIMADAS/ANO | J1: NASCIDOS VIVOS SUSDEPENDENTES ESTIMADOS/ANO
A2: Araraquara | B2: Central do DRS III | C2: Américo Brasiliense | D2: 368 | E2: 46.15 | F2: 4 | G2: 17.04 | H2: 39.26 | I2: =(D2*(1-E2/100)*1.1) -> 217.9848 | J2: =D2*(1-E2/100) -> 198.168
A3: Araraquara | B3: Central do DRS III | C3: Araraquara | D3: 2527 | E3: 49.23 | F3: 38 | G3: 36.54 | H3: 60.64 | I3: =(D3*(1-E3/100)*1.1) -> 1411.2537 | J3: =D3*(1-E3/100) -> 1282.9579
A4: Araraquara | B4: Central do DRS III | C4: Boa Esperança do Sul | D4: 149 | E4: 23.62 | F4: 4 | G4: 69.36 | H4: 100 | I4: =(D4*(1-E4/100)*1.1) -> 125.18682 | J4: =D4*(1-E4/100) -> 113.8062
A5: Araraquara | B5: Central do DRS III | C5: Gavião Peixoto | D5: 73 | E5: 43.83 | F5: 2 | G5: 100 | H5: 100 | I5: =(D5*(1-E5/100)*1.1) -> 45.10451 | J5: =D5*(1-E5/100) -> 41.0041
A6: Araraquara | B6: Central do DRS III | C6: Motuca | D6: 32 | E6: 37.61 | F6: 2 | G6: 72.51 | H6: 100 | I6: =(D6*(1-E6/100)*1.1) -> 21.96128 | J6: =D6*(1-E6/100) -> 19.9648
A7: Araraquara | B7: Central do DRS III | C7: Rincão | D7: 81 | E7: 32.96 | F7: 3 | G7: 95.84 | H7: 100 | I7: =(D7*(1-E7/100)*1.1) -> 59.73264 | J7: =D7*(1-E7/100) -> 54.3024
A8: Araraquara | B8: Central do DRS III | C8: SANTA LÚCIA | D8: 78 | E8: 50.67 | F8: 2 | G8: 39.13 | H8: 39.13 | I8: =(D8*(1-E8/100)*1.1) -> 42.32514 | J8: =D8*(1-E8/100) -> 38.4774
A9: Araraquara | B9: Central do DRS III | C9: Trabiju | D9: 17 | E9: 18.43 | F9: 1 | G9: 100 | H9: 100 | I9: =(D9*(1-E9/100)*1.1) -> 15.25359 | J9: =D9*(1-E9/100) -> 13.8669
A10: Araraquara | B10: Centro-Oeste | C10: Borborema | D10: 128 | E10: 13.32 | F10: 4 | G10: 64.5 | H10: 83.2 | I10: =(D10*(1-E10/100)*1.1) -> 122.04544 | J10: =D10*(1-E10/100) -> 110.9504
A11: Araraquara | B11: Centro-Oeste | C11: Ibitinga | D11: 680 | E11: 19.7 | F11: 10 | G11: 22.99 | H11: 52.97 | I11: =(D11*(1-E11/100)*1.1) -> 600.644 | J11: =D11*(1-E11/100) -> 546.04
A12: Araraquara | B12: Centro-Oeste | C12: Itápolis | D12: 375 | E12: 23.49 | F12: 7 | G12: 8 | H12: 8 | I12: =(D12*(1-E12/100)*1.1) -> 315.60375 | J12: =D12*(1-E12/100) -> 286.9125
A13: Araraquara | B13: Centro-Oeste | C13: Nova Europa | D13: 92 | E13: 46.18 | F13: 3 | G13: 61.68 | H13: 61.68 | I13: =(D13*(1-E13/100)*1.1) -> 54.46584 | J13: =D13*(1-E13/100) -> 49.5144
... A25: Araraquara | B25: Norte | C25: Taquaritinga | D25: 498 | E25: 30.62 | F25: 10 | G25: 30.17 | H25: 73.25 | I25: =(D25*(1-E25/100)*1.1) -> 380.06364 | J25: =D25*(1-E25/100) -> 345.5124

Sheet Tabela 1 APS - Referência AAE
A1: DRS | B1: REGIÃO DE SAÚDE | C1: MUNICÍPIO DA RRAS | D1: CNES | E1: NOME DO ESTABELECIMENTO | F1: MUNICÍPIO DO ESTABELECIMENTO
A2: Araraquara | B2: Central | C2: Américo Brasiliense | D2: 9424377 | E2: Ambulatório de Atenção à Saúde Integral da Mulher | F2: Araraquara
A3: Araraquara | B3: Central | C3: Araraquara | D3: 9424377 | E3: Ambulatório de Atenção à Saúde Integral da Mulher | F3: Araraquara
A4: Araraquara | B4: Central | C4: Boa Esperança do Sul | D4: 9424377 | E4: Ambulatório de Atenção à Saúde Integral da Mulher | F4: Araraquara
A5: Araraquara | B5: Central | C5: Gavião Peixoto | D5: 9424377 | E5: Ambulatório de Atenção à Saúde Integral da Mulher | F5: Araraquara
A6: Araraquara | B6: Central | C6: Motuca | D6: 9424377 | E6: Ambulatório de Atenção à Saúde Integral da Mulher | F6: Araraquara
A7: Araraquara | B7: Central | C7: Rincão | D7: 9424377 | E7: Ambulatório de Atenção à Saúde Integral da Mulher | F7: Araraquara
A8: Araraquara | B8: Central | C8: Santa Lucia | D8: 9424377 | E8: Ambulatório de Atenção à Saúde Integral da Mulher | F8: Araraquara
A9: Araraquara | B9: Central | C9: Trabiju | D9: 9424377 | E9: Ambulatório de Atenção à Saúde Integral da Mulher | F9: Araraquara
A10: Araraquara | B10: Centro-Oeste | C10: Borborema | D10: 2090961 | E10: Hospital Carlos Fernando Malzoni | F10: Matão
A11: Araraquara | B11: Centro-Oeste | C11: Ibitinga | D11: 2090961 | E11: Hospital Carlos Fernando Malzoni | F11: Matão
A12: Araraquara | B12: Centro-Oeste | C12: Itápolis | D12: 2090961 | E12: Hospital Carlos Fernando Malzoni | F12: Matão
A13: Araraquara | B13: Centro-Oeste | C13: Nova Europa | D13: 2090961 | E13: Hospital Carlos Fernando Malzoni | F13: Matão
... A25: Araraquara | B25: Norte | C25: Taquaritinga | D25: 2090961 | E25: Hospital Carlos Fernando Malzoni | F25: Matão

Sheet Tabela 1 APS - Referência Bx. R
A1: DRS | B1: REGIÃO DE SAÚDE | C1: MUNICÍPIO DA RRAS | D1: CNES | E1: NOME DO ESTABELECIMENTO | F1: MUNICÍPIO DO ESTABELECIMENTO
A2: Araraquara | B2: Central | C2: Américo Brasiliense | D2: 6943284 | E2: Maternidade Gota de Leite de Araraquara | F2: Araraquara
A3: Araraquara | B3: Central | C3: Araraquara | D3: 6943284 | E3: Maternidade Gota de Leite de Araraquara | F3: Araraquara
A4: Araraquara | B4: Central | C4: Boa Esperança do Sul | D4: 6943284 | E4: Maternidade Gota de Leite de Araraquara | F4: Araraquara
A5: Araraquara | B5: Central | C5: Gavião Peixoto | D5: 6943284 | E5: Maternidade Gota de Leite de Araraquara | F5: Araraquara
A6: Araraquara | B6: Central | C6: Motuca | D6: 6943284 | E6: Maternidade Gota de Leite de Araraquara | F6: Araraquara
A7: Araraquara | B7: Central | C7: Rincão | D7: 6943284 | E7: Maternidade Gota de Leite de Araraquara | F7: Araraquara
A8: Araraquara | B8: Central | C8: Santa Lucia | D8: 6943284 | E8: Maternidade Gota de Leite de Araraquara | F8: Araraquara
A9: Araraquara | B9: Central | C9: Trabiju | D9: 6943284 | E9: Maternidade Gota de Leite de Araraquara | F9: Araraquara
A10: Araraquara | B10: Centro-Oeste | C10: Borborema | D10: 2081989 | E10: Hospital São Sebastião - Borborema | F10: Borborema
A11: Araraquara | B11: Centro-Oeste | C11: Ibitinga | D11: 2082640 | E11: Santa Casa de Caridade e Maternidade Ibitinga | F11: Ibitinga
A12: Araraquara | B12: Centro-Oeste | C12: Itápolis | D12: 2079836 | E12: Santa Casa de Misericórdia Itápolis | F12: Itápolis
A13: Araraquara | B13: Centro-Oeste | C13: Nova Europa | D13: 2747685 | E13: Santa Casa de Misericórdia de Nova Europa | F13: Nova Europa
... A25: Araraquara | B25: Norte | C25: Taquaritinga | D25: 2078295 | E25: Santa Casa de Taquaritinga | F25: Taquaritinga

Sheet tabela 2 AGAR
A1: RRAS: | B1: ='Tabela 1 APS - Descr.'!B1
A4: CAPACIDADE OPERACIONAL PRÉ-NATAL DE ALTO RISCO
A6: TOTAL DE GESTANTES SUSDEPENDENTES ESTIMADAS/ANO = VIDE TABELA 1
A7: TOTAL DE GESTANTES DE ALTO RISCO SUSDEPENDENTES ESTIMADAS/ANO = 15% DAS GESTANTES SUSDEPENDENTES ESTIMADAS
A8: PREVISÃO DE NÚMERO DE CONSULTA DE PRÉ-NATAL ALTO RISCO/ANO = Nº DE GESTANTES DE ALTO RISCO ESTIMADAS X 12 CONSULTAS
A9: OBSERVAR QUE O RESULTADO OBTIDO É O TOTAL DE CONSULTAS NECESSÁRIAS PARA A RRAS/REGIÃO/MUNICIPIO/ANO . O ESTABELECIMENTO DEVERÁ PREVER SE HÁ NECESSIDADE DE CONTRATAÇÃO DE RH E SERVIÇOS PARA O ATENDIMENTO DE 100% DAS CONSULTAS ESTIMADAS
A10: PARA ESTIMATIVA DE CAPACIDADE DE CONSULTAS DO AAE(AGAR)/ANO CONSIDERAR DE 3 A 4 CONSULTAS /HORA/PROFISSIONAL, ESSA INFORMAÇÃO DEVE SER OBTIDA JUNTO AO SERVIÇO DE ALTO RISCO.
A11: NÃO ESQUECER DE COLOCAR O NOME DO ESTABELECIMENTO E CNES
A14: tabela: 2 Cobertura de Acesso e capacidade instalada na Atenção Ambulatorial Especializada (AAE) - PRÉ-NATAL DE ALTO RISCO (AGAR)
A16: DRS | B16: RS | C16: MUNICIPIO | D16: TOTAL DE GESTANTES SUSDEPENDENTES ESTIMADAS/ANO (trazer da tabela1 APS) | E16: TOTAL DE GESTANTES DE ALTO RISCO SUSDEPENDENTES ESTIMADAS/ANO | F16: PREVISÃO DE NÚMERO DE CONSULTA DE ALTO RISCO PARA MUNICIPIO/ANO | G16: CNES/ESTABELECIMENTO PARA REFERENCIA PARA AAE (AGAR) | H16: ESTIMATIVA DE CAPACIDADE PARA CONSULTAS DO AAE/ANO | I16: GESTÃO | J16: INDICADO PARA HABILITAÇÃO TIPO I OU TIPO II | K16: CONSULTA REGULADA (S) OU (N) | L16: CNES/ESTABELECIMENTO DA REFERENCIA PARA PARTO DE ALTO RISCO | M16: MUNICIPIO
A17: III-ARARAQUARA | B17: CENTRAL | C17: Américo Brasiliense | D17: ='Tabela 1 APS - Descr.'!I27 -> 217.9848 | E17: =D17*15/100 -> 32.69772 | F17: =E17*12 -> 392.37264 | G17: 9424377 | H17: 7920 | I17: Municipal | J17: II | K17: S | L17: 6943284 | M17: Araraquara
A18: III-ARARAQUARA | B18: CENTRAL | C18: Araraquara | D18: ='Tabela 1 APS - Descr.'!I28 -> 1411.2537 | E18: =D18*15/100 -> 211.68805 | F18: =E18*12 -> 2540.2566 | G18: 9424377 | H18: 7920 | I18: Municipal | J18: II | K18: S | L18: 6943284 | M18: Araraquara
A19: III-ARARAQUARA | B19: CENTRAL | C19: Boa Esperança do Sul | D19: ='Tabela 1 APS - Descr.'!I29 -> 125.18682 | E19: =D19*15/100 -> 18.778023 | F19: =E19*12 -> 225.33628 | G19: 9424377 | H19: 7920 | I19: Municipal | J19: II | K19: S | L19: 6943284 | M19: Araraquara
A20: III-ARARAQUARA | B20: CENTRAL | C20: Gavião Peixoto | D20: ='Tabela 1 APS - Descr.'!I30 -> 45.10451 | E20: =D20*15/100 -> 6.7656765 | F20: =E20*12 -> 81.188118 | G20: 9424377 | H20: 7920 | I20: Municipal | J20: II | K20: S | L20: 6943284 | M20: Araraquara
A21: III-ARARAQUARA | B21: CENTRAL | C21: Motuca | D21: ='Tabela 1 APS - Descr.'!I31 -> 21.96128 | E21: =D21*15/100 -> 3.294192 | F21: =E21*12 -> 39.530304 | G21: 9424377 | H21: 7920 | I21: Municipal | J21: II | K21: S | L21: 6943284 | M21: Araraquara
A22: III-ARARAQUARA | B22: CENTRAL | C22: Rincão | D22: ='Tabela 1 APS - Descr.'!I32 -> 59.73264 | E22: =D22*15/100 -> 8.959896 | F22: =E22*12 -> 107.51875 | G22: 9424377 | H22: 7920 | I22: Municipal | J22: II | K22: S | L22: 6943284 | M22: Araraquara
A23: III-ARARAQUARA | B23: CENTRAL | C23: Santa Lucia | D23: ='Tabela 1 APS - Descr.'!I33 -> 42.32514 | E23: =D23*15/100 -> 6.348771 | F23: =E23*12 -> 76.185252 | G23: 9424377 | H23: 7920 | I23: Municipal | J23: II | K23: S | L23: 6943284 | M23: Araraquara
A24: III-ARARAQUARA | B24: CENTRAL | C24: Trabiju | D24: ='Tabela 1 APS - Descr.'!I34 -> 15.25359 | E24: =D24*15/100 -> 2.2880385 | F24: =E24*12 -> 27.456462 | G24: 9424377 | H24: 7920 | I24: Municipal | J24: II | K24: S | L24: 6943284 | M24: Araraquara
A25: III-ARARAQUARA | B25: CENTRO-OESTE | C25: Borborema | D25: ='Tabela 1 APS - Descr.'!I35 -> 122.04544 | E25: =D25*15/100 -> 18.306816 | F25: =E25*12 -> 219.68179 | G25: 2090961 | H25: 2640 | I25: Estadual | J25: II | K25: S | L25: 2090961 | M25: Matão
A26: III-ARARAQUARA | B26: CENTRO-OESTE | C26: Ibitinga | D26: ='Tabela 1 APS - Descr.'!I36 -> 600.644 | E26: =D26*15/100 -> 90.0966 | F26: =E26*12 -> 1081.1592 | G26: 2090961 | H26: 2640 | I26: Estadual | J26: II | K26: S | L26: 2090961 | M26: Matão
A27: III-ARARAQUARA | B27: CENTRO-OESTE | C27: Itápolis | D27: ='Tabela 1 APS - Descr.'!I37 -> 315.60375 | E27: =D27*15/100 -> 47.340562 | F27: =E27*12 -> 568.08675 | G27: 2090961 | H27: 2640 | I27: Estadual | J27: II | K27: S | L27: 2090961 | M27: Matão
A28: III-ARARAQUARA | B28: CENTRO-OESTE | C28: Nova Europa | D28: ='Tabela 1 APS - Descr.'!I38 -> 54.46584 | E28: =D28*15/100 -> 8.169876 | F28: =E28*12 -> 98.038512 | G28: 2090961 | H28: 2640 | I28: Estadual | J28: II | K28: S | L28: 2090961 | M28: Matão
... A40: III-ARARAQUARA | B40: NORTE | C40: Taquaritinga | D40: ='Tabela 1 APS - Descr.'!I50 -> 380.06364 | E40: =D40*15/100 -> 57.009546 | F40: =E40*12 -> 684.11455 | G40: 2090961 | H40: 2640 | I40: Estadual | J40: II | K40: S | L40: 2090961 | M40: Matão

Sheet tabela 3 ANEO
A1: RRAS: | B1: ='Tabela 1 APS - Descr.'!B1
A3: CAPACIDADE OPERACIONAL ALTO RISCO - ANEO
A4: UNEO = UNIDADE NEONATAL
A6: (1) ESTIMATIVA DE RECEM NASCIDO DE ALTO RISCO /ANEO: CONSIDERAR AS SAIDAS DA DA UNEO NO ANO ANTERIOR
A7: (2) ESTIMATIVA PARA CONSULTAS MÉDICAS 2.500g = 92% DOS RN DE ALTO RISCO ESTIMADOS X 3 CONSULTAS
A8: (3) ESTIMATIVA PARA CONSULTAS DE ENFERMAGEM 2.500g = 92% DOS RN DE ALTO RISCO ESTIMADOS X 4 CONSULTAS
A9: (4) ESTIMATIVA PARA CONSULTAS MÉDICA PESO < 2.500G = 8% DOS RN DE ALTO RISCO ESTIMADOS X 7 CONSULTAS
A10: (5) ESTIMATIVA PARA CONSULTAS DE ENFERMAGEM PESO < 2.500GDOS 8% RN DE ALTO RISCO ESTIMADOS X 6 CONSULTAS
A16: Tabela 3 : Cobertura de Acesso e capacidade instalada na Atenção Ambulatorial Especializada (AAE) - ANEO
A18: DRS | B18: RS | C18: MUNICIPIO | D18: ESTIMATIVA DE RECEM NASCIDO DE ALTO RISCO /ANEO (1) | E18: CNES/ESTABELECIMENTO PARA REFERENCIA PARA AAE (ANEO) | F18: GESTÃO | G18: MUNICIPIO | H18: ESTIMATIVA PARA CONSULTAS MÉDICA DO ANEO > 2.500G (2) | I18: ESTIMATIVA PARA CONSULTAS ENFERMAGEM DO ANEO > 2.500G (3) | J18: ESTIMATIVA PARA CONSULTAS MÉDICA DO ANEO PESO < 2.500G (4) | K18: ESTIMATIVA PARA CONSULTAS DE ENFERMAGEM DO ANEO < 2.500G (5) | L18: CNES/ESTABELECIMENTO DE REFERENCIA HOSPITALAR PARA O AAE (ANEO) | M18: MUNICIPIO | N18: CONSULTA REGULADA (S) OU (N)
A19: III-ARARAQUARA | B19: CENTRAL | C19: Américo Brasiliense | D19: 36 | E19: 2080931 | F19: MUNICIPAL | G19: São Carlos | H19: =(D19*92/100)*3 -> 99.36 | I19: =(D19*92/100)*4 -> 132.48 | J19: =(D19*8/100)*7 -> 20.16 | K19: =(D19*8/100)*6 -> 17.28 | L19: 2080931 | M19: São Carlos | N19: S
A20: III-ARARAQUARA | B20: CENTRAL | C20: Araraquara | D20: 230 | E20: 2080931 | F20: MUNICIPAL | G20: São Carlos | H20: =(D20*92/100)*3 -> 634.8 | I20: =(D20*92/100)*4 -> 846.4 | J20: =(D20*8/100)*7 -> 128.8 | K20: =(D20*8/100)*6 -> 110.4 | L20: 2080931 | M20: São Carlos | N20: S
A21: III-ARARAQUARA | B21: CENTRAL | C21: Boa Esperança do Sul | D21: 19 | E21: 2080931 | F21: MUNICIPAL | G21: São Carlos | H21: =(D21*92/100)*3 -> 52.44 | I21: =(D21*92/100)*4 -> 69.92 | J21: =(D21*8/100)*7 -> 10.64 | K21: =(D21*8/100)*6 -> 9.12 | L21: 2080931 | M21: São Carlos | N21: S
A22: III-ARARAQUARA | B22: CENTRAL | C22: Gavião Peixoto | D22: 5 | E22: 2080931 | F22: MUNICIPAL | G22: São Carlos | H22: =(D22*92/100)*3 -> 13.8 | I22: =(D22*92/100)*4 -> 18.4 | J22: =(D22*8/100)*7 -> 2.8 | K22: =(D22*8/100)*6 -> 2.4 | L22: 2080931 | M22: São Carlos | N22: S
A23: III-ARARAQUARA | B23: CENTRAL | C23: Rincão | D23: 22 | E23: 2080931 | F23: MUNICIPAL | G23: São Carlos | H23: =(D23*92/100)*3 -> 60.72 | I23: =(D23*92/100)*4 -> 80.96 | J23: =(D23*8/100)*7 -> 12.32 | K23: =(D23*8/100)*6 -> 10.56 | L23: 2080931 | M23: São Carlos | N23: S
A24: III-ARARAQUARA | B24: CENTRAL | C24: Santa Lúcia | D24: 1 | E24: 2080931 | F24: MUNICIPAL | G24: São Carlos | H24: =(D24*92/100)*3 -> 2.76 | I24: =(D24*92/100)*4 -> 3.68 | J24: =(D24*8/100)*7 -> 0.56 | K24: =(D24*8/100)*6 -> 0.48 | L24: 2080931 | M24: São Carlos | N24: S
A25: III-ARARAQUARA | B25: CENTRAL | C25: Trabiju | D25: 3 | E25: 2080931 | F25: MUNICIPAL | G25: São Carlos | H25: =(D25*92/100)*3 -> 8.28 | I25: =(D25*92/100)*4 -> 11.04 | J25: =(D25*8/100)*7 -> 1.68 | K25: =(D25*8/100)*6 -> 1.44 | L25: 2080931 | M25: São Carlos | N25: S
A26: III-ARARAQUARA | B26: CENTRO OESTE | C26: Borborema | D26: 16 | E26: 2080931 | F26: MUNICIPAL | G26: São Carlos | H26: =(D26*92/100)*3 -> 44.16 | I26: =(D26*92/100)*4 -> 58.88 | J26: =(D26*8/100)*7 -> 8.96 | K26: =(D26*8/100)*6 -> 7.68 | L26: 2080931 | M26: São Carlos | N26: S
A27: III-ARARAQUARA | B27: CENTRO OESTE | C27: Ibitinga | D27: 52 | E27: 2080931 | F27: MUNICIPAL | G27: São Carlos | H27: =(D27*92/100)*3 -> 143.52 | I27: =(D27*92/100)*4 -> 191.36 | J27: =(D27*8/100)*7 -> 29.12 | K27: =(D27*8/100)*6 -> 24.96 | L27: 2080931 | M27: São Carlos | N27: S
A28: III-ARARAQUARA | B28: CENTRO OESTE | C28: Itápolis | D28: 22 | E28: 2080931 | F28: MUNICIPAL | G28: São Carlos | H28: =(D28*92/100)*3 -> 60.72 | I28: =(D28*92/100)*4 -> 80.96 | J28: =(D28*8/100)*7 -> 12.32 | K28: =(D28*8/100)*6 -> 10.56 | L28: 2080931 | M28: São Carlos | N28: S
A29: III-ARARAQUARA | B29: CENTRO OESTE | C29: Nova Europa | D29: 8 | E29: 2080931 | F29: MUNICIPAL | G29: São Carlos | H29: =(D29*92/100)*3 -> 22.08 | I29: =(D29*92/100)*4 -> 29.44 | J29: =(D29*8/100)*7 -> 4.48 | K29: =(D29*8/100)*6 -> 3.84 | L29: 2080931 | M29: São Carlos | N29: S
A30: III-ARARAQUARA | B30: CENTRO OESTE | C30: Tabatinga | D30: 8 | E30: 2080931 | F30: MUNICIPAL | G30: São Carlos | H30: =(D30*92/100)*3 -> 22.08 | I30: =(D30*92/100)*4 -> 29.44 | J30: =(D30*8/100)*7 -> 4.48 | K30: =(D30*8/100)*6 -> 3.84 | L30: 2080931 | M30: São Carlos | N30: S
... A41: III-ARARAQUARA | B41: NORTE | C41: Taquaritinga | D41: 51 | E41: 2080931 | F41: MUNICIPAL | G41: São Carlos | H41: =(D41*92/100)*3 -> 140.76 | I41: =(D41*92/100)*4 -> 187.68 | J41: =(D41*8/100)*7 -> 28.56 | K41: =(D41*8/100)*6 -> 24.48 | L41: 2080931 | M41: São Carlos | N41: S

Sheet totais TABELA 4

Sheet tabela 4  leitos existentes
A1: RRAS: | B1: ='Tabela 1 APS - Descr.'!B1
A3: TABELA 4 : LEITOS OBSTETRICOS E NEONATAIS EXISTENTES NA REDE
A5: OS ESTABELECIMENTOS CLASSIFICADOS COMO SERVIÇO DE ATENDIMENTO SECUNDÁRIO OU TERCIÁRIO A GESTAÇÃO DE ALTO RISCO DEVEM SER APONTADOS
A6: INSERIR SOMENTE OS LEITOS HABILITADOS, OS EXISTENTES DEVEM FAZER PARTE DA TABELA LEITOS A SEREM HABILITADOS
A7: OS LEITOS GAR FAZEM PARTE DOS LEITOS OBSTETRICOS, APONTAR O NÚMERO DE LEITOS HABILITADOS.
F10: NUMERO DE LEITOS EXISTENTES DA REDE MATERNA E INFANTIL
A12: DRS | B12: REGIÃO DE SAUDE | C12: CNES/ESTABELECIMENTO | D12: MUNICIPIO | E12: GESTÃO | F12: OBSTETRICOS | G12: GAR I | H12: GAR II | I12: SERVIÇO DE ATENDIMENTO SECUNDÁRIO OU TERCIÁRIO A GESTAÇÃO DE ALTO RISCO | J12: UTI ADULTO | K12: UTIN II | L12: UTIN III | M12: UCINCO | N12: UCINCA | O12: CPN I 3 LEITOS | P12: CPN I 5 LEITOS | Q12: CPN II 3 LEITOS | R12: CPN II 5 LEITOS | S12: CGBP 10 LEITOS | T12: CGBP 15 LEITOS | U12: CGBP 20 LEITOS | V12: BLH
A13: III-ARARAQUARA | B13: CENTRAL | C13: 6943284-MATERNIDADE GOTA DE LEITE DE ARARAQUARA | D13: Araraquara | E13: MUNICIPAL | F13: 36 | H13: 3 | K13: 7 | M13: 9 | N13: 3 | S13: 1 | V13: Não
A14: III-ARARAQUARA | B14: CENTRO OESTE | C14: 2081989 HOSP SÃO SEBASTIÃO BORBOREMA | D14: Borborema | E14: MUNICIPAL | F14: 2 | V14: Não
A15: III-ARARAQUARA | B15: CENTRO OESTE | C15: 2082640 SANTA CASA DE CARIDADE E MATERNIDADE DE IBITINGA | D15: IBITINGA | E15: MUNICIPAL | F15: 6 | V15: Não
A16: III-ARARAQUARA | B16: CENTRO OESTE | C16: 2079836 SANTA CASA DE MISERICORDIA ITAPOLIS | D16: ITAPOLIS | E16: MUNICIPAL | F16: 4 | V16: Não
A17: III-ARARAQUARA | B17: CENTRO OESTE | C17: 2079399 SANTA CASA DE MISERICORDIA TABATINGA SP | D17: TABATINGA | E17: MUNICIPAL | F17: 5 | V17: Não
A18: III-ARARAQUARA | B18: CENTRO OESTE | C18: 2747685 SANTA CASA DE MISERICORDIA NOVA EUROPA | D18: NOVA EUROPA | E18: MUNICIPAL | F18: 1 | V18: Não
A19: III-ARARAQUARA | B19: CORAÇÃO | C19: 2081717 SANTA CASA DESCALVADO | D19: DESCALVADO | E19: MUNICIPAL | F19: 3 | V19: Não
A20: III-ARARAQUARA | B20: CORAÇÃO | C20: 2747022 CASA DE SAUDE SANTA EMILIA | D20: Dourado | E20: MUNICIPAL | F20: 4 | V20: Não
A21: III-ARARAQUARA | B21: CORAÇÃO | C21: 2092395 HOSPITAL MUNICIPAL Ibaté | D21: Ibaté | E21: MUNICIPAL | F21: 7 | V21: Não
A22: III-ARARAQUARA | B22: CORAÇÃO | C22: 2747693 SANTA CASA DE MISERICORDIA RIBEIRAO BONITO | D22: Ribeirão Bonito | E22: MUNICIPAL | F22: 2 | V22: Não
A23: III-ARARAQUARA | B23: CORAÇÃO | C23: 2082322 HOSPITAL DONA BALBINA | D23: Porto Ferreira | E23: MUNICIPAL | F23: 8 | V23: Não
A24: III-ARARAQUARA | B24: CORAÇÃO | C24: 2080931-SANTA CASA DE SÃO CARLOS | D24: São Carlos | E24: MUNICIPAL | F24: 25 | H24: 4 | J24: 30 | K24: 5 | S24: 1 | V24: Sim
A25: III-ARARAQUARA | B25: NORTE | C25: 2090961-SANTA CASA DE MATÃO | D25: Matão | E25: ESTADUAL | F25: 20 | H25: 4 | J25: 20 | L25: 5 | M25: 5 | N25: 3 | S25: 1 | V25: Não
A26: III-ARARAQUARA | B26: NORTE | C26: 2078295-SANTA CASA DE TAQUARITINGA | D26: Taquaritinga | E26: MUNICIPAL | F26: 11 | K26: 4 | M26: 4 | N26: 1 | V26: Não

Sheet tabela 5 necessidade
A1: RRAS: | B1: ='Tabela 1 APS - Descr.'!B1
E3: NUMERO DE LEITOS NECESSÁRIOS PARA A REDE MATERNA E INFANTIL
A4: DRS | B4: REGIÃO DE SAUDE | C4: NASCIDOS VIVOS SUSDEPENDENTES (trazer da tabela1 APS) | D4: TOTAL DE GESTANTES SUSDEPENDENTES ESTIMADAS/ANO (trazer da tabela1 APS) | E4: OBSTETRICOS | F4: GAR | G4: UTI ADULTO | H4: UTIN | I4: UCINCO | J4: UCINCA | K4: CPN I | M4: CPN II | O4: CGBP | R4: BLH
K5: 3 LEITOS | L5: 5 LEITOS | M5: 3 LEITOS | N5: 5 LEITOS | O5: 10 LEITOS | P5: 15 LEITOS | Q5: 20 LEITOS
A6: III-ARARAQUARA | B6: CENTRAL | C6: 1897 | D6: 2086 | E6: =((D6*2.5)/(365*0.7))*1.21 -> 24.69726 | F6: =E6*15/100 -> 3.704589 | G6: =(E6*6/100) -> 1.4818356 | H6: =C6*2/1000 -> 3.794 | I6: =C6*2/1000 -> 3.794 | J6: =C6*1/1000 -> 1.897
A7: III-ARARAQUARA | B7: CENTRO-OESTE | C7: 1286 | D7: 1415 | E7: =((D7*2.5)/(365*0.7))*1.21 -> 16.752935 | F7: =E7*15/100 -> 2.5129403 | G7: =(E7*6/100) -> 1.0051761 | H7: =C7*2/1000 -> 2.572 | I7: =C7*2/1000 -> 2.572 | J7: =C7*1/1000 -> 1.286
A8: III-ARARAQUARA | B8: CORAÇÃO | C8: 2761 | D8: 3037 | E8: =((D8*2.5)/(365*0.7))*1.21 -> 35.956654 | F8: =E8*15/100 -> 5.393498 | G8: =(E8*6/100) -> 2.1573992 | H8: =C8*2/1000 -> 5.522 | I8: =C8*2/1000 -> 5.522 | J8: =C8*1/1000 -> 2.761
A9: III-ARARAQUARA | B9: NORTE | C9: 1028 | D9: 1131 | E9: =((D9*2.5)/(365*0.7))*1.21 -> 13.390509 | F9: =E9*15/100 -> 2.0085763 | G9: =(E9*6/100) -> 0.80343053 | H9: =C9*2/1000 -> 2.056 | I9: =C9*2/1000 -> 2.056 | J9: =C9*1/1000 -> 1.028
E13: NUMERO DE LEITOS EXISTENTES NA REDE MATERNA E INFANTIL (trazer da aba "totais TABELA 4")
A14: DRS | B14: REGIÃO DE SAUDE | C14: NASCIDOS VIVOS SUSDEPENDENTES (trazer da tabela1 APS) | D14: TOTAL DE GESTANTES SUSDEPENDENTES ESTIMADAS/ANO (trazer da tabela1 APS) | E14: OBSTETRICOS | F14: GAR | G14: UTI ADULTO | H14: UTIN | I14: UCINCO | J14: UCINCA | K14: CPN I 3 LEITOS | M14: CPN II | O14: CGBP | R14: BLH
K15: 3 LEITOS | L15: 5 LEITOS | M15: 3 LEITOS | N15: 5 LEITOS | O15: 10 LEITOS | P15: 15 LEITOS | Q15: 20 LEITOS
A16: =A6 -> III-ARARAQUARA | B16: =B6 -> CENTRAL | C16: =C6 -> 1897 | D16: =D6 -> 2086 | E16: 36 | F16: 3 | H16: 7 | I16: 9 | J16: 3 | O16: 1
A17: =A7 -> III-ARARAQUARA | B17: =B7 -> CENTRO-OESTE | C17: =C7 -> 1286 | D17: =D7 -> 1415 | E17: 18 | F17: 0
A18: =A8 -> III-ARARAQUARA | B18: =B8 -> CORAÇÃO | C18: =C8 -> 2761 | D18: =D8 -> 3037 | E18: 49 | F18: 4 | G18: 30 | H18: 5 | O18: 1
A19: =A9 -> III-ARARAQUARA | B19: =B9 -> NORTE | C19: =C9 -> 1028 | D19: =D9 -> 1131 | E19: 31 | F19: 4 | G19: 20 | H19: 9 | I19: 9 | J19: 4 | O19: 1
A20: =#REF! -> #REF! | B20: =#REF! -> #REF! | C20: =#REF! -> #REF! | D20: =#REF! -> #REF! | E20: 66 | F20: 5 | G20: 45 | H20: 8 | I20: 8 | J20: 4
A21: =#REF! -> #REF! | B21: =#REF! -> #REF! | C21: =#REF! -> #REF! | D21: =#REF! -> #REF! | E21: 28 | F21: 0 | G21: 0 | H21: 0 | I21: 0 | J21: 0 | K21: 0 | L21: 0 | M21: 0 | N21: 0 | O21: 0 | P21: 0 | Q21: 0 | R21: 0
A22: =#REF! -> #REF! | B22: =#REF! -> #REF! | C22: =#REF! -> #REF! | D22: =#REF! -> #REF! | E22: 23 | F22: 0 | G22: 0 | H22: 0 | I22: 0 | J22: 0 | K22: 0 | L22: 0 | M22: 0 | N22: 0 | O22: 0 | P22: 0 | Q22: 0 | R22: 0
A23: =#REF! -> #REF! | B23: =#REF! -> #REF! | C23: =#REF! -> #REF! | D23: =#REF! -> #REF! | E23: 40 | F23: 9 | G23: 4 | H23: 13 | I23: 0 | J23: 0 | K23: 0 | L23: 0 | M23: 0 | N23: 0 | O23: 0 | P23: 0 | Q23: 0 | R23: 1
A24: =#REF! -> #REF! | B24: =#REF! -> #REF! | C24: =#REF! -> #REF! | D24: =#REF! -> #REF! | E24: 110 | F24: 15 | G24: 12 | H24: 36 | I24: 26 | J24: 2 | R24: 1
A25: =#REF! -> #REF! | B25: =#REF! -> #REF! | C25: =#REF! -> #REF! | D25: =#REF! -> #REF! | E25: 62 | F25: 0 | G25: 2 | H25: 6 | I25: 5 | J25: 1
A26: =#REF! -> #REF! | B26: =#REF! -> #REF! | C26: =#REF! -> #REF! | D26: =#REF! -> #REF! | E26: 24 | F26: 0 | G26: 0 | H26: 0 | I26: 0 | J26: 0
A27: =#REF! -> #REF! | B27: =#REF! -> #REF! | C27: =#REF! -> #REF! | D27: =#REF! -> #REF!
A28: TOTAL DE LEITOS EXISTENTES | E28: =SUM(E16:E27) -> 487 | F28: =SUM(F16:F27) -> 40 | G28: =SUM(G16:G27) -> 113 | H28: =SUM(H16:H27) -> 84 | I28: =SUM(I16:I27) -> 57 | J28: =SUM(J16:J27) -> 14 | K28: =SUM(K16:K27) -> 0 | L28: =SUM(L16:L27) -> 0 | ... R28: =SUM(R16:R27) -> 2
E33: ANÁLISE DA SUFICIÊNCIA DE LEITOS PARA A REDE MATERNA E INFANTIL
A34: DRS | B34: REGIÃO DE SAUDE | C34: NASCIDOS VIVOS SUSDEPENDENTES (trazer da tabela1 APS) | D34: TOTAL DE GESTANTES SUSDEPENDENTES ESTIMADAS/ANO (trazer da tabela1 APS) | E34: OBSTETRICOS | F34: GAR | G34: UTI ADULTO | H34: UTIN | I34: UCINCO | J34: UCINCA | K34: CPN I | M34: CPN II | O34: CGBP | R34: BLH
K35: 3 LEITOS | L35: 5 LEITOS | M35: 3 LEITOS | N35: 5 LEITOS | O35: 10 LEITOS | P35: 15 LEITOS | Q35: 20 LEITOS
A36: =A6 -> III-ARARAQUARA | B36: =B6 -> CENTRAL | C36: =C6 -> 1897 | D36: =D6 -> 2086 | E36: =E16-E6 -> 11.30274 | F36: =F16-F6 -> -0.70458904 | G36: =G16-G6 -> -1.4818356 | H36: =H16-H6 -> 3.206 | I36: =I16-I6 -> 5.206 | J36: =J16-J6 -> 1.103
A37: =A7 -> III-ARARAQUARA | B37: =B7 -> CENTRO-OESTE | C37: =C7 -> 1286 | D37: =D7 -> 1415 | E37: =E17-E7 -> 1.2470646 | F37: =F17-F7 -> -2.5129403 | G37: =G17-G7 -> -1.0051761 | H37: =H17-H7 -> -2.572 | I37: =I17-I7 -> -2.572 | J37: =J17-J7 -> -1.286
A38: =A8 -> III-ARARAQUARA | B38: =B8 -> CORAÇÃO | C38: =C8 -> 2761 | D38: =D8 -> 3037 | E38: =E18-E8 -> 13.043346 | F38: =F18-F8 -> -1.393498 | G38: =G18-G8 -> 27.842601 | H38: =H18-H8 -> -0.522 | I38: =I18-I8 -> -5.522 | J38: =J18-J8 -> -2.761
A39: =A9 -> III-ARARAQUARA | B39: =B9 -> NORTE | C39: =C9 -> 1028 | D39: =D9 -> 1131 | E39: =E19-E9 -> 17.609491 | F39: =F19-F9 -> 1.9914237 | G39: =G19-G9 -> 19.196569 | H39: =H19-H9 -> 6.944 | I39: =I19-I9 -> 6.944 | J39: =J19-J9 -> 2.972
A40: =#REF! -> #REF! | B40: =#REF! -> #REF! | C40: =#REF! -> #REF! | D40: =#REF! -> #REF! | E40: =E20-#REF! -> #REF! | F40: =F20-#REF! -> #REF! | G40: =G20-#REF! -> #REF! | H40: =H20-#REF! -> #REF! | I40: =I20-#REF! -> #REF! | J40: =J20-#REF! -> #REF!
A41: =#REF! -> #REF! | B41: =#REF! -> #REF! | C41: =#REF! -> #REF! | D41: =#REF! -> #REF! | E41: =E21-#REF! -> #REF! | F41: =F21-#REF! -> #REF! | G41: =G21-#REF! -> #REF! | H41: =H21-#REF! -> #REF! | I41: =I21-#REF! -> #REF! | J41: =J21-#REF! -> #REF!
A42: =#REF! -> #REF! | B42: =#REF! -> #REF! | C42: =#REF! -> #REF! | D42: =#REF! -> #REF! | E42: =E22-#REF! -> #REF! | F42: =F22-#REF! -> #REF! | G42: =G22-#REF! -> #REF! | H42: =H22-#REF! -> #REF! | I42: =I22-#REF! -> #REF! | J42: =J22-#REF! -> #REF!
A43: =#REF! -> #REF! | B43: =#REF! -> #REF! | C43: =#REF! -> #REF! | D43: =#REF! -> #REF! | E43: =E23-#REF! -> #REF! | F43: =F23-#REF! -> #REF! | G43: =G23-#REF! -> #REF! | H43: =H23-#REF! -> #REF! | I43: =I23-#REF! -> #REF! | J43: =J23-#REF! -> #REF!
A44: =#REF! -> #REF! | B44: =#REF! -> #REF! | C44: =#REF! -> #REF! | D44: =#REF! -> #REF! | E44: =E24-#REF! -> #REF! | F44: =F24-#REF! -> #REF! | G44: =G24-#REF! -> #REF! | H44: =H24-#REF! -> #REF! | I44: =I24-#REF! -> #REF! | J44: =J24-#REF! -> #REF!
A45: =#REF! -> #REF! | B45: =#REF! -> #REF! | C45: =#REF! -> #REF! | D45: =#REF! -> #REF! | E45: =E25-#REF! -> #REF! | F45: =F25-#REF! -> #REF! | G45: =G25-#REF! -> #REF! | H45: =H25-#REF! -> #REF! | I45: =I25-#REF! -> #REF! | J45: =J25-#REF! -> #REF!
A46: =#REF! -> #REF! | B46: =#REF! -> #REF! | C46: =#REF! -> #REF! | D46: =#REF! -> #REF! | E46: =E27-#REF! -> #REF! | F46: =F27-#REF! -> #REF! | G46: =G27-#REF! -> #REF! | H46: =H27-#REF! -> #REF! | I46: =I27-#REF! -> #REF! | J46: =J27-#REF! -> #REF!
A47: TOTAL DE LEITOS NECESSÁRIOS | E47: =SUM(E36:E46) -> #REF! | F47: =SUM(F36:F46) -> #REF! | G47: =SUM(G36:G46) -> #REF! | H47: =SUM(H36:H46) -> #REF! | I47: =SUM(I36:I46) -> #REF! | J47: =SUM(J36:J46) -> #REF!
C81: nº de CPN
...

Sheet tabela 6 rede de serviços final
A1: RRAS: | B1: ='Tabela 1 APS - Descr.'!B1
A3: (1) Nº ANUAL DE PARTOS: Considerar para este plano a média de produção de partos dos anos de 2019/2020 e 2021
A4: (2) OBSTETRICOS : Somente assinalar com S(Sim) ou N(Não) o tipo de habilitação da maternidade, lembrar que serviços que tem leitos de alto risco não são elegíveis para receber o custeio global (MAB)
A6: (3) CGBP: Assinalar com Existente (E) ou Novo (N)
A7: (4) BLH ( banco de Leite Humano): Assinalar com Existente (E) ou Novo (N)
A8: LEITOS EXISTENTES: Leitos que já estão habilitados
A9: LEITOS NOVOS: Leitos a serem habilitados de acordo com a necessidade da Região
A10: TOTAL: Leitos totais por componente por maternidade
A12: Tabela 6: Serviços que compõe a RRAS, número de leitos existentes e novos.
G13: NUMERO DE LEITOS
A14: DRS | B14: REGIÃO DE SAUDE | C14: CNES/ESTABELECIMENTO | D14: MUNICIPIO | E14: GESTÃO | F14: Nº ANUAL DE PARTOS (1) | G14: OBSTETRICOS (2) | H14: GAR | K14: UTIN | N14: UCINCO | Q14: UCINCA | T14: CPN I | V14: CPN II | X14: CGBP | AA14: BLH
T15: 3 LEITOS | U15: 5 LEITOS | V15: 3 LEITOS | W15: 5 LEITOS | X15: 10 LEITOS | Y15: 15 LEITOS | Z15: 20 LEITOS
G16: HABILITAÇÃO MAB | H16: EXISTENTE | I16: NOVO | J16: TOTAL | K16: EXISTENTE | L16: NOVO | M16: TOTAL | N16: EXISTENTE | O16: NOVO | P16: TOTAL | Q16: EXISTENTE | R16: NOVO | S16: TOTAL | T16: STATUS | U16: STATUS | V16: STATUS | W16: STATUS | X16: STATUS | Y16: STATUS | Z16: STATUS | AA16: STATUS
A17: III-ARARAQUARA | B17: CENTRAL | C17: 6943284 MATERNIDADE GOTA DE LEITE DE ARARAQUARA | D17: ARARAQUARA | E17: MUNICIPAL | F17: 1997 | G17: S | H17: 3 | I17: 5 | J17: =SUM(H17:I17) -> 8 | K17: 7 | M17: =SUM(K17:L17) -> 7 | N17: 9 | P17: =SUM(N17:O17) -> 9 | Q17: 3 | S17: =SUM(Q17:R17) -> 3 | V17: N | Y17: E
A18: III-ARARAQUARA | B18: CENTRO OESTE | C18: 2079399 SANTA CASA DE MISERICORDIA TABATINGA SP | D18: TABATINGA | E18: MUNICIPAL | F18: 83 | J18: =SUM(H18:I18) -> 0 | M18: =SUM(K18:L18) -> 0 | P18: =SUM(N18:O18) -> 0 | S18: =SUM(Q18:R18) -> 0
A19: III-ARARAQUARA | B19: CENTRO OESTE | C19: 2079836 SANTA CASA DE MISERICORDIA ITAPOLIS | D19: ITÁPOLIS | E19: MUNICIPAL | F19: 229 | J19: =SUM(H19:I19) -> 0 | M19: =SUM(K19:L19) -> 0 | P19: =SUM(N19:O19) -> 0 | S19: =SUM(Q19:R19) -> 0
A20: III-ARARAQUARA | B20: CENTRO OESTE | C20: 2081989 HOSPITAL SAO SEBASTIAO DE BORBOREMA | D20: BORBOREMA | E20: MUNICIPAL | F20: 51 | J20: =SUM(H20:I20) -> 0 | M20: =SUM(K20:L20) -> 0 | P20: =SUM(N20:O20) -> 0 | S20: =SUM(Q20:R20) -> 0
A21: III-ARARAQUARA | B21: CENTRO OESTE | C21: 2082640 SANTA CASA DE CARIDADE E MATERNIDADE IBITINGA | D21: IBITINGA | E21: MUNICIPAL | F21: 475 | G21: S | J21: =SUM(H21:I21) -> 0 | M21: =SUM(K21:L21) -> 0 | P21: =SUM(N21:O21) -> 0 | S21: =SUM(Q21:R21) -> 0
A22: III-ARARAQUARA | B22: CENTRO OESTE | C22: 2747685 SANTA CASA DE MISERICORDIA NOVA EUROPA | D22: NOVA EUROPA | E22: MUNICIPAL | F22: 62 | J22: =SUM(H22:I22) -> 0 | M22: =SUM(K22:L22) -> 0 | P22: =SUM(N22:O22) -> 0 | S22: =SUM(Q22:R22) -> 0
A23: III-ARARAQUARA | B23: CORAÇÃO | C23: 2080931 SANTA CASA DE SAO CARLOS | D23: SÃO CARLOS | E23: MUNICIPAL | F23: 1753 | G23: S | H23: 4 | I23: 5 | J23: =SUM(H23:I23) -> 9 | K23: 5 | L23: 1 | M23: =SUM(K23:L23) -> 6 | O23: 6 | P23: =SUM(N23:O23) -> 6 | R23: 3 | S23: =SUM(Q23:R23) -> 3 | W23: N | X23: N | AA23: E
A24: III-ARARAQUARA | B24: CORAÇÃO | C24: 2081717 SANTA CASA DESCALVADO | D24: DESCALVADO | E24: MUNICIPAL | F24: 175 | J24: =SUM(H24:I24) -> 0 | M24: =SUM(K24:L24) -> 0 | P24: =SUM(N24:O24) -> 0 | S24: =SUM(Q24:R24) -> 0
A25: III-ARARAQUARA | B25: CORAÇÃO | C25: 2082322 HOSPITAL DONA BALBINA | D25: PORTO FERREIRA | E25: MUNICIPAL | F25: 313 | G25: S | J25: =SUM(H25:I25) -> 0 | M25: =SUM(K25:L25) -> 0 | P25: =SUM(N25:O25) -> 0 | S25: =SUM(Q25:R25) -> 0
A26: III-ARARAQUARA | B26: CORAÇÃO | C26: 2092395 HOSPITAL MUNICIPAL IBATE | D26: IBATÉ | E26: MUNICIPAL | F26: 286 | J26: =SUM(H26:I26) -> 0 | M26: =SUM(K26:L26) -> 0 | P26: =SUM(N26:O26) -> 0 | S26: =SUM(Q26:R26) -> 0
A27: III-ARARAQUARA | B27: CORAÇÃO | C27: 2747693 SANTA CASA DE MISERICORDIA RIBEIRAO BONITO | D27: RIBEIRÃO BONITO | E27: MUNICIPAL | F27: 75 | J27: =SUM(H27:I27) -> 0 | M27: =SUM(K27:L27) -> 0 | P27: =SUM(N27:O27) -> 0 | S27: =SUM(Q27:R27) -> 0
A28: III-ARARAQUARA | B28: NORTE | C28: 2078295 SANTA CASA DE TAQUARITINGA | D28: TAQUARITINGA | E28: MUNICIPAL | F28: 371 | G28: S | J28: =SUM(H28:I28) -> 0 | K28: 4 | M28: =SUM(K28:L28) -> 4 | N28: 4 | P28: =SUM(N28:O28) -> 4 | Q28: 1 | S28: =SUM(Q28:R28) -> 1
A29: III-ARARAQUARA | B29: NORTE | C29: 2090961 HOSPITAL CARLOS FERNANDO MALZONI MATAO | D29: MATÃO | E29: ESTADUAL | F29: 604 | G29: S | H29: 4 | I29: 1 | J29: =SUM(H29:I29) -> 5 | K29: 5 | M29: =SUM(K29:L29) -> 5 | N29: 5 | P29: =SUM(N29:O29) -> 5 | Q29: 3 | S29: =SUM(Q29:R29) -> 3 | X29: E
