Workbook

Sheet listas de opções
A1: RRAS | C1: DRS | E1: Região de Saúde | G1: STATUS | I1: HABILITAÇÃO MAB
A2: RRAS 01 | C2: Aracatuba | E2: Adamantina | G2: Existente | I2: MAB I
A3: RRAS 02 | C3: Araraquara | E3: Alta Anhanguera | G3: Novo | I3: MAB II
A4: RRAS 03 | C4: Baixada Santista | E4: Alta Mogiana | G4: Não existe | I4: MAB III
A5: RRAS 04 | C5: Barretos | E5: Alta Paulista | I5: SEM HABILITAÇÃO
A6: RRAS 05 | C6: Bauru | E6: Alta Sorocabana
A7: RRAS 06 | C7: Campinas | E7: Alto Capivari
A8: RRAS 07 | C8: Franca | E8: Alto do Tiete
A9: RRAS 08 | C9: Grande Sao Paulo | E9: Alto Vale do Paraíba
A10: RRAS 09 | C10: Marilia | E10: Aquifero Guarani
A11: RRAS 10 | C11: Piracicaba | E11: Araras
A12: RRAS 11 | C12: Presidente Prudente | E12: Assis
A13: RRAS 12 | C13: Registro | E13: Baixa Mogiana
A14: RRAS 13 | C14: Ribeirao Preto | E14: Baixada Santista
A15: RRAS 14 | C15: Sao Joao da Boa Vista | E15: Bauru
A16: RRAS 15 | C16: Sao Jose do Rio Preto | E16: Braganca
A17: RRAS 16 | C17: Sorocaba | E17: Catanduva
A18: RRAS 17 | C18: Taubaté | E18: Central do DRS II
E19: Central do DRS III
E20: Centro Oeste do DRS III
E21: Circ. da Fé - V. Histórico
E22: Circuito das Aguas
E23: Consorcio do DRS II
E24: Coracao do DRS III
E25: Extremo Oeste Paulista
E26: Fernandopolis
E27: Franco da Rocha
E28: Grande ABC
E29: Horizonte Verde
E30: Itapetininga
... E64: Votuporanga

Sheet Tabela 1 APS - Descr.
A1: RRAS: | B1: RRAS 17
C3: Planilha atualizada em: 13/11/2024
A6: A tabela 1 se refere a capacidade do municipio/territorio para atendimento a gestante de baixo risco e apontamento da pactuação do serviço que realiza o Pré-Natal de Alto Risco (AGAR), a entrada deve ser coerente com as referencias e Região de Saúde.
A8: NASCIDOS VIVOS: PARA ATUAL PLANO: CONSIDERAR ANO 2023
A9: ESTIMATIVA DE GESTANTES SUSDEPENDENTE (CÁLCULO) = NV + 10% - % Cobertura Saude Suplementar (por municipio)-fonte: https://tabnet.saude.sp.gov.br/tabcgi.exe?tabnet/ind47a_matriz.def
A10: COBERTURA ANS - REFERENCIA 2023 (Fonte/Tabnet:https://tabnet.saude.sp.gov.br/tabcgi.exe?tabnet/ind47a_matriz.def)
A11: Nº de UBS - Referência 2024. (Fonte: https://cnes2.datasus.gov.br/Mod_Ind_Unidade.asp?VEstado=35&VMun=351380&VComp=00&VUni=02)
A12: COBERTURA DA ESF/MUNICÍPIO - Referência 2020 (Fonte: https://tabnet.saude.sp.gov.br/tabcgi.exe?tabnet/ind33a_matriz.def)
A13: COBERTURA DA AB/MUNICÍPIO - Referência 2020 (Fonte: https://tabnet.saude.sp.gov.br/tabcgi.exe?tabnet/ind33a_matriz.def)
A15: GLOSSÁRIO
A16: AAE -Atenção Ambulatorial Especializada
A17: APS - ATENÇÃO PRIMÁRIA À SAÚDE
A18: ESF - ESTRATÉGIA SAÚDE DA FAMILIA
A19: UBS - UNIDADE BÁSICA DE SAÚDE
... A21: Tabela: 1 Cobertura de Acesso e capacidade instalada na Atenção Primária à Saúde (APS) para a gestação de baixo risco.
A23: DRS | B23: RS | C23: MUNICIPIO | D23: NASCIDOS VIVOS MUNICIPIO (2023) | E23: COBERTURA ANS % | F23: Nº DE UBS | G23: COBERTURA DE ESF/MUNICIPIO % | H23: COBERTURA DA APS/MUNICIPIO | I23: TOTAL DE GESTANTES SUSDEPENDENTES ESTIMADAS/ANO | J23: TOTAL DE NASCIDOS VIVOS SUSDEPENDENTES ESTIMADOS/ANO | K23: CNES/ESTABELECIMENTO PARA REFERENCIA PARA AAE (AGAR) | L23: MUNICIPIO | M23: CNES/ESTABELECIMENTO DA REFERENCIA PARA PARTO (BX RISCO) | N23: MUNICIPIO
A24: Taubate | B24: Alto Vale do Paraiba | C24: Caçapava | D24: 1041 | E24: 35.9 | F24: 21 | G24: 54.9 | H24: 61.26 | I24: =(D24*(1-E24/100)*1.1) -> 734.0091 | J24: =D24*(1-E24/100) -> 667.281 | K24: 6294049/ Ambulatório Médico de Especialidades | L24: São José dos Campos | M24: 2024756/ Hospital e Maternidade Nossa Senhora Da Ajuda - FUSAM | N24: Caçapava
C25: Igaratá | D25: 124 | E25: 12.55 | F25: 3 | G25: 0 | H25: 0 | I25: =(D25*(1-E25/100)*1.1) -> 119.2818 | J25: =D25*(1-E25/100) -> 108.438 | K25: 2085194/ Hospital São Francisco de Assis - CEAMI | L25: Jacareí | M25: 2085194/ Hospital São Francisco de Assis | N25: Jacareí
C26: Jacareí | D26: 2642 | E26: 42.82 | F26: 53 | G26: 64.97 | H26: 88.49 | I26: =(D26*(1-E26/100)*1.1) -> 1661.7652 | J26: =D26*(1-E26/100) -> 1510.6956 | K26: 2085194/ Hospital São Francisco de Assis - CEAMI | L26: Jacareí | M26: 2085194/ Hospital São Francisco de Assis | N26: Jacareí
C27: Jambeiro | D27: 73 | E27: 21.9 | F27: 1 | G27: 52.26 | H27: 52.26 | I27: =(D27*(1-E27/100)*1.1) -> 62.7143 | J27: =D27*(1-E27/100) -> 57.013 | K27: 6294049/ Ambulatório Médico de Especialidades | L27: São José dos Campos | M27: 2024756/ Hospital e Maternidade Nossa Senhora Da Ajuda - FUSAM | N27: Caçapava
C28: Monteiro Lobato | D28: 54 | E28: 13.3 | F28: 1 | G28: 74.15 | H28: 74.15 | I28: =(D28*(1-E28/100)*1.1) -> 51.4998 | J28: =D28*(1-E28/100) -> 46.818 | K28: 6294049/ Ambulatório Médico de Especialidades | L28: São José dos Campos | M28: 9628/ Hospital Municipal Dr José de Carvalho Florence | N28: São José dos Campos
C29: Paraibuna | D29: 196 | E29: 18.97 | F29: 1 | G29: 56.8 | H29: 73.26 | I29: =(D29*(1-E29/100)*1.1) -> 174.70068 | J29: =D29*(1-E29/100) -> 158.8188 | K29: 6294049/ Ambulatório Médico de Especialidades | L29: São José dos Campos | M29: 9628/ Hospital Municipal Dr José de Carvalho Florence | N29: São José dos Campos
C30: Santa Branca | D30: 153 | E30: 20.08 | F30: 2 | G30: 69.99 | H30: 100 | I30: =(D30*(1-E30/100)*1.1) -> 134.50536 | J30: =D30*(1-E30/100) -> 122.2776 | K30: 2085194/ Hospital São Francisco de Assis - CEAMI | L30: Jacareí | M30: 2085194/ Hospital São Francisco de Assis | N30: Jacareí
C31: São José dos Campos | D31: 8090 | E31: 45.38 | F31: 40 | G31: 20.07 | H31: 55.64 | I31: =(D31*(1-E31/100)*1.1) -> 4860.6338 | J31: =D31*(1-E31/100) -> 4418.758 | K31: 9628/ Hospital Municipal Dr José de Carvalho Florence - Ambulatório da Mulher Dra. Therezinha Veneziani Silva | L31: São José dos Campos | M31: 9628/ Hospital Municipal Dr José de Carvalho Florence | N31: São José dos Campos
A32: Taubate | B32: Circ. da Fe-V. Historico | C32: Aparecida | D32: 304 | E32: 17.64 | F32: 10 | G32: 66.79 | H32: 100 | I32: =(D32*(1-E32/100)*1.1) -> 275.41184 | J32: =D32*(1-E32/100) -> 250.3744 | K32: 2087111/ Irmandade Santa Casa de Lorena | L32: Lorena | M32: 2087111/ Irmandade Santa Casa de Lorena | N32: Lorena
C33: Arapeí | D33: 27 | E33: 2.73 | F33: 1 | G33: 100 | H33: 100 | I33: =(D33*(1-E33/100)*1.1) -> 28.88919 | J33: =D33*(1-E33/100) -> 26.2629 | K33: 2087111/ Irmandade Santa Casa de Lorena | L33: Lorena | M33: 2024691/ Santa Casa de Cruzeiro | N33: Cruzeiro
C34: Areias | D34: 53 | E34: 5.06 | F34: 1 | G34: 88.78 | H34: 100 | I34: =(D34*(1-E34/100)*1.1) -> 55.35002 | J34: =D34*(1-E34/100) -> 50.3182 | K34: 2087111/ Irmandade Santa Casa de Lorena | L34: Lorena | M34: 2024691/ Santa Casa de Cruzeiro | N34: Cruzeiro
C35: Bananal | D35: 89 | E35: 10.29 | F35: 5 | G35: 100 | H35: 100 | I35: =(D35*(1-E35/100)*1.1) -> 87.82609 | J35: =D35*(1-E35/100) -> 79.8419 | K35: 2087111/ Irmandade Santa Casa de Lorena | L35: Lorena | M35: 2024691/ Santa Casa de Cruzeiro | N35: Cruzeiro
C36: Cachoeira Paulista | D36: 346 | E36: 24.01 | F36: 9 | G36: 62.11 | H36: 71.11 | I36: =(D36*(1-E36/100)*1.1) -> 289.21794 | J36: =D36*(1-E36/100) -> 262.9254 | K36: 2087111/ Irmandade Santa Casa de Lorena | L36: Lorena | M36: 2087111/ Irmandade Santa Casa de Lorena | N36: Lorena
C37: Canas | D37: 79 | E37: 10.05 | F37: 1 | G37: 67.15 | H37: 79.36 | I37: =(D37*(1-E37/100)*1.1) -> 78.16655 | J37: =D37*(1-E37/100) -> 71.0605 | K37: 2087111/ Irmandade Santa Casa de Lorena | L37: Lorena | M37: 2087111/ Irmandade Santa Casa de Lorena | N37: Lorena
C38: Cruzeiro | D38: 760 | E38: 30.4 | F38: 13 | G38: 37.76 | H38: 59.64 | I38: =(D38*(1-E38/100)*1.1) -> 581.856 | J38: =D38*(1-E38/100) -> 528.96 | K38: 2749319/ Hospital Municipal Universitário de Taubaté | L38: Taubaté | M38: 2024691/ Santa Casa de Cruzeiro | N38: Cruzeiro
C39: Cunha | D39: 229 | E39: 5.16 | F39: 6 | G39: 64.05 | H39: 64 | I39: =(D39*(1-E39/100)*1.1) -> 238.90196 | J39: =D39*(1-E39/100) -> 217.1836 | K39: 2031027/ Assistência Médica Especializada | L39: Guaratinguetá | M39: 2079518/ Santa Casa de Misericordia e Maternidade Nossa Senhora da Conceição | N39: Cunha
C40: Guaratinguetá | D40: 1324 | E40: 24.87 | F40: 16 | G40: 22.66 | H40: 43.84 | I40: =(D40*(1-E40/100)*1.1) -> 1094.1933 | J40: =D40*(1-E40/100) -> 994.7212 | K40: 2031027/ Assistência Médica Especializada | L40: Guaratinguetá | M40: 2081512/ Santa Casa de Misericórdia de Guaratinguetá | N40: Guaratinguetá
C41: Lavrinhas | D41: 89 | E41: 25.33 | F41: 4 | G41: 100 | H41: 100 | I41: =(D41*(1-E41/100)*1.1) -> 73.10193 | J41: =D41*(1-E41/100) -> 66.4563 | K41: 2749319/ Hospital Municipal Universitário de Taubaté | L41: Taubaté | M41: 2024691/ Santa Casa de Cruzeiro | N41: Cruzeiro
C42: Lorena | D42: 1011 | E42: 28.71 | F42: 17 | G42: 35 | H42: 56.14 | I42: =(D42*(1-E42/100)*1.1) -> 792.81609 | J42: =D42*(1-E42/100) -> 720.7419 | K42: 2087111/ Irmandade Santa Casa de Lorena | L42: Lorena | M42: 2087111/ Irmandade Santa Casa de Lorena | N42: Lorena
C43: Piquete | D43: 106 | E43: 15.61 | F43: 4 | G43: 75.79 | H43: 75.79 | I43: =(D43*(1-E43/100)*1.1) -> 98.39874 | J43: =D43*(1-E43/100) -> 89.4534 | K43: 2087111/ Irmandade Santa Casa de Lorena | L43: Lorena | M43: 2087111/ Irmandade Santa Casa de Lorena | N43: Lorena
C44: Potim | D44: 219 | E44: 7.23 | F44: 6 | G44: 70 | H44: 100 | I44: =(D44*(1-E44/100)*1.1) -> 223.48293 | J44: =D44*(1-E44/100) -> 203.1663 | K44: 2087111/ Irmandade Santa Casa de Lorena | L44: Lorena | M44: 2087111/ Irmandade Santa Casa de Lorena | N44: Lorena
... C48: Silveiras | D48: 79 | E48: 6.52 | F48: 3 | G48: 100 | H48: 100 | I48: =(D48*(1-E48/100)*1.1) -> 81.23412 | J48: =D48*(1-E48/100) -> 73.8492 | K48: 2087111/ Irmandade Santa Casa de Lorena | L48: Lorena | M48: 2024691/ Santa Casa de Cruzeiro | N48: Cruzeiro
A49: Taubate | B49: Litoral Norte | C49: Caraguatatuba | D49: 1627 | E49: 18.25 | F49: 13 | G49: 76.65 | H49: 79.36 | I49: =(D49*(1-E49/100)*1.1) -> 1463.0798 | J49: =D49*(1-E49/100) -> 1330.0725 | K49: 9768289/ Centro de Referência de Saúde da Mulher Dra Ana M Veronesi | L49: Caraguatatuba | M49: 2082926/ Casa de Saúde Stella Maris | N49: Caraguatatuba
C50: IIhabela | D50: 490 | E50: 9.62 | F50: 8 | G50: 0 | H50: 79.35 | I50: =(D50*(1-E50/100)*1.1) -> 487.1482 | J50: =D50*(1-E50/100) -> 442.862 | K50: 9632786/ Centro de Referência Especializada Julia Tenório e mais 8 unidades de saúde | L50: Ilhabela | M50: 2747871/ Hospital Municipal Gov Mario Covas Jr | N50: Ilhabela
...

Sheet Tabela 1 APS - Dados
A1: DRS | B1: REGIÃO DE SAÚDE | C1: MUNICÍPIO DA RRAS | D1: NASCIDOS VIVOS MUNICÍPIO | E1: COBERTURA ANS (%) | F1: Nº DE UBS | G1: COBERTURA DA ESF (%) | H1: COBERTURA DA AB (%) | I1: GESTANTES SUSDEPENDENTES ESTIMADAS/ANO | J1: NASCIDOS VIVOS SUSDEPENDENTES ESTIMADOS/ANO
A2: Taubaté | B2: Alto Vale do Paraíba | C2: Caçapava | D2: 1041 | E2: 35.9 | F2: 21 | G2: 54.9 | H2: 61.26 | I2: =(D2*(1-E2/100)*1.1) -> 734.0091 | J2: =D2*(1-E2/100) -> 667.281
A3: Taubaté | B3: Alto Vale do Paraíba | C3: Igaratá | D3: 124 | E3: 12.55 | F3: 3 | G3: 0 | H3: 0 | I3: =(D3*(1-E3/100)*1.1) -> 119.2818 | J3: =D3*(1-E3/100) -> 108.438
A4: Taubaté | B4: Alto Vale do Paraíba | C4: Jacareí | D4: 2642 | E4: 42.82 | F4: 53 | G4: 64.97 | H4: 88.49 | I4: =(D4*(1-E4/100)*1.1) -> 1661.7652 | J4: =D4*(1-E4/100) -> 1510.6956
A5: Taubaté | B5: Alto Vale do Paraíba | C5: Jambeiro | D5: 73 | E5: 21.9 | F5: 1 | G5: 52.26 | H5: 52.26 | I5: =(D5*(1-E5/100)*1.1) -> 62.7143 | J5: =D5*(1-E5/100) -> 57.013
A6: Taubaté | B6: Alto Vale do Paraíba | C6: Monteiro Lobato | D6: 54 | E6: 13.3 | F6: 1 | G6: 74.15 | H6: 74.15 | I6: =(D6*(1-E6/100)*1.1) -> 51.4998 | J6: =D6*(1-E6/100) -> 46.818
A7: Taubaté | B7: Alto Vale do Paraíba | C7: Paraibuna | D7: 196 | E7: 18.97 | F7: 1 | G7: 56.8 | H7: 73.26 | I7: =(D7*(1-E7/100)*1.1) -> 174.70068 | J7: =D7*(1-E7/100) -> 158.8188
A8: Taubaté | B8: Alto Vale do Paraíba | C8: Santa Branca | D8: 153 | E8: 20.08 | F8: 2 | G8: 69.99 | H8: 100 | I8: =(D8*(1-E8/100)*1.1) -> 134.50536 | J8: =D8*(1-E8/100) -> 122.2776
A9: Taubaté | B9: Alto Vale do Paraíba | C9: São José dos Campos | D9: 8090 | E9: 45.38 | F9: 40 | G9: 20.07 | H9: 55.64 | I9: =(D9*(1-E9/100)*1.1) -> 4860.6338 | J9: =D9*(1-E9/100) -> 4418.758
A10: Taubaté | B10: Circ. da Fé - V. Histórico | C10: Aparecida | D10: 304 | E10: 17.64 | F10: 10 | G10: 66.79 | H10: 100 | I10: =(D10*(1-E10/100)*1.1) -> 275.41184 | J10: =D10*(1-E10/100) -> 250.3744
A11: Taubaté | B11: Circ. da Fé - V. Histórico | C11: Arapeí | D11: 27 | E11: 2.73 | F11: 1 | G11: 100 | H11: 100 | I11: =(D11*(1-E11/100)*1.1) -> 28.88919 | J11: =D11*(1-E11/100) -> 26.2629
A12: Taubaté | B12: Circ. da Fé - V. Histórico | C12: Areias | D12: 53 | E12: 5.06 | F12: 1 | G12: 88.78 | H12: 100 | I12: =(D12*(1-E12/100)*1.1) -> 55.35002 | J12: =D12*(1-E12/100) -> 50.3182
A13: Taubaté | B13: Circ. da Fé - V. Histórico | C13: Bananal | D13: 89 | E13: 10.29 | F13: 5 | G13: 100 | H13: 100 | I13: =(D13*(1-E13/100)*1.1) -> 87.82609 | J13: =D13*(1-E13/100) -> 79.8419
... A30: Taubaté | B30: Litoral Norte | C30: Ubatuba | D30: 1280 | E30: 11.76 | F30: 21 | G30: 100 | H30: 100 | I30: =(D30*(1-E30/100)*1.1) -> 1242.4192 | J30: =D30*(1-E30/100) -> 1129.472
A31: Taubaté | B31: V. Paraíba - R. Serrana | C31: Campos do Jordão | D31: 657 | E31: 13.69 | F31: 20 | G31: 66.23 | H31: 81,09 | I31: =(D31*(1-E31/100)*1.1) -> 623.76237 | J31: =D31*(1-E31/100) -> 567.0567
A32: Taubaté | B32: V. Paraíba - R. Serrana | C32: Lagoinha | D32: 38 | E32: 5.44 | F32: 2 | G32: 100 | H32: 100 | I32: =(D32*(1-E32/100)*1.1) -> 39.52608 | J32: =D32*(1-E32/100) -> 35.9328
A33: Taubaté | B33: V. Paraíba - R. Serrana | C33: Natividade da Serra | D33: 62 | E33: 5.59 | F33: 3 | G33: 51.79 | H33: 100 | I33: =(D33*(1-E33/100)*1.1) -> 64.38762 | J33: =D33*(1-E33/100) -> 58.5342
A34: Taubaté | B34: V. Paraíba - R. Serrana | C34: Pindamonhangaba | D34: 2172 | E34: 28.22 | F34: 29 | G34: 43.04 | H34: 67,99 | I34: =(D34*(1-E34/100)*1.1) -> 1714.9678 | J34: =D34*(1-E34/100) -> 1559.0616
A35: Taubaté | B35: V. Paraíba - R. Serrana | C35: Redenção da Serra | D35: 54 | E35: 6.68 | F35: 2 | G35: 89.59 | H35: 100 | I35: =(D35*(1-E35/100)*1.1) -> 55.43208 | J35: =D35*(1-E35/100) -> 50.3928
A36: Taubaté | B36: V. Paraíba - R. Serrana | C36: Santo Antônio do Pinhal | D36: 94 | E36: 8.81 | F36: 3 | G36: 100 | H36: 100 | I36: =(D36*(1-E36/100)*1.1) -> 94.29046 | J36: =D36*(1-E36/100) -> 85.7186
A37: Taubaté | B37: V. Paraíba - R. Serrana | C37: São Bento do Sapucaí | D37: 105 | E37: 7.14 | F37: 4 | G37: 63.43 | H37: 100 | I37: =(D37*(1-E37/100)*1.1) -> 107.2533 | J37: =D37*(1-E37/100) -> 97.503
A38: Taubaté | B38: V. Paraíba - R. Serrana | C38: São Luís do Paraitinga | D38: 101 | E38: 11.66 | F38: 3 | G38: 96.85 | H38: 96,85 | I38: =(D38*(1-E38/100)*1.1) -> 98.14574 | J38: =D38*(1-E38/100) -> 89.2234
A39: Taubaté | B39: V. Paraíba - R. Serrana | C39: Taubaté | D39: 3322 | E39: 33.49 | F39: 44 | G39: 32.87 | H39: 58,44 | I39: =(D39*(1-E39/100)*1.1) -> 2430.4084 | J39: =D39*(1-E39/100) -> 2209.4622
A40: Taubaté | B40: V. Paraíba - R. Serrana | C40: Tremembé | D40: 430 | E40: 19.38 | F40: 7 | G40: 29.25 | H40: 53,15 | I40: =(D40*(1-E40/100)*1.1) -> 381.3326 | J40: =D40*(1-E40/100) -> 346.666

Sheet Tabela 1 APS - Referência AAE
A1: DRS | B1: REGIÃO DE SAÚDE | C1: MUNICÍPIO DA RRAS | D1: CNES | E1: NOME DO ESTABELECIMENTO | F1: MUNICÍPIO DO ESTABELECIMENTO
A2: Taubaté | B2: Alto Vale do Paraíba | C2: Caçapava | D2: 6294049 | E2: Ambulatório Médico de Especialidades | F2: São José dos Campos
A3: Taubaté | B3: Alto Vale do Paraíba | C3: Igaratá | D3: 2085194 | E3: Hospital São Francisco de Assis - CEAMI | F3: Jacareí
A4: Taubaté | B4: Alto Vale do Paraíba | C4: Jacareí | D4: 2085194 | E4: Hospital São Francisco de Assis - CEAMI | F4: Jacareí
A5: Taubaté | B5: Alto Vale do Paraíba | C5: Jambeiro | D5: 6294049 | E5: Ambulatório Médico de Especialidades | F5: São José dos Campos
A6: Taubaté | B6: Alto Vale do Paraíba | C6: Monteiro Lobato | D6: 6294049 | E6: Ambulatório Médico de Especialidades | F6: São José dos Campos
A7: Taubaté | B7: Alto Vale do Paraíba | C7: Paraibuna | D7: 6294049 | E7: Ambulatório Médico de Especialidades | F7: São José dos Campos
A8: Taubaté | B8: Alto Vale do Paraíba | C8: Santa Branca | D8: 2085194 | E8: Hospital São Francisco de Assis - CEAMI | F8: Jacareí
A9: Taubaté | B9: Alto Vale do Paraíba | C9: São José dos Campos | D9: 9628 | E9: Hospital Municipal Dr José de Carvalho Florence | F9: São José dos Campos
A10: Taubaté | B10: Alto Vale do Paraíba | C10: São José dos Campos | D10: 3363201 | E10: Ambulatório da Mulher Dra. Therezinha Veneziani Silva | F10: São José dos Campos
A11: Taubaté | B11: Circ. da Fé - V. Histórico | C11: Aparecida | D11: 2087111 | E11: Irmandade Santa Casa de Lorena | F11: Lorena
A12: Taubaté | B12: Circ. da Fé - V. Histórico | C12: Arapeí | D12: 2087111 | E12: Irmandade Santa Casa de Lorena | F12: Lorena
A13: Taubaté | B13: Circ. da Fé - V. Histórico | C13: Areias | D13: 2087111 | E13: Irmandade Santa Casa de Lorena | F13: Lorena
... A43: Taubaté | B43: V. Paraíba - R. Serrana | C43: Tremembé | D43: 2749319 | E43: Hospital Municipal Universitário de Taubaté | F43: Taubaté

Sheet Tabela 1 APS - Referência Bx. R
A1: DRS | B1: REGIÃO DE SAÚDE | C1: MUNICÍPIO DA RRAS | D1: CNES | E1: NOME DO ESTABELECIMENTO | F1: MUNICÍPIO DO ESTABELECIMENTO
A2: Taubaté | B2: Alto Vale do Paraíba | C2: Caçapava | D2: 2024756 | E2: Hospital e Maternidade Nossa Senhora Da Ajuda - FUSAM | F2: Caçapava
A3: Taubaté | B3: Alto Vale do Paraíba | C3: Igaratá | D3: 2085194 | E3: Hospital São Francisco de Assis | F3: Jacareí
A4: Taubaté | B4: Alto Vale do Paraíba | C4: Jacareí | D4: 2085194 | E4: Hospital São Francisco de Assis | F4: Jacareí
A5: Taubaté | B5: Alto Vale do Paraíba | C5: Jambeiro | D5: 2024756 | E5: Hospital e Maternidade Nossa Senhora Da Ajuda - FUSAM | F5: Caçapava
A6: Taubaté | B6: Alto Vale do Paraíba | C6: Monteiro Lobato | D6: 9628 | E6: Hospital Municipal Dr. José de Carvalho Florence | F6: São José dos Campos
A7: Taubaté | B7: Alto Vale do Paraíba | C7: Paraibuna | D7: 9628 | E7: Hospital Municipal Dr. José de Carvalho Florence | F7: São José dos Campos
A8: Taubaté | B8: Alto Vale do Paraíba | C8: Santa Branca | D8: 2085194 | E8: Hospital São Francisco de Assis | F8: Jacareí
A9: Taubaté | B9: Alto Vale do Paraíba | C9: São José dos Campos | D9: 9628 | E9: Hospital Municipal Dr. José de Carvalho Florence | F9: São José dos Campos
A10: Taubaté | B10: Circ. da Fé - V. Histórico | C10: Aparecida | D10: 2087111 | E10: Irmandade Santa Casa de Lorena | F10: Lorena
A11: Taubaté | B11: Circ. da Fé - V. Histórico | C11: Arapeí | D11: 2024691 | E11: Santa Casa de Cruzeiro | F11: Cruzeiro
A12: Taubaté | B12: Circ. da Fé - V. Histórico | C12: Areias | D12: 2024691 | E12: Santa Casa de Cruzeiro | F12: Cruzeiro
A13: Taubaté | B13: Circ. da Fé - V. Histórico | C13: Bananal | D13: 2024691 | E13: Santa Casa de Cruzeiro | F13: Cruzeiro
... A49: Taubaté | B49: V. Paraíba - R. Serrana | C49: Tremembé | D49: 2755092 | E49: Santa Casa de Pindamonhangaba | F49: Pindamonhangaba

Sheet tabela 2 AGAR
A1: RRAS: | B1: ='Tabela 1 APS - Descr.'!B1 -> RRAS 17
A4: CAPACIDADE OPERACIONAL PRÉ-NATAL DE ALTO RISCO
A6: TOTAL DE GESTANTES SUSDEPENDENTES ESTIMADAS/ANO = VIDE TABELA 1
A7: TOTAL DE GESTANTES DE ALTO RISCO SUSDEPENDENTES ESTIMADAS/ANO = 15% DAS GESTANTES SUSDEPENDENTES ESTIMADAS
A8: PREVISÃO DE NÚMERO DE CONSULTA DE PRÉ-NATAL ALTO RISCO/ANO = Nº DE GESTANTES DE ALTO RISCO ESTIMADAS X 12 CONSULTAS
A9: OBSERVAR QUE O RESULTADO OBTIDO É O TOTAL DE CONSULTAS NECESSÁRIAS PARA A RRAS/REGIÃO/MUNICIPIO/ANO . O ESTABELECIMENTO DEVERÁ PREVER SE HÁ NECESSIDADE DE CONTRATAÇÃO DE RH E SERVIÇOS PARA O ATENDIMENTO DE 100% DAS CONSULTAS ESTIMADAS
A10: PARA ESTIMATIVA DE CAPACIDADE DE CONSULTAS DO AAE(AGAR)/ANO CONSIDERAR DE 3 A 4 CONSULTAS /HORA/PROFISSIONAL, ESSA INFORMAÇÃO DEVE SER OBTIDA JUNTO AO SERVIÇO DE ALTO RISCO.
A11: NÃO ESQUECER DE COLOCAR O NOME DO ESTABELECIMENTO E CNES
A14: tabela: 2 Cobertura de Acesso e capacidade instalada na Atenção Ambulatorial Especializada (AAE) - PRÉ-NATAL DE ALTO RISCO (AGAR)
A16: DRS | B16: RS | C16: MUNICIPIO | D16: TOTAL DE GESTANTES SUSDEPENDENTES ESTIMADAS/ANO (trazer da tabela1 APS) | E16: TOTAL DE GESTANTES DE ALTO RISCO SUSDEPENDENTES ESTIMADAS/ANO | F16: PREVISÃO DE NÚMERO DE CONSULTA DE ALTO RISCO PARA MUNICIPIO/ANO | G16: CNES/ESTABELECIMENTO PARA REFERENCIA PARA AAE (AGAR) | H16: ESTIMATIVA DE CAPACIDADE PARA CONSULTAS DO AAE/ANO | I16: GESTÃO | J16: INDICADO PARA HABILITAÇÃO TIPO I OU TIPO II | K16: CONSULTA REGULADA (S) OU (N) | L16: CNES/ESTABELECIMENTO DA REFERENCIA PARA PARTO DE ALTO RISCO | M16: MUNICIPIO
A17: Taubate | B17: Alto Vale do Paraiba | C17: Caçapava | D17: 781.56507 | E17: ='Tabela 1 APS - Descr.'!I24 -> 734.0091 | F17: =E17*12 -> 8808.1092 | G17: 6294049/ Ambulatório Médico de Especialidades | H17: 2500 | I17: Estadual | K17: SIM | L17: 9628/ Hospital Municipal Dr José de Carvalho Florence | M17: São José dos Campos
A18: Taubate | B18: Alto Vale do Paraiba | C18: Igaratá | D18: 135.20947 | E18: ='Tabela 1 APS - Descr.'!I25 -> 119.2818 | F18: =E18*12 -> 1431.3816 | G18: 2085194/ Hospital São Francisco de Assis - CEAMI | I18: Municipal | K18: SIM | L18: 2085194/ Hospital São Francisco de Assis | M18: Jacareí
A19: Taubate | B19: Alto Vale do Paraiba | C19: Jacareí | D19: 1736.5986 | E19: ='Tabela 1 APS - Descr.'!I26 -> 1661.7652 | F19: =E19*12 -> 19941.182 | G19: 2085194/ Hospital São Francisco de Assis - CEAMI | H19: 468 | I19: Municipal | K19: SIM | L19: 2085194/ Hospital São Francisco de Assis | M19: Jacareí
A20: Taubate | B20: Alto Vale do Paraiba | C20: Jambeiro | D20: 55.59884 | E20: ='Tabela 1 APS - Descr.'!I27 -> 62.7143 | F20: =E20*12 -> 752.5716 | G20: 6294049/ Ambulatório Médico de Especialidades | I20: Estadual | K20: SIM | L20: 9628/ Hospital Municipal Dr José de Carvalho Florence | M20: São José dos Campos
A21: Taubate | B21: Alto Vale do Paraiba | C21: Monteiro | D21: 36.81326 | E21: ='Tabela 1 APS - Descr.'!I28 -> 51.4998 | F21: =E21*12 -> 617.9976 | G21: 6294049/ Ambulatório Médico de Especialidades | I21: Estadual | K21: SIM | L21: 9628/ Hospital Municipal Dr José de Carvalho Florence | M21: São José dos Campos
A22: Taubate | B22: Alto Vale do Paraiba | C22: Paraibuna | D22: 175.46595 | E22: ='Tabela 1 APS - Descr.'!I29 -> 174.70068 | F22: =E22*12 -> 2096.4082 | G22: 6294049/ Ambulatório Médico de Especialidades | I22: Estadual | K22: SIM | L22: 9628/ Hospital Municipal Dr José de Carvalho Florence | M22: São José dos Campos
A23: Taubate | B23: Alto Vale do Paraiba | C23: Santa Branca | D23: 131.38686 | E23: ='Tabela 1 APS - Descr.'!I30 -> 134.50536 | F23: =E23*12 -> 1614.0643 | G23: 2085194/ Hospital São Francisco de Assis - CEAMI | I23: Municipal | K23: SIM | L23: 2085194/ Hospital São Francisco de Assis | M23: Jacareí
A24: Taubate | B24: Alto Vale do Paraiba | C24: São José dos Campos | D24: 5598.516 | E24: ='Tabela 1 APS - Descr.'!I31 -> 4860.6338 | F24: =E24*12 -> 58327.606 | G24: 9628/ Hospital Municipal Dr José de Carvalho Florence - Ambulatório da Mulher Dra. Therezinha Veneziani Silva | H24: 2160 | I24: Municipal | J24: AGAR TIPO II | K24: SIM | L24: 9628/ Hospital Municipal Dr José de Carvalho Florence | M24: São José dos Campos
A25: Taubate | B25: Circ. da Fe-V. Historico | C25: Aparecida | D25: 350.14254 | E25: ='Tabela 1 APS - Descr.'!I32 -> 275.41184 | F25: =E25*12 -> 3304.9421 | G25: 2087111/ Irmandade Santa Casa de Lorena | I25: Municipal | K25: SIM | L25: 2087111/ Irmandade Santa Casa de Lorena | M25: Lorena
A26: Taubate | B26: Circ. da Fe-V. Historico | C26: Arapeí | D26: 13.98111 | E26: ='Tabela 1 APS - Descr.'!I33 -> 28.88919 | F26: =E26*12 -> 346.67028 | G26: 2087111/ Irmandade Santa Casa de Lorena | I26: Municipal | K26: SIM | L26: 2087111/ Irmandade Santa Casa de Lorena | M26: Lorena
A27: Taubate | B27: Circ. da Fe-V. Historico | C27: Areias | D27: 44.85932 | E27: ='Tabela 1 APS - Descr.'!I34 -> 55.35002 | F27: =E27*12 -> 664.20024 | G27: 2087111/ Irmandade Santa Casa de Lorena | I27: Municipal | K27: SIM | L27: 2087111/ Irmandade Santa Casa de Lorena | M27: Lorena
A28: Taubate | B28: Circ. da Fe-V. Historico | C28: Bananal | D28: 69.5002 | E28: ='Tabela 1 APS - Descr.'!I35 -> 87.82609 | F28: =E28*12 -> 1053.9131 | G28: 2087111/ Irmandade Santa Casa de Lorena | I28: Municipal | K28: SIM | L28: 2087111/ Irmandade Santa Casa de Lorena | M28: Lorena
A29: Taubate | B29: Circ. da Fe-V. Historico | C29: Cachoeira Paulista | D29: 325.81912 | E29: ='Tabela 1 APS - Descr.'!I36 -> 289.21794 | F29: =E29*12 -> 3470.6153 | G29: 2087111/ Irmandade Santa Casa de Lorena | I29: Municipal | K29: SIM | L29: 2087111/ Irmandade Santa Casa de Lorena | M29: Lorena
A30: Taubate | B30: Circ. da Fe-V. Historico | C30: Canas | D30: 75.82575 | E30: ='Tabela 1 APS - Descr.'!I37 -> 78.16655 | F30: =E30*12 -> 937.9986 | G30: 2087111/ Irmandade Santa Casa de Lorena | I30: Municipal | K30: SIM | L30: 2087111/ Irmandade Santa Casa de Lorena | M30: Lorena
A31: Taubate | B31: Circ. da Fe-V. Historico | C31: Cruzeiro | D31: 714.56 | E31: ='Tabela 1 APS - Descr.'!I38 -> 581.856 | F31: =E31*12 -> 6982.272 | G31: 2749319/ Hospital Municipal Universitário de Taubaté | I31: Municipal | K31: SIM | L31: 2749319/ Hospital Municipal Universitário de Taubaté | M31: Taubaté
A32: Taubate | B32: Circ. da Fe-V. Historico | C32: Cunha | D32: 251.9616 | E32: ='Tabela 1 APS - Descr.'!I39 -> 238.90196 | F32: =E32*12 -> 2866.8235 | G32: 2031027/ Assistência Médica Especializada | I32: Municipal | K32: SIM | L32: 2081512/ Santa Casa de Misericórdia de Guaratinguetá | M32: Guaratinguetá
A33: Taubate | B33: Circ. da Fe-V. Historico | C33: Guaratinguetá | D33: 1256.0986 | E33: ='Tabela 1 APS - Descr.'!I40 -> 1094.1933 | F33: =E33*12 -> 13130.32 | G33: 2031027/ Assistência Médica Especializada | H33: 2040 | I33: Municipal | K33: SIM | L33: 2081512/ Santa Casa de Misericórdia de Guaratinguetá | M33: Guaratinguetá
A34: Taubate | B34: Circ. da Fe-V. Historico | C34: Lavrinhas | D34: 80.12466 | E34: ='Tabela 1 APS - Descr.'!I41 -> 73.10193 | F34: =E34*12 -> 877.22316 | G34: 2749319/ Hospital Municipal Universitário de Taubaté | I34: Municipal | K34: SIM | L34: 2749319/ Hospital Municipal Universitário de Taubaté | M34: Taubaté
A35: Taubate | B35: Circ. da Fe-V. Historico | C35: Lorena | D35: 884.25106 | E35: ='Tabela 1 APS - Descr.'!I42 -> 792.81609 | F35: =E35*12 -> 9513.7931 | G35: 2087111/ Irmandade Santa Casa de Lorena | H35: 2880 | I35: Municipal | K35: SIM | L35: 2087111/ Irmandade Santa Casa de Lorena
A36: Taubate | B36: Circ. da Fe-V. Historico | C36: Piquete | D36: 118.2225 | E36: ='Tabela 1 APS - Descr.'!I43 -> 98.39874 | F36: =E36*12 -> 1180.7849 | G36: 2087111/ Irmandade Santa Casa de Lorena | I36: Municipal | K36: SIM | L36: 2087111/ Irmandade Santa Casa de Lorena
A37: Taubate | B37: Circ. da Fe-V. Historico | C37: Potim | D37: 252.11725 | E37: ='Tabela 1 APS - Descr.'!I44 -> 223.48293 | F37: =E37*12 -> 2681.7952 | G37: 2087111/ Irmandade Santa Casa de Lorena | I37: Municipal | K37: SIM | L37: 2087111/ Irmandade Santa Casa de Lorena
A38: Taubate | B38: Circ. da Fe-V. Historico | C38: Queluz | D38: 112.1307 | E38: ='Tabela 1 APS - Descr.'!I45 -> 83.97235 | F38: =E38*12 -> 1007.6682 | G38: 2087111/ Irmandade Santa Casa de Lorena | I38: Municipal | K38: SIM | L38: 2087111/ Irmandade Santa Casa de Lorena
A39: Taubate | B39: Circ. da Fe-V. Historico | C39: Roseira | D39: 115.92504 | E39: ='Tabela 1 APS - Descr.'!I46 -> 105.48384 | F39: =E39*12 -> 1265.8061 | G39: 2087111/ Irmandade Santa Casa de Lorena | I39: Municipal | K39: SIM | L39: 2087111/ Irmandade Santa Casa de Lorena
A40: Taubate | B40: Circ. da Fe-V. Historico | C40: São José do Barreiro | D40: 41.8308 | E40: ='Tabela 1 APS - Descr.'!I47 -> 42.99383 | F40: =E40*12 -> 515.92596 | G40: 2087111/ Irmandade Santa Casa de Lorena | I40: Municipal | K40: SIM | L40: 2087111/ Irmandade Santa Casa de Lorena
A41: Taubate | B41: Circ. da Fe-V. Historico | C41: Silveiras | D41: 67.71402 | E41: ='Tabela 1 APS - Descr.'!I48 -> 81.23412 | F41: =E41*12 -> 974.80944 | G41: 2087111/ Irmandade Santa Casa de Lorena | I41: Municipal | K41: SIM | L41: 2087111/ Irmandade Santa Casa de Lorena
A42: Taubate | B42: Litoral Norte | C42: Caraguatatuba | D42: 1475.006 | E42: ='Tabela 1 APS - Descr.'!I49 -> 1463.0798 | F42: =E42*12 -> 17556.957 | G42: 9768289/ Centro de Referência de Saúde da Mulher Dra Ana M Veronesi | H42: 2000 | I42: Municipal | K42: SIM | L42: 2082926/ Casa de Saúde Stella Maris | M42: Caraguatatuba
A43: Taubate | B43: Litoral Norte | C43: Ihabela | D43: 490.33072 | E43: ='Tabela 1 APS - Descr.'!I50 -> 487.1482 | F43: =E43*12 -> 5845.7784 | G43: 9632786/ Centro de Referência Especializada Julia Tenório e mais 8 unidades de saúde | H43: 266 | I43: Municipal | K43: SIM | L43: 2082926/ Casa de Saúde Stella Maris | M43: Caraguatatuba
A44: Taubate | B44: Litoral Norte | C44: São Sebastião | D44: 1113.9363 | E44: ='Tabela 1 APS - Descr.'!I51 -> 1014.2794 | F44: =E44*12 -> 12171.353 | G44: 2086824/ Centro de Saude II Dr Carlos Alberto Camara Leal | H44: 873 | I44: Municipal | K44: SIM | L44: 2082926/ Casa de Saúde Stella Maris | M44: Caraguatatuba
A45: Taubate | B45: Litoral Norte | C45: Ubatuba | D45: 1276.1437 | E45: ='Tabela 1 APS - Descr.'!I52 -> 1242.4192 | F45: =E45*12 -> 14909.03 | G45: 2073285/ Centro de Especialidades Dr Affonso de Faria Fraga Ubatuba | H45: 3374 | I45: Municipal | K45: SIM | L45: 2082926/ Casa de Saúde Stella Maris | M45: Caraguatatuba
A46: Taubate | B46: V. Paraiba - R. Serrana | C46: Campos do Jordão | D46: 650.64384 | E46: ='Tabela 1 APS - Descr.'!I53 -> 623.76237 | F46: =E46*12 -> 7485.1484 | G46: 2749319/ Hospital Municipal Universitário de Taubaté | I46: Municipal | K46: SIM | L46: 2749319/ Hospital Municipal Universitário de Taubaté 2755092/ Santa Casa de Pindamonhangaba | M46: Taubaté
...

Sheet tabela 3 ANEO
A1: RRAS: | B1: ='Tabela 1 APS - Descr.'!B1 -> RRAS 17
A3: CAPACIDADE OPERACIONAL ALTO RISCO - ANEO
A4: UNEO = UNIDADE NEONATAL
A6: (1) ESTIMATIVA DE RECEM NASCIDO DE ALTO RISCO /ANEO: CONSIDERAR AS SAIDAS DA DA UNEO NO ANO ANTERIOR
A7: (2) ESTIMATIVA PARA CONSULTAS MÉDICAS 2.500g = 92% DOS RN DE ALTO RISCO ESTIMADOS X 3 CONSULTAS
A8: (3) ESTIMATIVA PARA CONSULTAS DE ENFERMAGEM 2.500g = 92% DOS RN DE ALTO RISCO ESTIMADOS X 4 CONSULTAS
A9: (4) ESTIMATIVA PARA CONSULTAS MÉDICA PESO < 2.500G = 8% DOS RN DE ALTO RISCO ESTIMADOS X 7 CONSULTAS
A10: (5) ESTIMATIVA PARA CONSULTAS DE ENFERMAGEM PESO < 2.500GDOS 8% RN DE ALTO RISCO ESTIMADOS X 6 CONSULTAS
A16: Tabela 3 : Cobertura de Acesso e capacidade instalada na Atenção Ambulatorial Especializada (AAE) - ANEO
A18: DRS | B18: RS | C18: MUNICIPIO | D18: ESTIMATIVA DE RECEM NASCIDO DE ALTO RISCO /ANEO (1) | E18: CNES/ESTABELECIMENTO PARA REFERENCIA PARA AAE (ANEO) | F18: GESTÃO | G18: MUNICIPIO | H18: ESTIMATIVA PARA CONSULTAS MÉDICA DO ANEO > 2.500G (2) | I18: ESTIMATIVA PARA CONSULTAS ENFERMAGEM DO ANEO > 2.500G (3) | J18: ESTIMATIVA PARA CONSULTAS MÉDICA DO ANEO PESO < 2.500G (4) | K18: ESTIMATIVA PARA CONSULTAS DE ENFERMAGEM DO ANEO < 2.500G (5) | L18: CNES/ESTABELECIMENTO DE REFERENCIA HOSPITALAR PARA O AAE (ANEO) | M18: MUNICIPIO | N18: CONSULTA REGULADA (S) OU (N)
A19: Taubate | B19: Alto Vale do Paraiba | C19: Jacareí | D19: 229 | F19: Municipal | H19: =(D19*92/100)*3 -> 632.04 | I19: =(D19*92/100)*4 -> 842.72 | J19: =(D19*8/100)*7 -> 128.24 | K19: =(D19*8/100)*6 -> 109.92
A20: Taubate | B20: Alto Vale do Paraiba | C20: São José dos Campos | D20: 369 | F20: Municipal | H20: =(D20*92/100)*3 -> 1018.44 | I20: =(D20*92/100)*4 -> 1357.92 | J20: =(D20*8/100)*7 -> 206.64 | K20: =(D20*8/100)*6 -> 177.12
A21: Taubate | B21: Alto Vale do Paraiba | C21: São José dos Campos | D21: 78 | F21: Estadual | H21: =(D21*92/100)*3 -> 215.28 | I21: =(D21*92/100)*4 -> 287.04 | J21: =(D21*8/100)*7 -> 43.68 | K21: =(D21*8/100)*6 -> 37.44
A22: Taubate | B22: Circ. da Fe-V. Historico | C22: Guaratinguetá | D22: 39 | F22: Municipal | H22: =(D22*92/100)*3 -> 107.64 | I22: =(D22*92/100)*4 -> 143.52 | J22: =(D22*8/100)*7 -> 21.84 | K22: =(D22*8/100)*6 -> 18.72
A23: Taubate | B23: Circ. da Fe-V. Historico | C23: Lorena | D23: 114 | F23: Municipal | H23: =(D23*92/100)*3 -> 314.64 | I23: =(D23*92/100)*4 -> 419.52 | J23: =(D23*8/100)*7 -> 63.84 | K23: =(D23*8/100)*6 -> 54.72
A24: Taubate | B24: Litoral Norte | C24: Caraguatatuba | D24: 111 | F24: Municipal | H24: =(D24*92/100)*3 -> 306.36 | I24: =(D24*92/100)*4 -> 408.48 | J24: =(D24*8/100)*7 -> 62.16 | K24: =(D24*8/100)*6 -> 53.28
A25: Taubate | B25: V. Paraiba - R. Serrana | C25: Pindamonhangaba | D25: 136 | F25: Municipal | H25: =(D25*92/100)*3 -> 375.36 | I25: =(D25*92/100)*4 -> 500.48 | J25: =(D25*8/100)*7 -> 76.16 | K25: =(D25*8/100)*6 -> 65.28
A26: Taubate | B26: V. Paraiba - R. Serrana | C26: Taubaté | D26: 179 | F26: Municipal | H26: =(D26*92/100)*3 -> 494.04 | I26: =(D26*92/100)*4 -> 658.72 | J26: =(D26*8/100)*7 -> 100.24 | K26: =(D26*8/100)*6 -> 85.92
H27: =(D27*92/100)*3 -> 0 | I27: =(D27*92/100)*4 -> 0 | J27: =(D27*8/100)*7 -> 0 | K27: =(D27*8/100)*6 -> 0
H28: =(D28*92/100)*3 -> 0 | I28: =(D28*92/100)*4 -> 0 | J28: =(D28*8/100)*7 -> 0 | K28: =(D28*8/100)*6 -> 0
H29: =(D29*92/100)*3 -> 0 | I29: =(D29*92/100)*4 -> 0 | J29: =(D29*8/100)*7 -> 0 | K29: =(D29*8/100)*6 -> 0
H30: =(D30*92/100)*3 -> 0 | I30: =(D30*92/100)*4 -> 0 | J30: =(D30*8/100)*7 -> 0 | K30: =(D30*8/100)*6 -> 0
H31: =(D31*92/100)*3 -> 0 | I31: =(D31*92/100)*4 -> 0 | J31: =(D31*8/100)*7 -> 0 | K31: =(D31*8/100)*6 -> 0
H32: =(D32*92/100)*3 -> 0 | I32: =(D32*92/100)*4 -> 0 | J32: =(D32*8/100)*7 -> 0 | K32: =(D32*8/100)*6 -> 0
H33: =(D33*92/100)*3 -> 0 | I33: =(D33*92/100)*4 -> 0 | J33: =(D33*8/100)*7 -> 0 | K33: =(D33*8/100)*6 -> 0
H34: =(D34*92/100)*3 -> 0 | I34: =(D34*92/100)*4 -> 0 | J34: =(D34*8/100)*7 -> 0 | K34: =(D34*8/100)*6 -> 0
H35: =(D35*92/100)*3 -> 0 | I35: =(D35*92/100)*4 -> 0 | J35: =(D35*8/100)*7 -> 0 | K35: =(D35*8/100)*6 -> 0
H36: =(D36*92/100)*3 -> 0 | I36: =(D36*92/100)*4 -> 0 | J36: =(D36*8/100)*7 -> 0 | K36: =(D36*8/100)*6 -> 0
H37: =(D37*92/100)*3 -> 0 | I37: =(D37*92/100)*4 -> 0 | J37: =(D37*8/100)*7 -> 0 | K37: =(D37*8/100)*6 -> 0
H38: =(D38*92/100)*3 -> 0 | I38: =(D38*92/100)*4 -> 0 | J38: =(D38*8/100)*7 -> 0 | K38: =(D38*8/100)*6 -> 0
... H168: =(D168*92/100)*3 -> 0 | I168: =(D168*92/100)*4 -> 0 | J168: =(D168*8/100)*7 -> 0 | K168: =(D168*8/100)*6 -> 0

Sheet totais TABELA 4

Sheet tabela 4  leitos existentes
A1: RRAS: | B1: ='Tabela 1 APS - Descr.'!B1 -> RRAS 17
A3: TABELA 4 : LEITOS OBSTETRICOS E NEONATAIS EXISTENTES NA REDE
A5: OS ESTABELECIMENTOS CLASSIFICADOS COMO SERVIÇO DE ATENDIMENTO SECUNDÁRIO OU TERCIÁRIO A GESTAÇÃO DE ALTO RISCO DEVEM SER APONTADOS
A6: INSERIR SOMENTE OS LEITOS HABILITADOS, OS EXISTENTES DEVEM FAZER PARTE DA TABELA LEITOS A SEREM HABILITADOS
A7: OS LEITOS GAR FAZEM PARTE DOS LEITOS OBSTETRICOS, APONTAR O NÚMERO DE LEITOS HABILITADOS.
F10: NUMERO DE LEITOS EXISTENTES DA REDE MATERNA E INFANTIL
A12: DRS | B12: REGIÃO DE SAUDE | C12: CNES/ESTABELECIMENTO | D12: MUNICIPIO | E12: GESTÃO | F12: OBSTETRICOS | G12: GAR I | H12: GAR II | I12: SERVIÇO DE ATENDIMENTO SECUNDÁRIO OU TERCIÁRIO A GESTAÇÃO DE ALTO RISCO | J12: UTI ADULTO | K12: UTIN II | L12: UTIN III | M12: UCINCO | N12: UCINCA | O12: CPN I 3 LEITOS | P12: CPN I 5 LEITOS | Q12: CPN II 3 LEITOS | R12: CPN II 5 LEITOS | S12: CGBP 10 LEITOS | T12: CGBP 15 LEITOS | U12: CGBP 20 LEITOS | V12: BLH
A13: Taubate | B13: Alto Vale do Paraiba | C13: 2024756/ Hospital e Maternidade Nossa Senhora Da Ajuda - FUSAM | D13: Caçapava | E13: Municipal | F13: 10
C14: 2085194/ Hospital São Francisco de Assis | D14: Jacareí | E14: Municipal | F14: 26 | H14: 5 | J14: 2 | K14: 8 | M14: 7 | N14: 3 | Q14: 3
C15: 9628/ Hospital Municipal Dr José de Carvalho Florence | D15: São José dos Campos | E15: Municipal | F15: 79 | J15: 4 | K15: 10 | M15: 16 | V15: 1
C16: 2748029/ Santa Casa de Misericórdia de São José dos Campos | D16: São José dos Campos | E16: Estadual | F16: 5 | J16: 2 | K16: 12
A17: Taubate | B17: Circ. da Fe-V. Historico | C17: 2079518/ Santa Casa de Misericordia e Maternidade Nossa Senhora da Conceição | D17: Cunha | E17: Municipal | F17: 4
C18: 2024691/ Santa Casa de Cruzeiro | D18: Cruzeiro | E18: Municipal | F18: 13
C19: 2081512/ Santa Casa de Misericórdia de Guaratinguetá | D19: Guaratinguetá | E19: Municipal | F19: 14 | J19: 1 | K19: 6
C20: 2081644/ Hospital e Maternidade Frei Galvão | D20: Guaratinguetá | E20: Municipal | K20: 6
C21: 2087111/ Irmandade Santa Casa de Lorena | D21: Lorena | E21: Municipal | F21: 16 | J21: 2 | K21: 7
C22: 2087642/ Unidade Mista de Bananal | D22: Bananal | E22: Municipal | F22: 5
C23: 2058340/ Hospital Municipal de Queluz | D23: Queluz | E23: Municipal | F23: 3
A24: Taubate | B24: Litoral Norte | C24: 2082926/ Casa de Saúde Stella Maris | D24: Caraguatatuba | E24: Municipal | F24: 27 | J24: 2 | K24: 10 | V24: 1
C25: 2747871/ Hospital Municipal Gov Mario Covas Jr | D25: Ilhabela | E25: Municipal | F25: 11
C26: 2765934/ Hospital de Clínicas de São Sebastião | D26: São Sebastião | E26: Municipal | F26: 17 | V26: 1
C27: 2702193/ Santa Casa de Misericórdia de Ubatuba | D27: Ubatuba | E27: Municipal | F27: 20
A28: Taubate | B28: V. Paraiba - R. Serrana | C28: 7947984/ Complexo Municipal de Saúde | D28: Campos do Jordão | E28: Municipal | F28: 14
C29: 2755092/ Santa Casa de Pindamonhangaba | D29: Pindamonhangaba | E29: Municipal | F29: 36 | H29: 2 | J29: 1 | K29: 7 | M29: 7
C30: 2078546/ Santa Casa São Bento do Sapucaí | D30: São Bento do Sapucaí | E30: Municipal | F30: 6
C31: 2749319/ Hospital Municipal Universitário de Taubaté | D31: Taubaté | E31: Municipal | F31: 30 | I31: 6 | J31: 3 | K31: 10 | V31: 1
C32: 2079690/ Santa Casa de Misericordia de São Luis do Paraitinga | D32: São Luis do Paraitinga | E32: Municipal | F32: 2
F204: =SUBTOTAL(109,'tabela 4 leitos existentes'!$F$13:$F$202) -> 338 | H204: =SUBTOTAL(109,'tabela 4 leitos existentes'!$H$13:$H$202) -> 7 | J204: =SUBTOTAL(109,'tabela 4 leitos existentes'!$J$13:$J$202) -> 17 | K204: =SUBTOTAL(109,'tabela 4 leitos existentes'!$K$13:$K$202) -> 76 | L204: =SUBTOTAL(109,'tabela 4 leitos existentes'!$L$13:$L$202) -> 0 | M204: =SUBTOTAL(109,'tabela 4 leitos existentes'!$M$13:$M$202) -> 30

Sheet tabela 5 necessidade
A1: RRAS: | B1: ='Tabela 1 APS - Descr.'!B1 -> RRAS 17
E3: NUMERO DE LEITOS NECESSÁRIOS PARA A REDE MATERNA E INFANTIL
A4: DRS | B4: REGIÃO DE SAUDE | C4: NASCIDOS VIVOS SUSDEPENDENTES (trazer da tabela1 APS) | D4: TOTAL DE GESTANTES SUSDEPENDENTES ESTIMADAS/ANO (trazer da tabela1 APS) | E4: OBSTETRICOS | F4: GAR | G4: UTI ADULTO | H4: UTIN | I4: UCINCO | J4: UCINCA | K4: CPN I | M4: CPN II | O4: CGBP | R4: BLH
K5: 3 LEITOS | L5: 5 LEITOS | M5: 3 LEITOS | N5: 5 LEITOS | O5: 10 LEITOS | P5: 15 LEITOS | Q5: 20 LEITOS
A6: Taubate | B6: Alto Vale do Paraiba | C6: 7863 | D6: 8652 | E6: =((D6*2.5)/(365*0.7))*1.21 -> 102.43562 | F6: =E6*15/100 -> 15.365342 | G6: =(E6*6/100) -> 6.146137 | H6: =C6*2/1000 -> 15.726 | I6: =C6*2/1000 -> 15.726 | J6: =C6*1/1000 -> 7.863
A7: Taubate | B7: Circ. da Fe-V. Historico | C7: 4342 | D7: 4775 | E7: =((D7*2.5)/(365*0.7))*1.21 -> 56.533757 | F7: =E7*15/100 -> 8.4800636 | G7: =(E7*6/100) -> 3.3920254 | H7: =C7*2/1000 -> 8.684 | I7: =C7*2/1000 -> 8.684 | J7: =C7*1/1000 -> 4.342
A8: Taubate | B8: Litoral Norte | C8: 3960 | D8: 4355 | E8: =((D8*2.5)/(365*0.7))*1.21 -> 51.561155 | F8: =E8*15/100 -> 7.7341732 | G8: =(E8*6/100) -> 3.0936693 | H8: =C8*2/1000 -> 7.92 | I8: =C8*2/1000 -> 7.92 | J8: =C8*1/1000 -> 3.96
A9: Taubate | B9: V. Paraiba - R. Serrana | C9: 5495 | D9: 6046 | E9: =((D9*2.5)/(365*0.7))*1.21 -> 71.5818 | F9: =E9*15/100 -> 10.73727 | G9: =(E9*6/100) -> 4.294908 | H9: =C9*2/1000 -> 10.99 | I9: =C9*2/1000 -> 10.99 | J9: =C9*1/1000 -> 5.495
E10: =((D10*2.5)/(365*0.7))*1.21 -> 0 | F10: =E10*15/100 -> 0 | G10: =(E10*6/100) -> 0 | H10: =C10*2/1000 -> 0 | I10: =C10*2/1000 -> 0 | J10: =C10*1/1000 -> 0
E11: =((D11*2.5)/(365*0.7))*1.21 -> 0 | F11: =E11*15/100 -> 0 | G11: =(E11*6/100) -> 0 | H11: =C11*2/1000 -> 0 | I11: =C11*2/1000 -> 0 | J11: =C11*1/1000 -> 0
E12: =((D12*2.5)/(365*0.7))*1.21 -> 0 | F12: =E12*15/100 -> 0 | G12: =(E12*6/100) -> 0 | H12: =C12*2/1000 -> 0 | I12: =C12*2/1000 -> 0 | J12: =C12*1/1000 -> 0
E13: =((D13*2.5)/(365*0.7))*1.21 -> 0 | F13: =E13*15/100 -> 0 | G13: =(E13*6/100) -> 0 | H13: =C13*2/1000 -> 0 | I13: =C13*2/1000 -> 0 | J13: =C13*1/1000 -> 0
E14: =((D14*2.5)/(365*0.7))*1.21 -> 0 | F14: =E14*15/100 -> 0 | G14: =(E14*6/100) -> 0 | H14: =C14*2/1000 -> 0 | I14: =C14*2/1000 -> 0 | J14: =C14*1/1000 -> 0
E15: =((D15*2.5)/(365*0.7))*1.21 -> 0 | F15: =E15*15/100 -> 0 | G15: =(E15*6/100) -> 0 | H15: =C15*2/1000 -> 0 | I15: =C15*2/1000 -> 0 | J15: =C15*1/1000 -> 0
E16: =((D16*2.5)/(365*0.7))*1.21 -> 0 | F16: =E16*15/100 -> 0 | G16: =(E16*6/100) -> 0 | H16: =C16*2/1000 -> 0 | I16: =C16*2/1000 -> 0 | J16: =C16*1/1000 -> 0
E17: =((D17*2.5)/(365*0.7))*1.21 -> 0 | F17: =E17*15/100 -> 0 | G17: =(E17*6/100) -> 0 | H17: =C17*2/1000 -> 0 | I17: =C17*2/1000 -> 0 | J17: =C17*1/1000 -> 0
A18: TOTAL DA RRAS | E18: =ROUNDUP(SUM(E6:E16),0) -> 283 | F18: =ROUNDUP(SUM(F6:F16),0) -> 43 | G18: =ROUNDUP(SUM(G6:G16),0) -> 17 | H18: =ROUNDUP(SUM(H6:H16),0) -> 44 | I18: =ROUNDUP(SUM(I6:I16),0) -> 44 | J18: =ROUNDUP(SUM(J6:J16),0) -> 22
E22: NUMERO DE LEITOS EXISTENTES NA REDE MATERNA E INFANTIL (trazer da aba "totais TABELA 4")
A23: DRS | B23: REGIÃO DE SAUDE | C23: NASCIDOS VIVOS SUSDEPENDENTES (trazer da tabela1 APS) | D23: TOTAL DE GESTANTES SUSDEPENDENTES ESTIMADAS/ANO (trazer da tabela1 APS) | E23: OBSTETRICOS | F23: GAR | G23: UTI ADULTO | H23: UTIN | I23: UCINCO | J23: UCINCA | K23: CPN I 3 LEITOS | M23: CPN II | O23: CGBP | R23: BLH
K24: 3 LEITOS | L24: 5 LEITOS | M24: 3 LEITOS | N24: 5 LEITOS | O24: 10 LEITOS | P24: 15 LEITOS | Q24: 20 LEITOS
A25: =A6 -> Taubate | B25: =B6 -> Alto Vale do Paraiba | C25: =C6 -> 7863 | D25: =D6 -> 8652 | E25: 120 | F25: 5 | G25: 8 | H25: 30 | I25: 23 | J25: 3 | M25: 1 | R25: 1
A26: =A7 -> Taubate | B26: =B7 -> Circ. da Fe-V. Historico | C26: =C7 -> 4342 | D26: =D7 -> 4775 | E26: 47 | F26: 0 | G26: 3 | H26: 13
A27: =A8 -> Taubate | B27: =B8 -> Litoral Norte | C27: =C8 -> 3960 | D27: =D8 -> 4355 | E27: 75 | F27: 0 | G27: 2 | H27: 10 | R27: 2
A28: =A9 -> Taubate | B28: =B9 -> V. Paraiba - R. Serrana | C28: =C9 -> 5495 | D28: =D9 -> 6046 | E28: 86 | F28: 8 | G28: 4 | H28: 17 | I28: 7 | R28: 1
A29: =A10 | B29: =B10 | C29: =C10 | D29: =D10
A30: =A11 | B30: =B11 | C30: =C11 | D30: =D11
A31: =A12 | B31: =B12 | C31: =C12 | D31: =D12
A32: =A13 | B32: =B13 | C32: =C13 | D32: =D13
A33: =A14 | B33: =B14 | C33: =C14 | D33: =D14
A34: =A15 | B34: =B15 | C34: =C15 | D34: =D15
A35: =A16 | B35: =B16 | C35: =C16 | D35: =D16
A36: =A17 | B36: =B17 | C36: =C17 | D36: =D17
A37: TOTAL DE LEITOS EXISTENTES
E42: ANÁLISE DA SUFICIÊNCIA DE LEITOS PARA A REDE MATERNA E INFANTIL
A43: DRS | B43: REGIÃO DE SAUDE | C43: NASCIDOS VIVOS SUSDEPENDENTES (trazer da tabela1 APS) | D43: TOTAL DE GESTANTES SUSDEPENDENTES ESTIMADAS/ANO (trazer da tabela1 APS) | E43: OBSTETRICOS | F43: GAR | G43: UTI ADULTO | H43: UTIN | I43: UCINCO | J43: UCINCA | K43: CPN I | M43: CPN II | O43: CGBP | R43: BLH
K44: 3 LEITOS | L44: 5 LEITOS | M44: 3 LEITOS | N44: 5 LEITOS | O44: 10 LEITOS | P44: 15 LEITOS | Q44: 20 LEITOS
A45: =A6 -> Taubate | B45: =B6 -> Alto Vale do Paraiba | C45: =C6 -> 7863 | D45: =D6 -> 8652 | E45: =E25-E6 -> 17.564384 | F45: =F25-F6 -> -10.365342 | G45: =G25-G6 -> 1.853863 | H45: =H25-H6 -> 14.274 | I45: =I25-I6 -> 7.274 | J45: =J25-J6 -> -4.863
A46: =A7 -> Taubate | B46: =B7 -> Circ. da Fe-V. Historico | C46: =C7 -> 4342 | D46: =D7 -> 4775 | E46: =E26-E7 -> -9.5337573 | F46: =F26-F7 -> -8.4800636 | G46: =G26-G7 -> -0.39202544 | H46: =H26-H7 -> 4.316 | I46: =I26-I7 -> -8.684 | J46: =J26-J7 -> -4.342
A47: =A8 -> Taubate | B47: =B8 -> Litoral Norte | C47: =C8 -> 3960 | D47: =D8 -> 4355 | E47: =E27-E8 -> 23.438845 | F47: =F27-F8 -> -7.7341732 | G47: =G27-G8 -> -1.0936693 | H47: =H27-H8 -> 2.08 | I47: =I27-I8 -> -7.92 | J47: =J27-J8 -> -3.96
A48: =A9 -> Taubate | B48: =B9 -> V. Paraiba - R. Serrana | C48: =C9 -> 5495 | D48: =D9 -> 6046 | E48: =E28-E9 -> 14.4182 | F48: =F28-F9 -> -2.7372701 | G48: =G28-G9 -> -0.29490802 | H48: =H28-H9 -> 6.01 | I48: =I28-I9 -> -3.99 | J48: =J28-J9 -> -5.495
...

Sheet tabela 6 rede de serviços final
A1: RRAS: | B1: ='Tabela 1 APS - Descr.'!B1 -> RRAS 17
A3: (1) Nº ANUAL DE PARTOS: Considerar para este plano a média de produção de partos dos anos de 2019/2020 e 2021
A4: (2) OBSTETRICOS : Somente assinalar com S(Sim) ou N(Não) o tipo de habilitação da maternidade, lembrar que serviços que tem leitos de alto risco não são elegíveis para receber o custeio global (MAB)
A6: (3) CGBP: Assinalar com Existente (E) ou Novo (N)
A7: (4) BLH ( banco de Leite Humano): Assinalar com Existente (E) ou Novo (N)
A8: LEITOS EXISTENTES: Leitos que já estão habilitados
A9: LEITOS NOVOS: Leitos a serem habilitados de acordo com a necessidade da Região
A10: TOTAL: Leitos totais por componente por maternidade
A12: Tabela 6: Serviços que compõe a RRAS, número de leitos existentes e novos.
G13: NUMERO DE LEITOS
A14: DRS | B14: REGIÃO DE SAUDE | C14: CNES/ESTABELECIMENTO | D14: MUNICIPIO | E14: GESTÃO | F14: Nº ANUAL DE PARTOS (1) | G14: OBSTETRICOS (2) | H14: GAR | K14: UTIN | N14: UCINCO | Q14: UCINCA | T14: CPN I | V14: CPN II | X14: CGBP | AA14: BLH
T15: 3 LEITOS | U15: 5 LEITOS | V15: 3 LEITOS | W15: 5 LEITOS | X15: 10 LEITOS | Y15: 15 LEITOS | Z15: 20 LEITOS
G16: HABILITAÇÃO MAB | H16: EXISTENTE | I16: NOVO | J16: TOTAL | K16: EXISTENTE | L16: NOVO | M16: TOTAL | N16: EXISTENTE | O16: NOVO | P16: TOTAL | Q16: EXISTENTE | R16: NOVO | S16: TOTAL | T16: STATUS | U16: STATUS | V16: STATUS | W16: STATUS | X16: STATUS | Y16: STATUS | Z16: STATUS | AA16: STATUS
A17: Taubate | B17: Alto Vale do Paraiba | C17: 2024756/ Hospital e Maternidade Nossa Senhora Da Ajuda - FUSAM | D17: Caçapava | E17: Municipal | F17: 473 | G17: MAB I | J17: =SUM(H17:I17) -> 0 | M17: =SUM(K17:L17) -> 0 | P17: =SUM(N17:O17) -> 0 | S17: =SUM(Q17:R17) -> 0
C18: 2085194/ Hospital São Francisco de Assis | D18: Jacareí | E18: Municipal | F18: 1827 | G18: SEM HABILITAÇÃO | H18: 5 | J18: =SUM(H18:I18) -> 5 | K18: 8 | M18: =SUM(K18:L18) -> 8 | N18: 7 | P18: =SUM(N18:O18) -> 7 | Q18: 3 | S18: =SUM(Q18:R18) -> 3 | V18: Existente | X18: Novo
C19: 9628/ Hospital Municipal Dr José de Carvalho Florence | D19: São José dos Campos | E19: Municipal | F19: 5421 | G19: SEM HABILITAÇÃO | I19: 13 | J19: =SUM(H19:I19) -> 13 | K19: 10 | M19: =SUM(K19:L19) -> 10 | N19: 16 | P19: =SUM(N19:O19) -> 16 | R19: 5 | S19: =SUM(Q19:R19) -> 5 | U19: Novo | X19: Não existe | AA19: Existente
C20: 2748029/ Santa Casa de Misericórdia de São José dos Campos | D20: São José dos Campos | E20: Estadual | F20: 44 | G20: SEM HABILITAÇÃO | J20: =SUM(H20:I20) -> 0 | K20: 12 | M20: =SUM(K20:L20) -> 12 | O20: 7 | P20: =SUM(N20:O20) -> 7 | R20: 3 | S20: =SUM(Q20:R20) -> 3 | U20: Novo
A21: Taubate | B21: Circ. da Fe-V. Historico | C21: 2079518/ Santa Casa de Misericordia e Maternidade Nossa Senhora da Conceição | D21: Cunha | E21: Municipal | F21: 143 | G21: SEM HABILITAÇÃO | J21: =SUM(H21:I21) -> 0 | M21: =SUM(K21:L21) -> 0 | P21: =SUM(N21:O21) -> 0 | S21: =SUM(Q21:R21) -> 0
C22: 2024691/ Santa Casa de Cruzeiro | D22: Cruzeiro | E22: Municipal | F22: 849 | G22: MAB I | J22: =SUM(H22:I22) -> 0 | M22: =SUM(K22:L22) -> 0 | P22: =SUM(N22:O22) -> 0 | S22: =SUM(Q22:R22) -> 0
C23: 2081512/ Santa Casa de Misericórdia de Guaratinguetá | D23: Guaratinguetá | E23: Municipal | F23: 983 | G23: MAB I | J23: =SUM(H23:I23) -> 0 | K23: 6 | M23: =SUM(K23:L23) -> 6 | O23: 4 | P23: =SUM(N23:O23) -> 4 | R23: 2 | S23: =SUM(Q23:R23) -> 2
C24: 2081644/ Hospital e Maternidade Frei Galvão | D24: Guaratinguetá | E24: Municipal | F24: 0 | G24: SEM HABILITAÇÃO | J24: =SUM(H25:I25) -> 8 | K24: 6 | M24: =SUM(K24:L24) -> 6 | P24: =SUM(N24:O24) -> 0 | S24: =SUM(Q24:R24) -> 0
C25: 2087111/ Irmandade Santa Casa de Lorena | D25: Lorena | E25: Municipal | F25: 1573 | G25: SEM HABILITAÇÃO | I25: 8 | J25: =SUM(H26:I26) -> 0 | K25: 7 | M25: =SUM(K25:L25) -> 7 | O25: 7 | P25: =SUM(N25:O25) -> 7 | R25: 3 | S25: =SUM(Q25:R25) -> 3 | T25: Novo | U25: Não existe | X25: Novo
C26: 2087642/ Unidade Mista de Bananal | D26: Bananal | E26: Municipal | F26: 1 | G26: SEM HABILITAÇÃO | J26: =SUM(H27:I27) -> 0 | M26: =SUM(K26:L26) -> 0 | P26: =SUM(N26:O26) -> 0 | S26: =SUM(Q26:R26) -> 0
C27: 2058340/ Hospital Municipal de Queluz | D27: Queluz | E27: Municipal | F27: 1 | G27: SEM HABILITAÇÃO | J27: =SUM(H28:I28) -> 8 | M27: =SUM(K27:L27) -> 0 | P27: =SUM(N27:O27) -> 0 | S27: =SUM(Q27:R27) -> 0
A28: Taubate | B28: Litoral Norte | C28: 2082926/ Casa de Saúde Stella Maris | D28: Caraguatatuba | E28: Municipal | F28: 1649 | G28: SEM HABILITAÇÃO | I28: 8 | J28: =SUM(H29:I29) -> 0 | K28: 10 | M28: =SUM(K28:L28) -> 10 | O28: 7 | P28: =SUM(N28:O28) -> 7 | R28: 3 | S28: =SUM(Q28:R28) -> 3 | U28: Não existe | V28: Novo | X28: Não existe | AA28: Existente
C29: 2747871/ Hospital Municipal Gov Mario Covas Jr | D29: Ilhabela | E29: Municipal | F29: 460 | G29: MAB I | J29: =SUM(H30:I30) -> 0 | M29: =SUM(K29:L29) -> 0 | P29: =SUM(N29:O29) -> 0 | S29: =SUM(Q29:R29) -> 0
C30: 2765934/ Hospital de Clínicas de São Sebastião | D30: São Sebastião | E30: Municipal | F30: 941 | G30: MAB I | J30: =SUM(H31:I31) -> 0 | M30: =SUM(K30:L30) -> 0 | P30: =SUM(N30:O30) -> 0 | S30: =SUM(Q30:R30) -> 0 | AA30: Existente
C31: 2702193/ Santa Casa de Misericórdia de Ubatuba | D31: Ubatuba | E31: Municipal | F31: 935 | G31: MAB I | J31: =SUM(H32:I32) -> 0 | M31: =SUM(K31:L31) -> 0 | P31: =SUM(N31:O31) -> 0 | S31: =SUM(Q31:R31) -> 0
A32: Taubate | B32: V. Paraiba - R. Serrana | C32: 7947984/ Complexo Municipal de Saúde | D32: Campos do Jordão | E32: Municipal | F32: 644 | G32: MAB I | J32: =SUM(H33:I33) -> 5 | M32: =SUM(K32:L32) -> 0 | P32: =SUM(N32:O32) -> 0 | S32: =SUM(Q32:R32) -> 0
C33: 2755092/ Santa Casa de Pindamonhangaba | D33: Pindamonhangaba | E33: Municipal | F33: 2155 | G33: SEM HABILITAÇÃO | H33: 2 | I33: 3 | J33: =SUM(H34:I34) -> 0 | K33: 7 | M33: =SUM(K33:L33) -> 7 | N33: 7 | P33: =SUM(N33:O33) -> 7 | R33: 3 | S33: =SUM(Q33:R33) -> 3 | U33: Não existe | W33: Novo
C34: 2078546/ Santa Casa São Bento do Sapucaí | D34: São Bento do Sapucaí | E34: Municipal | F34: 78 | G34: SEM HABILITAÇÃO | J34: =SUM(H35:I35) -> 6 | M34: =SUM(K34:L34) -> 0 | P34: =SUM(N34:O34) -> 0 | S34: =SUM(Q34:R34) -> 0
C35: 2749319/ Hospital Municipal Universitário de Taubaté | D35: Taubaté | E35: Municipal | F35: 2656 | G35: SEM HABILITAÇÃO | H35: 6 | J35: =SUM(H36:I36) -> 0 | K35: 10 | M35: =SUM(K35:L35) -> 10 | O35: 7 | P35: =SUM(N35:O35) -> 7 | R35: 3 | S35: =SUM(Q35:R35) -> 3 | T35: Novo | U35: Não existe | X35: Não existe | AA35: Existente
C36: 2079690/ Santa Casa de Misericordia de São Luis do Paraitinga | D36: São Luís do Paraitinga | E36: Municipal | F36: 1 | G36: SEM HABILITAÇÃO | J36: =SUM(#REF!) -> #REF! | M36: =SUM(K36:L36) -> 0 | P36: =SUM(N36:O36) -> 0 | S36: =SUM(Q36:R36) -> 0
J37: =SUM(H37:I37) -> 0 | M37: =SUM(K37:L37) -> 0 | P37: =SUM(N37:O37) -> 0 | S37: =SUM(Q37:R37) -> 0
J38: =SUM(H38:I38) -> 0 | M38: =SUM(K38:L38) -> 0 | P38: =SUM(N38:O38) -> 0 | S38: =SUM(Q38:R38) -> 0
J39: =SUM(H39:I39) -> 0 | M39: =SUM(K39:L39) -> 0 | P39: =SUM(N39:O39) -> 0 | S39: =SUM(Q39:R39) -> 0
J40: =SUM(H40:I40) -> 0 | M40: =SUM(K40:L40) -> 0 | P40: =SUM(N40:O40) -> 0 | S40: =SUM(Q40:R40) -> 0
J41: =SUM(H41:I41) -> 0 | M41: =SUM(K41:L41) -> 0 | P41: =SUM(N41:O41) -> 0 | S41: =SUM(Q41:R41) -> 0
J42: =SUM(H42:I42) -> 0 | M42: =SUM(K42:L42) -> 0 | P42: =SUM(N42:O42) -> 0 | S42: =SUM(Q42:R42) -> 0
J43: =SUM(H43:I43) -> 0 | M43: =SUM(K43:L43) -> 0 | P43: =SUM(N43:O43) -> 0 | S43: =SUM(Q43:R43) -> 0
...
